Workbook

Sheet Dashboard
A1: Ghee Production Dashboard | Y1: All
A2: ="Period "&TEXT(Summary!$P$2,"0")&" — "&TEXT(Summary!$AT$2,"0")&" of month | Source: Summary + channel order tabs | Refreshed live" -> Period 46258 — 46288 of month | Source: Summary + channel order tabs | Refreshed live | O2: Selected Plan | P2: Row Flag | Q2: Channel Flag | R2: Selected Pending | S2: Section | T2: Selected Produced | U2: Product Flag | Y2: =IF(Summary!E3="","",Summary!E3) -> Butter/Makhan - 200 gm
A3: Product Selector | C3: All | E3: Channel Selector | G3: All | O3: {=_xlfn.SWITCH($G$3,"MRP (Domestic)",Summary!G3,"ROW Manjari",Summary!H3,"USA Sea",Summary!I3,"Amazon USA Sea",Summary!J3,"USA Air",Summary!K3,"USA Amazon",Summary!L3,"UK",Summary!M3,"MENA",Summary!N3,Summary!O3)} -> 186 | P3: =--(ISNUMBER(Summary!$A3))*--(Summary!$D3<>"") -> 1 | Q3: =IF($G$3="All",1,--(O3>0)) -> 1 | R3: =T3-O3 -> -186 | S3: =IF(Summary!$D3="","",Summary!B3) -> Ghee | T3: {=_xlfn.SWITCH($G$3,"MRP (Domestic)",IFERROR(_xlfn.XLOOKUP(Summary!$D3,Domestic!$C:$C,Domestic!$AU:$AU),0),"ROW Manjari",IFERROR(_xlfn.XLOOKUP(Summary!$D3,'INT-_Manjiri'!$C:$C,'INT-_Manjiri'!$AT:$AT),0),"USA Sea",IFERROR(_xlfn.XLOOKUP(Summary!$D3,'USA-_Sea_shipment'!$C:$C,'USA-_Sea_shipment'!#REF!),0),"Amazon USA Sea",IFERROR(_xlfn.XLOOKUP(Summary!$D3,Amazon_USA_Sea!$C:$C,Amazon_USA_Sea!$AT:$AT),0),"USA Air",IFERROR(_xlfn.XLOOKUP(Summary!$D3,USA_Air_Shipment!$C:$C,USA_Air_Shipment!$AS:$AS),0),"USA Amazon",IFERROR(_xlfn.XLOOKUP(Summary!$D3,Amazon_USA_Air_Shipment!$C:$C,Amazon_USA_Air_Shipment!$AS:$AS),0),"UK",IFERROR(_xlfn.XLOOKUP(Summary!$D3,UK!$C:$C,UK!$AW:$AW),0),"MENA",IFERROR(_xlfn.XLOOKUP(Summary!$D3,MENA!$C:$C,MENA!$AS:$AS),0),Summary!BB3)} -> 0 | U3: =IF($C$3="All",1,--(Summary!E3=$C$3)) -> 1 | Y3: =IF(Summary!E4="","",Summary!E4) -> Brahmi Ghee - 250 gm
O4: {=_xlfn.SWITCH($G$3,"MRP (Domestic)",Summary!G4,"ROW Manjari",Summary!H4,"USA Sea",Summary!I4,"Amazon USA Sea",Summary!J4,"USA Air",Summary!K4,"USA Amazon",Summary!L4,"UK",Summary!M4,"MENA",Summary!N4,Summary!O4)} -> 253 | P4: =--(ISNUMBER(Summary!$A4))*--(Summary!$D4<>"") -> 1 | Q4: =IF($G$3="All",1,--(O4>0)) -> 1 | R4: =T4-O4 -> -186 | S4: =IF(Summary!$D4="","",Summary!B4) -> Ghee | T4: {=_xlfn.SWITCH($G$3,"MRP (Domestic)",IFERROR(_xlfn.XLOOKUP(Summary!$D4,Domestic!$C:$C,Domestic!$AU:$AU),0),"ROW Manjari",IFERROR(_xlfn.XLOOKUP(Summary!$D4,'INT-_Manjiri'!$C:$C,'INT-_Manjiri'!$AT:$AT),0),"USA Sea",IFERROR(_xlfn.XLOOKUP(Summary!$D4,'USA-_Sea_shipment'!$C:$C,'USA-_Sea_shipment'!#REF!),0),"Amazon USA Sea",IFERROR(_xlfn.XLOOKUP(Summary!$D4,Amazon_USA_Sea!$C:$C,Amazon_USA_Sea!$AT:$AT),0),"USA Air",IFERROR(_xlfn.XLOOKUP(Summary!$D4,USA_Air_Shipment!$C:$C,USA_Air_Shipment!$AS:$AS),0),"USA Amazon",IFERROR(_xlfn.XLOOKUP(Summary!$D4,Amazon_USA_Air_Shipment!$C:$C,Amazon_USA_Air_Shipment!$AS:$AS),0),"UK",IFERROR(_xlfn.XLOOKUP(Summary!$D4,UK!$C:$C,UK!$AW:$AW),0),"MENA",IFERROR(_xlfn.XLOOKUP(Summary!$D4,MENA!$C:$C,MENA!$AS:$AS),0),Summary!BB4)} -> 67 | U4: =IF($C$3="All",1,--(Summary!E4=$C$3)) -> 1 | Y4: =IF(Summary!E5="","",Summary!E5) -> Tulsi Ghee - 250gm
A5: Total Plan | C5: Produced PKT | E5: Fulfillment % | G5: Pending PKT | I5: Pending SKUs | K5: Critical SKUs | O5: {=_xlfn.SWITCH($G$3,"MRP (Domestic)",Summary!G5,"ROW Manjari",Summary!H5,"USA Sea",Summary!I5,"Amazon USA Sea",Summary!J5,"USA Air",Summary!K5,"USA Amazon",Summary!L5,"UK",Summary!M5,"MENA",Summary!N5,Summary!O5)} -> 75 | P5: =--(ISNUMBER(Summary!$A5))*--(Summary!$D5<>"") -> 1 | Q5: =IF($G$3="All",1,--(O5>0)) -> 1 | R5: =T5-O5 -> -29 | S5: =IF(Summary!$D5="","",Summary!B5) -> Ghee | T5: {=_xlfn.SWITCH($G$3,"MRP (Domestic)",IFERROR(_xlfn.XLOOKUP(Summary!$D5,Domestic!$C:$C,Domestic!$AU:$AU),0),"ROW Manjari",IFERROR(_xlfn.XLOOKUP(Summary!$D5,'INT-_Manjiri'!$C:$C,'INT-_Manjiri'!$AT:$AT),0),"USA Sea",IFERROR(_xlfn.XLOOKUP(Summary!$D5,'USA-_Sea_shipment'!$C:$C,'USA-_Sea_shipment'!#REF!),0),"Amazon USA Sea",IFERROR(_xlfn.XLOOKUP(Summary!$D5,Amazon_USA_Sea!$C:$C,Amazon_USA_Sea!$AT:$AT),0),"USA Air",IFERROR(_xlfn.XLOOKUP(Summary!$D5,USA_Air_Shipment!$C:$C,USA_Air_Shipment!$AS:$AS),0),"USA Amazon",IFERROR(_xlfn.XLOOKUP(Summary!$D5,Amazon_USA_Air_Shipment!$C:$C,Amazon_USA_Air_Shipment!$AS:$AS),0),"UK",IFERROR(_xlfn.XLOOKUP(Summary!$D5,UK!$C:$C,UK!$AW:$AW),0),"MENA",IFERROR(_xlfn.XLOOKUP(Summary!$D5,MENA!$C:$C,MENA!$AS:$AS),0),Summary!BB5)} -> 46 | U5: =IF($C$3="All",1,--(Summary!E5=$C$3)) -> 1 | Y5: =IF(Summary!E6="","",Summary!E6) -> Shatavari Ghee - 250 gm
A6: =IFERROR(SUMPRODUCT($O$3:$O$70,$P$3:$P$70,$Q$3:$Q$70,$U$3:$U$70),"") -> 129806.55 | C6: =IFERROR(SUMPRODUCT($T$3:$T$70,$P$3:$P$70,$Q$3:$Q$70,$U$3:$U$70),"") -> 73114 | E6: =IFERROR(C6/A6,"") -> 0.56325355 | G6: {=IFERROR(ABS(SUMPRODUCT($R$3:$R$70,--($R$3:$R$70<0),$P$3:$P$70,$Q$3:$Q$70,$U$3:$U$70)),"")} -> 57528.85 | I6: {=IFERROR(SUMPRODUCT(--($R$3:$R$70<0),$P$3:$P$70,$Q$3:$Q$70,$U$3:$U$70),"")} -> 16 | K6: {=IFERROR(SUMPRODUCT(--(Summary!$BK$3:$BK$70="P1 – Critical"),$P$3:$P$70,$Q$3:$Q$70,$U$3:$U$70),"")} -> 13 | O6: {=_xlfn.SWITCH($G$3,"MRP (Domestic)",Summary!G6,"ROW Manjari",Summary!H6,"USA Sea",Summary!I6,"Amazon USA Sea",Summary!J6,"USA Air",Summary!K6,"USA Amazon",Summary!L6,"UK",Summary!M6,"MENA",Summary!N6,Summary!O6)} -> 319 | P6: =--(ISNUMBER(Summary!$A6))*--(Summary!$D6<>"") -> 1 | Q6: =IF($G$3="All",1,--(O6>0)) -> 1 | R6: =T6-O6 -> -255 | S6: =IF(Summary!$D6="","",Summary!B6) -> Ghee | T6: {=_xlfn.SWITCH($G$3,"MRP (Domestic)",IFERROR(_xlfn.XLOOKUP(Summary!$D6,Domestic!$C:$C,Domestic!$AU:$AU),0),"ROW Manjari",IFERROR(_xlfn.XLOOKUP(Summary!$D6,'INT-_Manjiri'!$C:$C,'INT-_Manjiri'!$AT:$AT),0),"USA Sea",IFERROR(_xlfn.XLOOKUP(Summary!$D6,'USA-_Sea_shipment'!$C:$C,'USA-_Sea_shipment'!#REF!),0),"Amazon USA Sea",IFERROR(_xlfn.XLOOKUP(Summary!$D6,Amazon_USA_Sea!$C:$C,Amazon_USA_Sea!$AT:$AT),0),"USA Air",IFERROR(_xlfn.XLOOKUP(Summary!$D6,USA_Air_Shipment!$C:$C,USA_Air_Shipment!$AS:$AS),0),"USA Amazon",IFERROR(_xlfn.XLOOKUP(Summary!$D6,Amazon_USA_Air_Shipment!$C:$C,Amazon_USA_Air_Shipment!$AS:$AS),0),"UK",IFERROR(_xlfn.XLOOKUP(Summary!$D6,UK!$C:$C,UK!$AW:$AW),0),"MENA",IFERROR(_xlfn.XLOOKUP(Summary!$D6,MENA!$C:$C,MENA!$AS:$AS),0),Summary!BB6)} -> 64 | U6: =IF($C$3="All",1,--(Summary!E6=$C$3)) -> 1 | Y6: =IF(Summary!E7="","",Summary!E7) -> Turmeric Ghee 250gm
O7: {=_xlfn.SWITCH($G$3,"MRP (Domestic)",Summary!G7,"ROW Manjari",Summary!H7,"USA Sea",Summary!I7,"Amazon USA Sea",Summary!J7,"USA Air",Summary!K7,"USA Amazon",Summary!L7,"UK",Summary!M7,"MENA",Summary!N7,Summary!O7)} -> 149 | P7: =--(ISNUMBER(Summary!$A7))*--(Summary!$D7<>"") -> 1 | Q7: =IF($G$3="All",1,--(O7>0)) -> 1 | R7: =T7-O7 -> -19 | S7: =IF(Summary!$D7="","",Summary!B7) -> Ghee | T7: {=_xlfn.SWITCH($G$3,"MRP (Domestic)",IFERROR(_xlfn.XLOOKUP(Summary!$D7,Domestic!$C:$C,Domestic!$AU:$AU),0),"ROW Manjari",IFERROR(_xlfn.XLOOKUP(Summary!$D7,'INT-_Manjiri'!$C:$C,'INT-_Manjiri'!$AT:$AT),0),"USA Sea",IFERROR(_xlfn.XLOOKUP(Summary!$D7,'USA-_Sea_shipment'!$C:$C,'USA-_Sea_shipment'!#REF!),0),"Amazon USA Sea",IFERROR(_xlfn.XLOOKUP(Summary!$D7,Amazon_USA_Sea!$C:$C,Amazon_USA_Sea!$AT:$AT),0),"USA Air",IFERROR(_xlfn.XLOOKUP(Summary!$D7,USA_Air_Shipment!$C:$C,USA_Air_Shipment!$AS:$AS),0),"USA Amazon",IFERROR(_xlfn.XLOOKUP(Summary!$D7,Amazon_USA_Air_Shipment!$C:$C,Amazon_USA_Air_Shipment!$AS:$AS),0),"UK",IFERROR(_xlfn.XLOOKUP(Summary!$D7,UK!$C:$C,UK!$AW:$AW),0),"MENA",IFERROR(_xlfn.XLOOKUP(Summary!$D7,MENA!$C:$C,MENA!$AS:$AS),0),Summary!BB7)} -> 130 | U7: =IF($C$3="All",1,--(Summary!E7=$C$3)) -> 1 | Y7: =IF(Summary!E8="","",Summary!E8) -> Buffalo Ghee - A2 Cultured 500ml
O8: {=_xlfn.SWITCH($G$3,"MRP (Domestic)",Summary!G8,"ROW Manjari",Summary!H8,"USA Sea",Summary!I8,"Amazon USA Sea",Summary!J8,"USA Air",Summary!K8,"USA Amazon",Summary!L8,"UK",Summary!M8,"MENA",Summary!N8,Summary!O8)} -> 22881 | P8: =--(ISNUMBER(Summary!$A8))*--(Summary!$D8<>"") -> 1 | Q8: =IF($G$3="All",1,--(O8>0)) -> 1 | R8: =T8-O8 -> -18586 | S8: =IF(Summary!$D8="","",Summary!B8) -> Ghee | T8: {=_xlfn.SWITCH($G$3,"MRP (Domestic)",IFERROR(_xlfn.XLOOKUP(Summary!$D8,Domestic!$C:$C,Domestic!$AU:$AU),0),"ROW Manjari",IFERROR(_xlfn.XLOOKUP(Summary!$D8,'INT-_Manjiri'!$C:$C,'INT-_Manjiri'!$AT:$AT),0),"USA Sea",IFERROR(_xlfn.XLOOKUP(Summary!$D8,'USA-_Sea_shipment'!$C:$C,'USA-_Sea_shipment'!#REF!),0),"Amazon USA Sea",IFERROR(_xlfn.XLOOKUP(Summary!$D8,Amazon_USA_Sea!$C:$C,Amazon_USA_Sea!$AT:$AT),0),"USA Air",IFERROR(_xlfn.XLOOKUP(Summary!$D8,USA_Air_Shipment!$C:$C,USA_Air_Shipment!$AS:$AS),0),"USA Amazon",IFERROR(_xlfn.XLOOKUP(Summary!$D8,Amazon_USA_Air_Shipment!$C:$C,Amazon_USA_Air_Shipment!$AS:$AS),0),"UK",IFERROR(_xlfn.XLOOKUP(Summary!$D8,UK!$C:$C,UK!$AW:$AW),0),"MENA",IFERROR(_xlfn.XLOOKUP(Summary!$D8,MENA!$C:$C,MENA!$AS:$AS),0),Summary!BB8)} -> 4295 | U8: =IF($C$3="All",1,--(Summary!E8=$C$3)) -> 1 | Y8: =IF(Summary!E9="","",Summary!E9) -> A2 Desi Cow Ghee - 500ml
A9: =IFERROR("Channel: "&$G$3&" | Product: "&$C$3&". Fulfillment is "&TEXT(E6,"0%")&" against "&TEXT(A6,"#,##0")&" planned packets. Pending exposure is "&TEXT(G6,"#,##0")&" packets across "&TEXT(I6,"#,##0")&" SKUs, including "&TEXT(K6,"#,##0")&" critical SKUs.","") -> Channel: All | Product: All. Fulfillment is 56% against 1,29,807 planned packets. Pending exposure is 57,529 packets across 16 SKUs, including 13 critical SKUs. | O9: {=_xlfn.SWITCH($G$3,"MRP (Domestic)",Summary!G9,"ROW Manjari",Summary!H9,"USA Sea",Summary!I9,"Amazon USA Sea",Summary!J9,"USA Air",Summary!K9,"USA Amazon",Summary!L9,"UK",Summary!M9,"MENA",Summary!N9,Summary!O9)} -> 10468.7 | P9: =--(ISNUMBER(Summary!$A9))*--(Summary!$D9<>"") -> 1 | Q9: =IF($G$3="All",1,--(O9>0)) -> 1 | R9: =T9-O9 -> -7087.7 | S9: =IF(Summary!$D9="","",Summary!B9) -> Ghee | T9: {=_xlfn.SWITCH($G$3,"MRP (Domestic)",IFERROR(_xlfn.XLOOKUP(Summary!$D9,Domestic!$C:$C,Domestic!$AU:$AU),0),"ROW Manjari",IFERROR(_xlfn.XLOOKUP(Summary!$D9,'INT-_Manjiri'!$C:$C,'INT-_Manjiri'!$AT:$AT),0),"USA Sea",IFERROR(_xlfn.XLOOKUP(Summary!$D9,'USA-_Sea_shipment'!$C:$C,'USA-_Sea_shipment'!#REF!),0),"Amazon USA Sea",IFERROR(_xlfn.XLOOKUP(Summary!$D9,Amazon_USA_Sea!$C:$C,Amazon_USA_Sea!$AT:$AT),0),"USA Air",IFERROR(_xlfn.XLOOKUP(Summary!$D9,USA_Air_Shipment!$C:$C,USA_Air_Shipment!$AS:$AS),0),"USA Amazon",IFERROR(_xlfn.XLOOKUP(Summary!$D9,Amazon_USA_Air_Shipment!$C:$C,Amazon_USA_Air_Shipment!$AS:$AS),0),"UK",IFERROR(_xlfn.XLOOKUP(Summary!$D9,UK!$C:$C,UK!$AW:$AW),0),"MENA",IFERROR(_xlfn.XLOOKUP(Summary!$D9,MENA!$C:$C,MENA!$AS:$AS),0),Summary!BB9)} -> 3381 | U9: =IF($C$3="All",1,--(Summary!E9=$C$3)) -> 1 | Y9: =IF(Summary!E10="","",Summary!E10) -> Colostrum Powder, Desi Gir Cow - 100 gm
O10: {=_xlfn.SWITCH($G$3,"MRP (Domestic)",Summary!G10,"ROW Manjari",Summary!H10,"USA Sea",Summary!I10,"Amazon USA Sea",Summary!J10,"USA Air",Summary!K10,"USA Amazon",Summary!L10,"UK",Summary!M10,"MENA",Summary!N10,Summary!O10)} -> 1712 | P10: =--(ISNUMBER(Summary!$A10))*--(Summary!$D10<>"") -> 1 | Q10: =IF($G$3="All",1,--(O10>0)) -> 1 | R10: =T10-O10 -> -799 | S10: =IF(Summary!$D10="","",Summary!B10) -> Ghee | T10: {=_xlfn.SWITCH($G$3,"MRP (Domestic)",IFERROR(_xlfn.XLOOKUP(Summary!$D10,Domestic!$C:$C,Domestic!$AU:$AU),0),"ROW Manjari",IFERROR(_xlfn.XLOOKUP(Summary!$D10,'INT-_Manjiri'!$C:$C,'INT-_Manjiri'!$AT:$AT),0),"USA Sea",IFERROR(_xlfn.XLOOKUP(Summary!$D10,'USA-_Sea_shipment'!$C:$C,'USA-_Sea_shipment'!#REF!),0),"Amazon USA Sea",IFERROR(_xlfn.XLOOKUP(Summary!$D10,Amazon_USA_Sea!$C:$C,Amazon_USA_Sea!$AT:$AT),0),"USA Air",IFERROR(_xlfn.XLOOKUP(Summary!$D10,USA_Air_Shipment!$C:$C,USA_Air_Shipment!$AS:$AS),0),"USA Amazon",IFERROR(_xlfn.XLOOKUP(Summary!$D10,Amazon_USA_Air_Shipment!$C:$C,Amazon_USA_Air_Shipment!$AS:$AS),0),"UK",IFERROR(_xlfn.XLOOKUP(Summary!$D10,UK!$C:$C,UK!$AW:$AW),0),"MENA",IFERROR(_xlfn.XLOOKUP(Summary!$D10,MENA!$C:$C,MENA!$AS:$AS),0),Summary!BB10)} -> 913 | U10: =IF($C$3="All",1,--(Summary!E10=$C$3)) -> 1 | Y10: =IF(Summary!E11="","",Summary!E11) -> Full Moon Cultured Ghee - 500 ml
A11: SECTION PERFORMANCE | H11: CHANNEL PLAN MIX | O11: {=_xlfn.SWITCH($G$3,"MRP (Domestic)",Summary!G11,"ROW Manjari",Summary!H11,"USA Sea",Summary!I11,"Amazon USA Sea",Summary!J11,"USA Air",Summary!K11,"USA Amazon",Summary!L11,"UK",Summary!M11,"MENA",Summary!N11,Summary!O11)} -> 3303.3 | P11: =--(ISNUMBER(Summary!$A11))*--(Summary!$D11<>"") -> 1 | Q11: =IF($G$3="All",1,--(O11>0)) -> 1 | R11: =T11-O11 -> -1701.3 | S11: =IF(Summary!$D11="","",Summary!B11) -> Ghee | T11: {=_xlfn.SWITCH($G$3,"MRP (Domestic)",IFERROR(_xlfn.XLOOKUP(Summary!$D11,Domestic!$C:$C,Domestic!$AU:$AU),0),"ROW Manjari",IFERROR(_xlfn.XLOOKUP(Summary!$D11,'INT-_Manjiri'!$C:$C,'INT-_Manjiri'!$AT:$AT),0),"USA Sea",IFERROR(_xlfn.XLOOKUP(Summary!$D11,'USA-_Sea_shipment'!$C:$C,'USA-_Sea_shipment'!#REF!),0),"Amazon USA Sea",IFERROR(_xlfn.XLOOKUP(Summary!$D11,Amazon_USA_Sea!$C:$C,Amazon_USA_Sea!$AT:$AT),0),"USA Air",IFERROR(_xlfn.XLOOKUP(Summary!$D11,USA_Air_Shipment!$C:$C,USA_Air_Shipment!$AS:$AS),0),"USA Amazon",IFERROR(_xlfn.XLOOKUP(Summary!$D11,Amazon_USA_Air_Shipment!$C:$C,Amazon_USA_Air_Shipment!$AS:$AS),0),"UK",IFERROR(_xlfn.XLOOKUP(Summary!$D11,UK!$C:$C,UK!$AW:$AW),0),"MENA",IFERROR(_xlfn.XLOOKUP(Summary!$D11,MENA!$C:$C,MENA!$AS:$AS),0),Summary!BB11)} -> 1602 | U11: =IF($C$3="All",1,--(Summary!E11=$C$3)) -> 1 | Y11: =IF(Summary!E12="","",Summary!E12) -> Non cultured ghee 1l
A12: Section | B12: Plan | C12: Produced | D12: Fulfillment | E12: Pending SKUs | F12: Critical SKUs | H12: Channel | I12: Plan | J12: Share | O12: {=_xlfn.SWITCH($G$3,"MRP (Domestic)",Summary!G12,"ROW Manjari",Summary!H12,"USA Sea",Summary!I12,"Amazon USA Sea",Summary!J12,"USA Air",Summary!K12,"USA Amazon",Summary!L12,"UK",Summary!M12,"MENA",Summary!N12,Summary!O12)} -> 6049 | P12: =--(ISNUMBER(Summary!$A12))*--(Summary!$D12<>"") -> 1 | Q12: =IF($G$3="All",1,--(O12>0)) -> 1 | R12: =T12-O12 -> -3718 | S12: =IF(Summary!$D12="","",Summary!B12) -> Ghee | T12: {=_xlfn.SWITCH($G$3,"MRP (Domestic)",IFERROR(_xlfn.XLOOKUP(Summary!$D12,Domestic!$C:$C,Domestic!$AU:$AU),0),"ROW Manjari",IFERROR(_xlfn.XLOOKUP(Summary!$D12,'INT-_Manjiri'!$C:$C,'INT-_Manjiri'!$AT:$AT),0),"USA Sea",IFERROR(_xlfn.XLOOKUP(Summary!$D12,'USA-_Sea_shipment'!$C:$C,'USA-_Sea_shipment'!#REF!),0),"Amazon USA Sea",IFERROR(_xlfn.XLOOKUP(Summary!$D12,Amazon_USA_Sea!$C:$C,Amazon_USA_Sea!$AT:$AT),0),"USA Air",IFERROR(_xlfn.XLOOKUP(Summary!$D12,USA_Air_Shipment!$C:$C,USA_Air_Shipment!$AS:$AS),0),"USA Amazon",IFERROR(_xlfn.XLOOKUP(Summary!$D12,Amazon_USA_Air_Shipment!$C:$C,Amazon_USA_Air_Shipment!$AS:$AS),0),"UK",IFERROR(_xlfn.XLOOKUP(Summary!$D12,UK!$C:$C,UK!$AW:$AW),0),"MENA",IFERROR(_xlfn.XLOOKUP(Summary!$D12,MENA!$C:$C,MENA!$AS:$AS),0),Summary!BB12)} -> 2331 | U12: =IF($C$3="All",1,--(Summary!E12=$C$3)) -> 1 | Y12: =IF(Summary!E13="","",Summary!E13) -> Ashwagandha Ghee - 250 gm
A13: Ghee | B13: {=IF($A13="","",IFERROR(SUMPRODUCT(--($S$3:$S$70=$A13),$O$3:$O$70,$P$3:$P$70,$Q$3:$Q$70,$U$3:$U$70),""))} -> 129806.55 | C13: {=IF($A13="","",IFERROR(SUMPRODUCT(--($S$3:$S$70=$A13),$T$3:$T$70,$P$3:$P$70,$Q$3:$Q$70,$U$3:$U$70),""))} -> 73114 | D13: =IFERROR(C13/B13,"") -> 0.56325355 | E13: {=IF($A13="","",IFERROR(SUMPRODUCT(--($S$3:$S$70=$A13),--($R$3:$R$70<0),$P$3:$P$70,$Q$3:$Q$70,$U$3:$U$70),""))} -> 16 | F13: {=IF($A13="","",IFERROR(SUMPRODUCT(--($S$3:$S$70=$A13),--(Summary!$BK$3:$BK$70="P1 – Critical"),$P$3:$P$70,$Q$3:$Q$70,$U$3:$U$70),""))} -> 13 | H13: =Summary!G2 -> MRP (Domestic) | I13: =IFERROR(SUMPRODUCT($P$3:$P$70,$U$3:$U$70,INDEX(Summary!$G$3:$N$70,0,ROW()-12)),"") -> 113086.55 | J13: =IFERROR(I13/SUM($I$13:$I$20),"") -> 0.87119294 | O13: {=_xlfn.SWITCH($G$3,"MRP (Domestic)",Summary!G13,"ROW Manjari",Summary!H13,"USA Sea",Summary!I13,"Amazon USA Sea",Summary!J13,"USA Air",Summary!K13,"USA Amazon",Summary!L13,"UK",Summary!M13,"MENA",Summary!N13,Summary!O13)} -> 309 | P13: =--(ISNUMBER(Summary!$A13))*--(Summary!$D13<>"") -> 1 | Q13: =IF($G$3="All",1,--(O13>0)) -> 1 | R13: =T13-O13 -> -121 | S13: =IF(Summary!$D13="","",Summary!B13) -> Ghee | T13: {=_xlfn.SWITCH($G$3,"MRP (Domestic)",IFERROR(_xlfn.XLOOKUP(Summary!$D13,Domestic!$C:$C,Domestic!$AU:$AU),0),"ROW Manjari",IFERROR(_xlfn.XLOOKUP(Summary!$D13,'INT-_Manjiri'!$C:$C,'INT-_Manjiri'!$AT:$AT),0),"USA Sea",IFERROR(_xlfn.XLOOKUP(Summary!$D13,'USA-_Sea_shipment'!$C:$C,'USA-_Sea_shipment'!#REF!),0),"Amazon USA Sea",IFERROR(_xlfn.XLOOKUP(Summary!$D13,Amazon_USA_Sea!$C:$C,Amazon_USA_Sea!$AT:$AT),0),"USA Air",IFERROR(_xlfn.XLOOKUP(Summary!$D13,USA_Air_Shipment!$C:$C,USA_Air_Shipment!$AS:$AS),0),"USA Amazon",IFERROR(_xlfn.XLOOKUP(Summary!$D13,Amazon_USA_Air_Shipment!$C:$C,Amazon_USA_Air_Shipment!$AS:$AS),0),"UK",IFERROR(_xlfn.XLOOKUP(Summary!$D13,UK!$C:$C,UK!$AW:$AW),0),"MENA",IFERROR(_xlfn.XLOOKUP(Summary!$D13,MENA!$C:$C,MENA!$AS:$AS),0),Summary!BB13)} -> 188 | U13: =IF($C$3="All",1,--(Summary!E13=$C$3)) -> 1 | Y13: =IF(Summary!E14="","",Summary!E14) -> A2 Cultured Ghee - 500 ml
B14: {=IF($A14="","",IFERROR(SUMPRODUCT(--($S$3:$S$70=$A14),$O$3:$O$70,$P$3:$P$70,$Q$3:$Q$70,$U$3:$U$70),""))} | C14: {=IF($A14="","",IFERROR(SUMPRODUCT(--($S$3:$S$70=$A14),$T$3:$T$70,$P$3:$P$70,$Q$3:$Q$70,$U$3:$U$70),""))} | D14: =IFERROR(C14/B14,"") | E14: {=IF($A14="","",IFERROR(SUMPRODUCT(--($S$3:$S$70=$A14),--($R$3:$R$70<0),$P$3:$P$70,$Q$3:$Q$70,$U$3:$U$70),""))} | F14: {=IF($A14="","",IFERROR(SUMPRODUCT(--($S$3:$S$70=$A14),--(Summary!$BK$3:$BK$70="P1 – Critical"),$P$3:$P$70,$Q$3:$Q$70,$U$3:$U$70),""))} | H14: =Summary!H2 -> ROW Manjari | I14: =IFERROR(SUMPRODUCT($P$3:$P$70,$U$3:$U$70,INDEX(Summary!$G$3:$N$70,0,ROW()-12)),"") -> 0 | J14: =IFERROR(I14/SUM($I$13:$I$20),"") -> 0 | O14: {=_xlfn.SWITCH($G$3,"MRP (Domestic)",Summary!G14,"ROW Manjari",Summary!H14,"USA Sea",Summary!I14,"Amazon USA Sea",Summary!J14,"USA Air",Summary!K14,"USA Amazon",Summary!L14,"UK",Summary!M14,"MENA",Summary!N14,Summary!O14)} -> 37298.25 | P14: =--(ISNUMBER(Summary!$A14))*--(Summary!$D14<>"") -> 1 | Q14: =IF($G$3="All",1,--(O14>0)) -> 1 | R14: =T14-O14 -> -14481.25 | S14: =IF(Summary!$D14="","",Summary!B14) -> Ghee | T14: {=_xlfn.SWITCH($G$3,"MRP (Domestic)",IFERROR(_xlfn.XLOOKUP(Summary!$D14,Domestic!$C:$C,Domestic!$AU:$AU),0),"ROW Manjari",IFERROR(_xlfn.XLOOKUP(Summary!$D14,'INT-_Manjiri'!$C:$C,'INT-_Manjiri'!$AT:$AT),0),"USA Sea",IFERROR(_xlfn.XLOOKUP(Summary!$D14,'USA-_Sea_shipment'!$C:$C,'USA-_Sea_shipment'!#REF!),0),"Amazon USA Sea",IFERROR(_xlfn.XLOOKUP(Summary!$D14,Amazon_USA_Sea!$C:$C,Amazon_USA_Sea!$AT:$AT),0),"USA Air",IFERROR(_xlfn.XLOOKUP(Summary!$D14,USA_Air_Shipment!$C:$C,USA_Air_Shipment!$AS:$AS),0),"USA Amazon",IFERROR(_xlfn.XLOOKUP(Summary!$D14,Amazon_USA_Air_Shipment!$C:$C,Amazon_USA_Air_Shipment!$AS:$AS),0),"UK",IFERROR(_xlfn.XLOOKUP(Summary!$D14,UK!$C:$C,UK!$AW:$AW),0),"MENA",IFERROR(_xlfn.XLOOKUP(Summary!$D14,MENA!$C:$C,MENA!$AS:$AS),0),Summary!BB14)} -> 22817 | U14: =IF($C$3="All",1,--(Summary!E14=$C$3)) -> 1 | Y14: =IF(Summary!E15="","",Summary!E15) -> A2 Cultured Ghee - 5 Ltr
B15: {=IF($A15="","",IFERROR(SUMPRODUCT(--($S$3:$S$70=$A15),$O$3:$O$70,$P$3:$P$70,$Q$3:$Q$70,$U$3:$U$70),""))} | C15: {=IF($A15="","",IFERROR(SUMPRODUCT(--($S$3:$S$70=$A15),$T$3:$T$70,$P$3:$P$70,$Q$3:$Q$70,$U$3:$U$70),""))} | D15: =IFERROR(C15/B15,"") | E15: {=IF($A15="","",IFERROR(SUMPRODUCT(--($S$3:$S$70=$A15),--($R$3:$R$70<0),$P$3:$P$70,$Q$3:$Q$70,$U$3:$U$70),""))} | F15: {=IF($A15="","",IFERROR(SUMPRODUCT(--($S$3:$S$70=$A15),--(Summary!$BK$3:$BK$70="P1 – Critical"),$P$3:$P$70,$Q$3:$Q$70,$U$3:$U$70),""))} | H15: =Summary!I2 -> USA Sea | I15: =IFERROR(SUMPRODUCT($P$3:$P$70,$U$3:$U$70,INDEX(Summary!$G$3:$N$70,0,ROW()-12)),"") -> 2171 | J15: =IFERROR(I15/SUM($I$13:$I$20),"") -> 0.016724888 | O15: {=_xlfn.SWITCH($G$3,"MRP (Domestic)",Summary!G15,"ROW Manjari",Summary!H15,"USA Sea",Summary!I15,"Amazon USA Sea",Summary!J15,"USA Air",Summary!K15,"USA Amazon",Summary!L15,"UK",Summary!M15,"MENA",Summary!N15,Summary!O15)} -> 1035.25 | P15: =--(ISNUMBER(Summary!$A15))*--(Summary!$D15<>"") -> 1 | Q15: =IF($G$3="All",1,--(O15>0)) -> 1 | R15: =T15-O15 -> -441.25 | S15: =IF(Summary!$D15="","",Summary!B15) -> Ghee | T15: {=_xlfn.SWITCH($G$3,"MRP (Domestic)",IFERROR(_xlfn.XLOOKUP(Summary!$D15,Domestic!$C:$C,Domestic!$AU:$AU),0),"ROW Manjari",IFERROR(_xlfn.XLOOKUP(Summary!$D15,'INT-_Manjiri'!$C:$C,'INT-_Manjiri'!$AT:$AT),0),"USA Sea",IFERROR(_xlfn.XLOOKUP(Summary!$D15,'USA-_Sea_shipment'!$C:$C,'USA-_Sea_shipment'!#REF!),0),"Amazon USA Sea",IFERROR(_xlfn.XLOOKUP(Summary!$D15,Amazon_USA_Sea!$C:$C,Amazon_USA_Sea!$AT:$AT),0),"USA Air",IFERROR(_xlfn.XLOOKUP(Summary!$D15,USA_Air_Shipment!$C:$C,USA_Air_Shipment!$AS:$AS),0),"USA Amazon",IFERROR(_xlfn.XLOOKUP(Summary!$D15,Amazon_USA_Air_Shipment!$C:$C,Amazon_USA_Air_Shipment!$AS:$AS),0),"UK",IFERROR(_xlfn.XLOOKUP(Summary!$D15,UK!$C:$C,UK!$AW:$AW),0),"MENA",IFERROR(_xlfn.XLOOKUP(Summary!$D15,MENA!$C:$C,MENA!$AS:$AS),0),Summary!BB15)} -> 594 | U15: =IF($C$3="All",1,--(Summary!E15=$C$3)) -> 1 | Y15: =IF(Summary!E16="","",Summary!E16) -> Steel Can Ghee 1 Ltr
B16: {=IF($A16="","",IFERROR(SUMPRODUCT(--($S$3:$S$70=$A16),$O$3:$O$70,$P$3:$P$70,$Q$3:$Q$70,$U$3:$U$70),""))} | C16: {=IF($A16="","",IFERROR(SUMPRODUCT(--($S$3:$S$70=$A16),$T$3:$T$70,$P$3:$P$70,$Q$3:$Q$70,$U$3:$U$70),""))} | D16: =IFERROR(C16/B16,"") | E16: {=IF($A16="","",IFERROR(SUMPRODUCT(--($S$3:$S$70=$A16),--($R$3:$R$70<0),$P$3:$P$70,$Q$3:$Q$70,$U$3:$U$70),""))} | F16: {=IF($A16="","",IFERROR(SUMPRODUCT(--($S$3:$S$70=$A16),--(Summary!$BK$3:$BK$70="P1 – Critical"),$P$3:$P$70,$Q$3:$Q$70,$U$3:$U$70),""))} | H16: =Summary!J2 -> Amazon USA Sea | I16: =IFERROR(SUMPRODUCT($P$3:$P$70,$U$3:$U$70,INDEX(Summary!$G$3:$N$70,0,ROW()-12)),"") -> 6819 | J16: =IFERROR(I16/SUM($I$13:$I$20),"") -> 0.052532018 | O16: {=_xlfn.SWITCH($G$3,"MRP (Domestic)",Summary!G16,"ROW Manjari",Summary!H16,"USA Sea",Summary!I16,"Amazon USA Sea",Summary!J16,"USA Air",Summary!K16,"USA Amazon",Summary!L16,"UK",Summary!M16,"MENA",Summary!N16,Summary!O16)} -> 413.05 | P16: =--(ISNUMBER(Summary!$A16))*--(Summary!$D16<>"") -> 1 | Q16: =IF($G$3="All",1,--(O16>0)) -> 1 | R16: =T16-O16 -> -43.05 | S16: =IF(Summary!$D16="","",Summary!B16) -> Ghee | T16: {=_xlfn.SWITCH($G$3,"MRP (Domestic)",IFERROR(_xlfn.XLOOKUP(Summary!$D16,Domestic!$C:$C,Domestic!$AU:$AU),0),"ROW Manjari",IFERROR(_xlfn.XLOOKUP(Summary!$D16,'INT-_Manjiri'!$C:$C,'INT-_Manjiri'!$AT:$AT),0),"USA Sea",IFERROR(_xlfn.XLOOKUP(Summary!$D16,'USA-_Sea_shipment'!$C:$C,'USA-_Sea_shipment'!#REF!),0),"Amazon USA Sea",IFERROR(_xlfn.XLOOKUP(Summary!$D16,Amazon_USA_Sea!$C:$C,Amazon_USA_Sea!$AT:$AT),0),"USA Air",IFERROR(_xlfn.XLOOKUP(Summary!$D16,USA_Air_Shipment!$C:$C,USA_Air_Shipment!$AS:$AS),0),"USA Amazon",IFERROR(_xlfn.XLOOKUP(Summary!$D16,Amazon_USA_Air_Shipment!$C:$C,Amazon_USA_Air_Shipment!$AS:$AS),0),"UK",IFERROR(_xlfn.XLOOKUP(Summary!$D16,UK!$C:$C,UK!$AW:$AW),0),"MENA",IFERROR(_xlfn.XLOOKUP(Summary!$D16,MENA!$C:$C,MENA!$AS:$AS),0),Summary!BB16)} -> 370 | U16: =IF($C$3="All",1,--(Summary!E16=$C$3)) -> 1 | Y16: =IF(Summary!E17="","",Summary!E17) -> A2 Cultured Ghee - 250 ml
B17: {=IF($A17="","",IFERROR(SUMPRODUCT(--($S$3:$S$70=$A17),$O$3:$O$70,$P$3:$P$70,$Q$3:$Q$70,$U$3:$U$70),""))} | C17: {=IF($A17="","",IFERROR(SUMPRODUCT(--($S$3:$S$70=$A17),$T$3:$T$70,$P$3:$P$70,$Q$3:$Q$70,$U$3:$U$70),""))} | D17: =IFERROR(C17/B17,"") | E17: {=IF($A17="","",IFERROR(SUMPRODUCT(--($S$3:$S$70=$A17),--($R$3:$R$70<0),$P$3:$P$70,$Q$3:$Q$70,$U$3:$U$70),""))} | F17: {=IF($A17="","",IFERROR(SUMPRODUCT(--($S$3:$S$70=$A17),--(Summary!$BK$3:$BK$70="P1 – Critical"),$P$3:$P$70,$Q$3:$Q$70,$U$3:$U$70),""))} | H17: =Summary!K2 -> USA Air | I17: =IFERROR(SUMPRODUCT($P$3:$P$70,$U$3:$U$70,INDEX(Summary!$G$3:$N$70,0,ROW()-12)),"") -> 0 | J17: =IFERROR(I17/SUM($I$13:$I$20),"") -> 0 | O17: {=_xlfn.SWITCH($G$3,"MRP (Domestic)",Summary!G17,"ROW Manjari",Summary!H17,"USA Sea",Summary!I17,"Amazon USA Sea",Summary!J17,"USA Air",Summary!K17,"USA Amazon",Summary!L17,"UK",Summary!M17,"MENA",Summary!N17,Summary!O17)} -> 20236.7 | P17: =--(ISNUMBER(Summary!$A17))*--(Summary!$D17<>"") -> 1 | Q17: =IF($G$3="All",1,--(O17>0)) -> 1 | R17: =T17-O17 -> -6541.7 | S17: =IF(Summary!$D17="","",Summary!B17) -> Ghee | T17: {=_xlfn.SWITCH($G$3,"MRP (Domestic)",IFERROR(_xlfn.XLOOKUP(Summary!$D17,Domestic!$C:$C,Domestic!$AU:$AU),0),"ROW Manjari",IFERROR(_xlfn.XLOOKUP(Summary!$D17,'INT-_Manjiri'!$C:$C,'INT-_Manjiri'!$AT:$AT),0),"USA Sea",IFERROR(_xlfn.XLOOKUP(Summary!$D17,'USA-_Sea_shipment'!$C:$C,'USA-_Sea_shipment'!#REF!),0),"Amazon USA Sea",IFERROR(_xlfn.XLOOKUP(Summary!$D17,Amazon_USA_Sea!$C:$C,Amazon_USA_Sea!$AT:$AT),0),"USA Air",IFERROR(_xlfn.XLOOKUP(Summary!$D17,USA_Air_Shipment!$C:$C,USA_Air_Shipment!$AS:$AS),0),"USA Amazon",IFERROR(_xlfn.XLOOKUP(Summary!$D17,Amazon_USA_Air_Shipment!$C:$C,Amazon_USA_Air_Shipment!$AS:$AS),0),"UK",IFERROR(_xlfn.XLOOKUP(Summary!$D17,UK!$C:$C,UK!$AW:$AW),0),"MENA",IFERROR(_xlfn.XLOOKUP(Summary!$D17,MENA!$C:$C,MENA!$AS:$AS),0),Summary!BB17)} -> 13695 | U17: =IF($C$3="All",1,--(Summary!E17=$C$3)) -> 1 | Y17: =IF(Summary!E18="","",Summary!E18) -> A2 Cultured Ghee - 100 ml
B18: {=IF($A18="","",IFERROR(SUMPRODUCT(--($S$3:$S$70=$A18),$O$3:$O$70,$P$3:$P$70,$Q$3:$Q$70,$U$3:$U$70),""))} | C18: {=IF($A18="","",IFERROR(SUMPRODUCT(--($S$3:$S$70=$A18),$T$3:$T$70,$P$3:$P$70,$Q$3:$Q$70,$U$3:$U$70),""))} | D18: =IFERROR(C18/B18,"") | E18: {=IF($A18="","",IFERROR(SUMPRODUCT(--($S$3:$S$70=$A18),--($R$3:$R$70<0),$P$3:$P$70,$Q$3:$Q$70,$U$3:$U$70),""))} | F18: {=IF($A18="","",IFERROR(SUMPRODUCT(--($S$3:$S$70=$A18),--(Summary!$BK$3:$BK$70="P1 – Critical"),$P$3:$P$70,$Q$3:$Q$70,$U$3:$U$70),""))} | H18: =Summary!L2 -> USA Amazon | I18: =IFERROR(SUMPRODUCT($P$3:$P$70,$U$3:$U$70,INDEX(Summary!$G$3:$N$70,0,ROW()-12)),"") -> 735 | J18: =IFERROR(I18/SUM($I$13:$I$20),"") -> 0.0056622721 | O18: {=_xlfn.SWITCH($G$3,"MRP (Domestic)",Summary!G18,"ROW Manjari",Summary!H18,"USA Sea",Summary!I18,"Amazon USA Sea",Summary!J18,"USA Air",Summary!K18,"USA Amazon",Summary!L18,"UK",Summary!M18,"MENA",Summary!N18,Summary!O18)} -> 14077.7 | P18: =--(ISNUMBER(Summary!$A18))*--(Summary!$D18<>"") -> 1 | Q18: =IF($G$3="All",1,--(O18>0)) -> 1 | R18: =T18-O18 -> 836.3 | S18: =IF(Summary!$D18="","",Summary!B18) -> Ghee | T18: {=_xlfn.SWITCH($G$3,"MRP (Domestic)",IFERROR(_xlfn.XLOOKUP(Summary!$D18,Domestic!$C:$C,Domestic!$AU:$AU),0),"ROW Manjari",IFERROR(_xlfn.XLOOKUP(Summary!$D18,'INT-_Manjiri'!$C:$C,'INT-_Manjiri'!$AT:$AT),0),"USA Sea",IFERROR(_xlfn.XLOOKUP(Summary!$D18,'USA-_Sea_shipment'!$C:$C,'USA-_Sea_shipment'!#REF!),0),"Amazon USA Sea",IFERROR(_xlfn.XLOOKUP(Summary!$D18,Amazon_USA_Sea!$C:$C,Amazon_USA_Sea!$AT:$AT),0),"USA Air",IFERROR(_xlfn.XLOOKUP(Summary!$D18,USA_Air_Shipment!$C:$C,USA_Air_Shipment!$AS:$AS),0),"USA Amazon",IFERROR(_xlfn.XLOOKUP(Summary!$D18,Amazon_USA_Air_Shipment!$C:$C,Amazon_USA_Air_Shipment!$AS:$AS),0),"UK",IFERROR(_xlfn.XLOOKUP(Summary!$D18,UK!$C:$C,UK!$AW:$AW),0),"MENA",IFERROR(_xlfn.XLOOKUP(Summary!$D18,MENA!$C:$C,MENA!$AS:$AS),0),Summary!BB18)} -> 14914 | U18: =IF($C$3="All",1,--(Summary!E18=$C$3)) -> 1 | Y18: =IF(Summary!E19="","",Summary!E19) -> A2 Cultured Ghee - 1000 ml
H19: =Summary!M2 -> UK | I19: =IFERROR(SUMPRODUCT($P$3:$P$70,$U$3:$U$70,INDEX(Summary!$G$3:$N$70,0,ROW()-12)),"") -> 0 | J19: =IFERROR(I19/SUM($I$13:$I$20),"") -> 0 | O19: {=_xlfn.SWITCH($G$3,"MRP (Domestic)",Summary!G19,"ROW Manjari",Summary!H19,"USA Sea",Summary!I19,"Amazon USA Sea",Summary!J19,"USA Air",Summary!K19,"USA Amazon",Summary!L19,"UK",Summary!M19,"MENA",Summary!N19,Summary!O19)} -> 11040.6 | P19: =--(ISNUMBER(Summary!$A19))*--(Summary!$D19<>"") -> 1 | Q19: =IF($G$3="All",1,--(O19>0)) -> 1 | R19: =T19-O19 -> -3333.6 | S19: =IF(Summary!$D19="","",Summary!B19) -> Ghee | T19: {=_xlfn.SWITCH($G$3,"MRP (Domestic)",IFERROR(_xlfn.XLOOKUP(Summary!$D19,Domestic!$C:$C,Domestic!$AU:$AU),0),"ROW Manjari",IFERROR(_xlfn.XLOOKUP(Summary!$D19,'INT-_Manjiri'!$C:$C,'INT-_Manjiri'!$AT:$AT),0),"USA Sea",IFERROR(_xlfn.XLOOKUP(Summary!$D19,'USA-_Sea_shipment'!$C:$C,'USA-_Sea_shipment'!#REF!),0),"Amazon USA Sea",IFERROR(_xlfn.XLOOKUP(Summary!$D19,Amazon_USA_Sea!$C:$C,Amazon_USA_Sea!$AT:$AT),0),"USA Air",IFERROR(_xlfn.XLOOKUP(Summary!$D19,USA_Air_Shipment!$C:$C,USA_Air_Shipment!$AS:$AS),0),"USA Amazon",IFERROR(_xlfn.XLOOKUP(Summary!$D19,Amazon_USA_Air_Shipment!$C:$C,Amazon_USA_Air_Shipment!$AS:$AS),0),"UK",IFERROR(_xlfn.XLOOKUP(Summary!$D19,UK!$C:$C,UK!$AW:$AW),0),"MENA",IFERROR(_xlfn.XLOOKUP(Summary!$D19,MENA!$C:$C,MENA!$AS:$AS),0),Summary!BB19)} -> 7707 | U19: =IF($C$3="All",1,--(Summary!E19=$C$3)) -> 1 | Y19: =IF(Summary!E20="","",Summary!E20)
A20: KEY INSIGHTS | H20: =Summary!N2 -> MENA | I20: =IFERROR(SUMPRODUCT($P$3:$P$70,$U$3:$U$70,INDEX(Summary!$G$3:$N$70,0,ROW()-12)),"") -> 6995 | J20: =IFERROR(I20/SUM($I$13:$I$20),"") -> 0.053887882 | O20: {=_xlfn.SWITCH($G$3,"MRP (Domestic)",Summary!G20,"ROW Manjari",Summary!H20,"USA Sea",Summary!I20,"Amazon USA Sea",Summary!J20,"USA Air",Summary!K20,"USA Amazon",Summary!L20,"UK",Summary!M20,"MENA",Summary!N20,Summary!O20)} -> 129806.55 | P20: =--(ISNUMBER(Summary!$A20))*--(Summary!$D20<>"") -> 0 | Q20: =IF($G$3="All",1,--(O20>0)) -> 1 | R20: =T20-O20 -> -56692.55 | S20: =IF(Summary!$D20="","",Summary!B20) | T20: {=_xlfn.SWITCH($G$3,"MRP (Domestic)",IFERROR(_xlfn.XLOOKUP(Summary!$D20,Domestic!$C:$C,Domestic!$AU:$AU),0),"ROW Manjari",IFERROR(_xlfn.XLOOKUP(Summary!$D20,'INT-_Manjiri'!$C:$C,'INT-_Manjiri'!$AT:$AT),0),"USA Sea",IFERROR(_xlfn.XLOOKUP(Summary!$D20,'USA-_Sea_shipment'!$C:$C,'USA-_Sea_shipment'!#REF!),0),"Amazon USA Sea",IFERROR(_xlfn.XLOOKUP(Summary!$D20,Amazon_USA_Sea!$C:$C,Amazon_USA_Sea!$AT:$AT),0),"USA Air",IFERROR(_xlfn.XLOOKUP(Summary!$D20,USA_Air_Shipment!$C:$C,USA_Air_Shipment!$AS:$AS),0),"USA Amazon",IFERROR(_xlfn.XLOOKUP(Summary!$D20,Amazon_USA_Air_Shipment!$C:$C,Amazon_USA_Air_Shipment!$AS:$AS),0),"UK",IFERROR(_xlfn.XLOOKUP(Summary!$D20,UK!$C:$C,UK!$AW:$AW),0),"MENA",IFERROR(_xlfn.XLOOKUP(Summary!$D20,MENA!$C:$C,MENA!$AS:$AS),0),Summary!BB20)} -> 73114 | U20: =IF($C$3="All",1,--(Summary!E20=$C$3)) -> 1 | Y20: =IF(Summary!E21="","",Summary!E21)
A21: =IF($A$6="","No data for the current selection.","Overall fulfillment "&TEXT($E$6,"0%")&" — "&TEXT($G$6,"#,##0")&" packets pending across "&TEXT($I$6,"#,##0")&" SKUs.") -> Overall fulfillment 56% — 57,529 packets pending across 16 SKUs. | H21: Priority | I21: SKU Count | O21: {=_xlfn.SWITCH($G$3,"MRP (Domestic)",Summary!G21,"ROW Manjari",Summary!H21,"USA Sea",Summary!I21,"Amazon USA Sea",Summary!J21,"USA Air",Summary!K21,"USA Amazon",Summary!L21,"UK",Summary!M21,"MENA",Summary!N21,Summary!O21)} -> 0 | P21: =--(ISNUMBER(Summary!$A21))*--(Summary!$D21<>"") -> 0 | Q21: =IF($G$3="All",1,--(O21>0)) -> 1 | R21: =T21-O21 -> 0 | S21: =IF(Summary!$D21="","",Summary!B21) | T21: {=_xlfn.SWITCH($G$3,"MRP (Domestic)",IFERROR(_xlfn.XLOOKUP(Summary!$D21,Domestic!$C:$C,Domestic!$AU:$AU),0),"ROW Manjari",IFERROR(_xlfn.XLOOKUP(Summary!$D21,'INT-_Manjiri'!$C:$C,'INT-_Manjiri'!$AT:$AT),0),"USA Sea",IFERROR(_xlfn.XLOOKUP(Summary!$D21,'USA-_Sea_shipment'!$C:$C,'USA-_Sea_shipment'!#REF!),0),"Amazon USA Sea",IFERROR(_xlfn.XLOOKUP(Summary!$D21,Amazon_USA_Sea!$C:$C,Amazon_USA_Sea!$AT:$AT),0),"USA Air",IFERROR(_xlfn.XLOOKUP(Summary!$D21,USA_Air_Shipment!$C:$C,USA_Air_Shipment!$AS:$AS),0),"USA Amazon",IFERROR(_xlfn.XLOOKUP(Summary!$D21,Amazon_USA_Air_Shipment!$C:$C,Amazon_USA_Air_Shipment!$AS:$AS),0),"UK",IFERROR(_xlfn.XLOOKUP(Summary!$D21,UK!$C:$C,UK!$AW:$AW),0),"MENA",IFERROR(_xlfn.XLOOKUP(Summary!$D21,MENA!$C:$C,MENA!$AS:$AS),0),Summary!BB21)} -> 0 | U21: =IF($C$3="All",1,--(Summary!E21=$C$3)) -> 1 | Y21: =IF(Summary!E22="","",Summary!E22)
A22: =IF($I$6="","",TEXT($K$6,"#,##0")&" of "&TEXT($I$6,"#,##0")&" pending SKUs are P1–Critical ("&IFERROR(TEXT($K$6/$I$6,"0%"),"0%")&" of pending).") -> 13 of 16 pending SKUs are P1–Critical (81% of pending). | H22: P1 – Critical | I22: {=IFERROR(SUMPRODUCT(--(Summary!$BK$3:$BK$70=$H22),$P$3:$P$70,$Q$3:$Q$70,$U$3:$U$70),"")} -> 13 | O22: {=_xlfn.SWITCH($G$3,"MRP (Domestic)",Summary!G22,"ROW Manjari",Summary!H22,"USA Sea",Summary!I22,"Amazon USA Sea",Summary!J22,"USA Air",Summary!K22,"USA Amazon",Summary!L22,"UK",Summary!M22,"MENA",Summary!N22,Summary!O22)} -> 0 | P22: =--(ISNUMBER(Summary!$A22))*--(Summary!$D22<>"") -> 0 | Q22: =IF($G$3="All",1,--(O22>0)) -> 1 | R22: =T22-O22 -> 0 | S22: =IF(Summary!$D22="","",Summary!B22) | T22: {=_xlfn.SWITCH($G$3,"MRP (Domestic)",IFERROR(_xlfn.XLOOKUP(Summary!$D22,Domestic!$C:$C,Domestic!$AU:$AU),0),"ROW Manjari",IFERROR(_xlfn.XLOOKUP(Summary!$D22,'INT-_Manjiri'!$C:$C,'INT-_Manjiri'!$AT:$AT),0),"USA Sea",IFERROR(_xlfn.XLOOKUP(Summary!$D22,'USA-_Sea_shipment'!$C:$C,'USA-_Sea_shipment'!#REF!),0),"Amazon USA Sea",IFERROR(_xlfn.XLOOKUP(Summary!$D22,Amazon_USA_Sea!$C:$C,Amazon_USA_Sea!$AT:$AT),0),"USA Air",IFERROR(_xlfn.XLOOKUP(Summary!$D22,USA_Air_Shipment!$C:$C,USA_Air_Shipment!$AS:$AS),0),"USA Amazon",IFERROR(_xlfn.XLOOKUP(Summary!$D22,Amazon_USA_Air_Shipment!$C:$C,Amazon_USA_Air_Shipment!$AS:$AS),0),"UK",IFERROR(_xlfn.XLOOKUP(Summary!$D22,UK!$C:$C,UK!$AW:$AW),0),"MENA",IFERROR(_xlfn.XLOOKUP(Summary!$D22,MENA!$C:$C,MENA!$AS:$AS),0),Summary!BB22)} -> 0 | U22: =IF($C$3="All",1,--(Summary!E22=$C$3)) -> 1 | Y22: =IF(Summary!E23="","",Summary!E23)
A23: =IFERROR(IF($A$6="","","Biggest single gap: "&INDEX($D$28:$D$95,MATCH(MIN($G$28:$G$95),$G$28:$G$95,0))&" ("&INDEX($B$28:$B$95,MATCH(MIN($G$28:$G$95),$G$28:$G$95,0))&") — "&TEXT(-MIN($G$28:$G$95),"#,##0")&" pkt pending."),"") -> Biggest single gap: Buffalo Ghee - A2 Cultured 500ml (Ghee) — 18,586 pkt pending. | H23: P2 – High | I23: {=IFERROR(SUMPRODUCT(--(Summary!$BK$3:$BK$70=$H23),$P$3:$P$70,$Q$3:$Q$70,$U$3:$U$70),"")} -> 2 | O23: {=_xlfn.SWITCH($G$3,"MRP (Domestic)",Summary!G23,"ROW Manjari",Summary!H23,"USA Sea",Summary!I23,"Amazon USA Sea",Summary!J23,"USA Air",Summary!K23,"USA Amazon",Summary!L23,"UK",Summary!M23,"MENA",Summary!N23,Summary!O23)} -> 0 | P23: =--(ISNUMBER(Summary!$A23))*--(Summary!$D23<>"") -> 0 | Q23: =IF($G$3="All",1,--(O23>0)) -> 1 | R23: =T23-O23 -> 0 | S23: =IF(Summary!$D23="","",Summary!B23) | T23: {=_xlfn.SWITCH($G$3,"MRP (Domestic)",IFERROR(_xlfn.XLOOKUP(Summary!$D23,Domestic!$C:$C,Domestic!$AU:$AU),0),"ROW Manjari",IFERROR(_xlfn.XLOOKUP(Summary!$D23,'INT-_Manjiri'!$C:$C,'INT-_Manjiri'!$AT:$AT),0),"USA Sea",IFERROR(_xlfn.XLOOKUP(Summary!$D23,'USA-_Sea_shipment'!$C:$C,'USA-_Sea_shipment'!#REF!),0),"Amazon USA Sea",IFERROR(_xlfn.XLOOKUP(Summary!$D23,Amazon_USA_Sea!$C:$C,Amazon_USA_Sea!$AT:$AT),0),"USA Air",IFERROR(_xlfn.XLOOKUP(Summary!$D23,USA_Air_Shipment!$C:$C,USA_Air_Shipment!$AS:$AS),0),"USA Amazon",IFERROR(_xlfn.XLOOKUP(Summary!$D23,Amazon_USA_Air_Shipment!$C:$C,Amazon_USA_Air_Shipment!$AS:$AS),0),"UK",IFERROR(_xlfn.XLOOKUP(Summary!$D23,UK!$C:$C,UK!$AW:$AW),0),"MENA",IFERROR(_xlfn.XLOOKUP(Summary!$D23,MENA!$C:$C,MENA!$AS:$AS),0),Summary!BB23)} -> 0 | U23: =IF($C$3="All",1,--(Summary!E23=$C$3)) -> 1 | Y23: =IF(Summary!E24="","",Summary!E24)
A24: {=IF($A$6="","","Sections at 0% fulfillment: "&TEXT(SUMPRODUCT(--($B$13:$B$18>0),--($C$13:$C$18=0)),"0")&" of "&TEXT(COUNTA($A$13:$A$18),"0")&".")} -> Sections at 0% fulfillment: 0 of 1. | H24: P3 – Normal | I24: {=IFERROR(SUMPRODUCT(--(Summary!$BK$3:$BK$70=$H24),$P$3:$P$70,$Q$3:$Q$70,$U$3:$U$70),"")} -> 2 | O24: {=_xlfn.SWITCH($G$3,"MRP (Domestic)",Summary!G24,"ROW Manjari",Summary!H24,"USA Sea",Summary!I24,"Amazon USA Sea",Summary!J24,"USA Air",Summary!K24,"USA Amazon",Summary!L24,"UK",Summary!M24,"MENA",Summary!N24,Summary!O24)} -> 0 | P24: =--(ISNUMBER(Summary!$A24))*--(Summary!$D24<>"") -> 0 | Q24: =IF($G$3="All",1,--(O24>0)) -> 1 | R24: =T24-O24 -> 0 | S24: =IF(Summary!$D24="","",Summary!B24) | T24: {=_xlfn.SWITCH($G$3,"MRP (Domestic)",IFERROR(_xlfn.XLOOKUP(Summary!$D24,Domestic!$C:$C,Domestic!$AU:$AU),0),"ROW Manjari",IFERROR(_xlfn.XLOOKUP(Summary!$D24,'INT-_Manjiri'!$C:$C,'INT-_Manjiri'!$AT:$AT),0),"USA Sea",IFERROR(_xlfn.XLOOKUP(Summary!$D24,'USA-_Sea_shipment'!$C:$C,'USA-_Sea_shipment'!#REF!),0),"Amazon USA Sea",IFERROR(_xlfn.XLOOKUP(Summary!$D24,Amazon_USA_Sea!$C:$C,Amazon_USA_Sea!$AT:$AT),0),"USA Air",IFERROR(_xlfn.XLOOKUP(Summary!$D24,USA_Air_Shipment!$C:$C,USA_Air_Shipment!$AS:$AS),0),"USA Amazon",IFERROR(_xlfn.XLOOKUP(Summary!$D24,Amazon_USA_Air_Shipment!$C:$C,Amazon_USA_Air_Shipment!$AS:$AS),0),"UK",IFERROR(_xlfn.XLOOKUP(Summary!$D24,UK!$C:$C,UK!$AW:$AW),0),"MENA",IFERROR(_xlfn.XLOOKUP(Summary!$D24,MENA!$C:$C,MENA!$AS:$AS),0),Summary!BB24)} -> 0 | U24: =IF($C$3="All",1,--(Summary!E24=$C$3)) -> 1 | Y24: =IF(Summary!E25="","",Summary!E25)
O25: {=_xlfn.SWITCH($G$3,"MRP (Domestic)",Summary!G25,"ROW Manjari",Summary!H25,"USA Sea",Summary!I25,"Amazon USA Sea",Summary!J25,"USA Air",Summary!K25,"USA Amazon",Summary!L25,"UK",Summary!M25,"MENA",Summary!N25,Summary!O25)} -> 0 | P25: =--(ISNUMBER(Summary!$A25))*--(Summary!$D25<>"") -> 0 | Q25: =IF($G$3="All",1,--(O25>0)) -> 1 | R25: =T25-O25 -> 0 | S25: =IF(Summary!$D25="","",Summary!B25) | T25: {=_xlfn.SWITCH($G$3,"MRP (Domestic)",IFERROR(_xlfn.XLOOKUP(Summary!$D25,Domestic!$C:$C,Domestic!$AU:$AU),0),"ROW Manjari",IFERROR(_xlfn.XLOOKUP(Summary!$D25,'INT-_Manjiri'!$C:$C,'INT-_Manjiri'!$AT:$AT),0),"USA Sea",IFERROR(_xlfn.XLOOKUP(Summary!$D25,'USA-_Sea_shipment'!$C:$C,'USA-_Sea_shipment'!#REF!),0),"Amazon USA Sea",IFERROR(_xlfn.XLOOKUP(Summary!$D25,Amazon_USA_Sea!$C:$C,Amazon_USA_Sea!$AT:$AT),0),"USA Air",IFERROR(_xlfn.XLOOKUP(Summary!$D25,USA_Air_Shipment!$C:$C,USA_Air_Shipment!$AS:$AS),0),"USA Amazon",IFERROR(_xlfn.XLOOKUP(Summary!$D25,Amazon_USA_Air_Shipment!$C:$C,Amazon_USA_Air_Shipment!$AS:$AS),0),"UK",IFERROR(_xlfn.XLOOKUP(Summary!$D25,UK!$C:$C,UK!$AW:$AW),0),"MENA",IFERROR(_xlfn.XLOOKUP(Summary!$D25,MENA!$C:$C,MENA!$AS:$AS),0),Summary!BB25)} -> 0 | U25: =IF($C$3="All",1,--(Summary!E25=$C$3)) -> 1 | Y25: =IF(Summary!E26="","",Summary!E26)
A26: PENDING SKU DETAILS WITH REMARKS | O26: {=_xlfn.SWITCH($G$3,"MRP (Domestic)",Summary!G26,"ROW Manjari",Summary!H26,"USA Sea",Summary!I26,"Amazon USA Sea",Summary!J26,"USA Air",Summary!K26,"USA Amazon",Summary!L26,"UK",Summary!M26,"MENA",Summary!N26,Summary!O26)} -> 0 | P26: =--(ISNUMBER(Summary!$A26))*--(Summary!$D26<>"") -> 0 | Q26: =IF($G$3="All",1,--(O26>0)) -> 1 | R26: =T26-O26 -> 0 | S26: =IF(Summary!$D26="","",Summary!B26) | T26: {=_xlfn.SWITCH($G$3,"MRP (Domestic)",IFERROR(_xlfn.XLOOKUP(Summary!$D26,Domestic!$C:$C,Domestic!$AU:$AU),0),"ROW Manjari",IFERROR(_xlfn.XLOOKUP(Summary!$D26,'INT-_Manjiri'!$C:$C,'INT-_Manjiri'!$AT:$AT),0),"USA Sea",IFERROR(_xlfn.XLOOKUP(Summary!$D26,'USA-_Sea_shipment'!$C:$C,'USA-_Sea_shipment'!#REF!),0),"Amazon USA Sea",IFERROR(_xlfn.XLOOKUP(Summary!$D26,Amazon_USA_Sea!$C:$C,Amazon_USA_Sea!$AT:$AT),0),"USA Air",IFERROR(_xlfn.XLOOKUP(Summary!$D26,USA_Air_Shipment!$C:$C,USA_Air_Shipment!$AS:$AS),0),"USA Amazon",IFERROR(_xlfn.XLOOKUP(Summary!$D26,Amazon_USA_Air_Shipment!$C:$C,Amazon_USA_Air_Shipment!$AS:$AS),0),"UK",IFERROR(_xlfn.XLOOKUP(Summary!$D26,UK!$C:$C,UK!$AW:$AW),0),"MENA",IFERROR(_xlfn.XLOOKUP(Summary!$D26,MENA!$C:$C,MENA!$AS:$AS),0),Summary!BB26)} -> 0 | U26: =IF($C$3="All",1,--(Summary!E26=$C$3)) -> 1 | Y26: =IF(Summary!E27="","",Summary!E27)
A27: Rank | B27: Section | C27: FG Code | D27: Product | E27: Plan | F27: Produced | G27: Pending PKT | H27: Fulfillment | I27: DOH | J27: Risk | K27: Priority | L27: Remark | N27: Row idx | Z27: P1 abs pend | AA27: abs pend
A28: =IF($N28="","",ROW()-27) -> 1 | B28: {=IF($N28="","",INDEX(Summary!$B:$B,$N28))} -> Ghee | C28: {=IF($N28="","",INDEX(Summary!$D:$D,$N28))} -> FG00005 | D28: {=IF($N28="","",INDEX(Summary!$E:$E,$N28))} -> Butter/Makhan - 200 gm | E28: {=IF($N28="","",INDEX($O:$O,$N28))} -> 186 | F28: {=IF($N28="","",INDEX($T:$T,$N28))} -> 0 | G28: {=IF($N28="","",INDEX($R:$R,$N28))} -> -186 | H28: {=IF($N28="","",IFERROR(INDEX($T:$T,$N28)/INDEX($O:$O,$N28),""))} -> 0 | I28: {=IF($N28="","",INDEX(Summary!$BI:$BI,$N28))} -> 0.32258065 | J28: {=IF($N28="","",INDEX(Summary!$BJ:$BJ,$N28))} -> 10 | K28: {=IF($N28="","",INDEX(Summary!$BK:$BK,$N28))} -> P1 – Critical | L28: {=IF($N28="","",INDEX(Summary!$BG:$BG,$N28))} | N28: {=IFERROR(_xlfn.AGGREGATE(15,6,ROW(Summary!$D$3:$D$70)/(($R$3:$R$70<0)*$P$3:$P$70*$Q$3:$Q$70*$U$3:$U$70),ROW()-27),"")} -> 3 | O28: {=_xlfn.SWITCH($G$3,"MRP (Domestic)",Summary!G28,"ROW Manjari",Summary!H28,"USA Sea",Summary!I28,"Amazon USA Sea",Summary!J28,"USA Air",Summary!K28,"USA Amazon",Summary!L28,"UK",Summary!M28,"MENA",Summary!N28,Summary!O28)} -> 0 | P28: =--(ISNUMBER(Summary!$A28))*--(Summary!$D28<>"") -> 0 | Q28: =IF($G$3="All",1,--(O28>0)) -> 1 | R28: =T28-O28 -> 0 | S28: =IF(Summary!$D28="","",Summary!B28) | T28: {=_xlfn.SWITCH($G$3,"MRP (Domestic)",IFERROR(_xlfn.XLOOKUP(Summary!$D28,Domestic!$C:$C,Domestic!$AU:$AU),0),"ROW Manjari",IFERROR(_xlfn.XLOOKUP(Summary!$D28,'INT-_Manjiri'!$C:$C,'INT-_Manjiri'!$AT:$AT),0),"USA Sea",IFERROR(_xlfn.XLOOKUP(Summary!$D28,'USA-_Sea_shipment'!$C:$C,'USA-_Sea_shipment'!#REF!),0),"Amazon USA Sea",IFERROR(_xlfn.XLOOKUP(Summary!$D28,Amazon_USA_Sea!$C:$C,Amazon_USA_Sea!$AT:$AT),0),"USA Air",IFERROR(_xlfn.XLOOKUP(Summary!$D28,USA_Air_Shipment!$C:$C,USA_Air_Shipment!$AS:$AS),0),"USA Amazon",IFERROR(_xlfn.XLOOKUP(Summary!$D28,Amazon_USA_Air_Shipment!$C:$C,Amazon_USA_Air_Shipment!$AS:$AS),0),"UK",IFERROR(_xlfn.XLOOKUP(Summary!$D28,UK!$C:$C,UK!$AW:$AW),0),"MENA",IFERROR(_xlfn.XLOOKUP(Summary!$D28,MENA!$C:$C,MENA!$AS:$AS),0),Summary!BB28)} -> 0 | U28: =IF($C$3="All",1,--(Summary!E28=$C$3)) -> 1 | Y28: =IF(Summary!E29="","",Summary!E29) | Z28: =IF(AND($G28<0,ISNUMBER(SEARCH("P1",$K28))),-$G28,"") -> 186 | AA28: =IF($G28<0,-$G28,"") -> 186
A29: =IF($N29="","",ROW()-27) -> 2 | B29: {=IF($N29="","",INDEX(Summary!$B:$B,$N29))} -> Ghee | C29: {=IF($N29="","",INDEX(Summary!$D:$D,$N29))} -> FG00039 | D29: {=IF($N29="","",INDEX(Summary!$E:$E,$N29))} -> Brahmi Ghee - 250 gm | E29: {=IF($N29="","",INDEX($O:$O,$N29))} -> 253 | F29: {=IF($N29="","",INDEX($T:$T,$N29))} -> 67 | G29: {=IF($N29="","",INDEX($R:$R,$N29))} -> -186 | H29: {=IF($N29="","",IFERROR(INDEX($T:$T,$N29)/INDEX($O:$O,$N29),""))} -> 0.26482213 | I29: {=IF($N29="","",INDEX(Summary!$BI:$BI,$N29))} -> 1.3043478 | J29: {=IF($N29="","",INDEX(Summary!$BJ:$BJ,$N29))} -> 10 | K29: {=IF($N29="","",INDEX(Summary!$BK:$BK,$N29))} -> P1 – Critical | L29: {=IF($N29="","",INDEX(Summary!$BG:$BG,$N29))} -> WIP | N29: {=IFERROR(_xlfn.AGGREGATE(15,6,ROW(Summary!$D$3:$D$70)/(($R$3:$R$70<0)*$P$3:$P$70*$Q$3:$Q$70*$U$3:$U$70),ROW()-27),"")} -> 4 | O29: {=_xlfn.SWITCH($G$3,"MRP (Domestic)",Summary!G29,"ROW Manjari",Summary!H29,"USA Sea",Summary!I29,"Amazon USA Sea",Summary!J29,"USA Air",Summary!K29,"USA Amazon",Summary!L29,"UK",Summary!M29,"MENA",Summary!N29,Summary!O29)} -> 0 | P29: =--(ISNUMBER(Summary!$A29))*--(Summary!$D29<>"") -> 0 | Q29: =IF($G$3="All",1,--(O29>0)) -> 1 | R29: =T29-O29 -> 0 | S29: =IF(Summary!$D29="","",Summary!B29) | T29: {=_xlfn.SWITCH($G$3,"MRP (Domestic)",IFERROR(_xlfn.XLOOKUP(Summary!$D29,Domestic!$C:$C,Domestic!$AU:$AU),0),"ROW Manjari",IFERROR(_xlfn.XLOOKUP(Summary!$D29,'INT-_Manjiri'!$C:$C,'INT-_Manjiri'!$AT:$AT),0),"USA Sea",IFERROR(_xlfn.XLOOKUP(Summary!$D29,'USA-_Sea_shipment'!$C:$C,'USA-_Sea_shipment'!#REF!),0),"Amazon USA Sea",IFERROR(_xlfn.XLOOKUP(Summary!$D29,Amazon_USA_Sea!$C:$C,Amazon_USA_Sea!$AT:$AT),0),"USA Air",IFERROR(_xlfn.XLOOKUP(Summary!$D29,USA_Air_Shipment!$C:$C,USA_Air_Shipment!$AS:$AS),0),"USA Amazon",IFERROR(_xlfn.XLOOKUP(Summary!$D29,Amazon_USA_Air_Shipment!$C:$C,Amazon_USA_Air_Shipment!$AS:$AS),0),"UK",IFERROR(_xlfn.XLOOKUP(Summary!$D29,UK!$C:$C,UK!$AW:$AW),0),"MENA",IFERROR(_xlfn.XLOOKUP(Summary!$D29,MENA!$C:$C,MENA!$AS:$AS),0),Summary!BB29)} -> 0 | U29: =IF($C$3="All",1,--(Summary!E29=$C$3)) -> 1 | Y29: =IF(Summary!E30="","",Summary!E30) | Z29: =IF(AND($G29<0,ISNUMBER(SEARCH("P1",$K29))),-$G29,"") -> 186 | AA29: =IF($G29<0,-$G29,"") -> 186
A30: =IF($N30="","",ROW()-27) -> 3 | B30: {=IF($N30="","",INDEX(Summary!$B:$B,$N30))} -> Ghee | C30: {=IF($N30="","",INDEX(Summary!$D:$D,$N30))} -> FG00596 | D30: {=IF($N30="","",INDEX(Summary!$E:$E,$N30))} -> Tulsi Ghee - 250gm | E30: {=IF($N30="","",INDEX($O:$O,$N30))} -> 75 | F30: {=IF($N30="","",INDEX($T:$T,$N30))} -> 46 | G30: {=IF($N30="","",INDEX($R:$R,$N30))} -> -29 | H30: {=IF($N30="","",IFERROR(INDEX($T:$T,$N30)/INDEX($O:$O,$N30),""))} -> 0.61333333 | I30: {=IF($N30="","",INDEX(Summary!$BI:$BI,$N30))} -> 21.6 | J30: {=IF($N30="","",INDEX(Summary!$BJ:$BJ,$N30))} -> 3 | K30: {=IF($N30="","",INDEX(Summary!$BK:$BK,$N30))} -> P3 – Normal | L30: {=IF($N30="","",INDEX(Summary!$BG:$BG,$N30))} | N30: {=IFERROR(_xlfn.AGGREGATE(15,6,ROW(Summary!$D$3:$D$70)/(($R$3:$R$70<0)*$P$3:$P$70*$Q$3:$Q$70*$U$3:$U$70),ROW()-27),"")} -> 5 | O30: {=_xlfn.SWITCH($G$3,"MRP (Domestic)",Summary!G30,"ROW Manjari",Summary!H30,"USA Sea",Summary!I30,"Amazon USA Sea",Summary!J30,"USA Air",Summary!K30,"USA Amazon",Summary!L30,"UK",Summary!M30,"MENA",Summary!N30,Summary!O30)} -> 0 | P30: =--(ISNUMBER(Summary!$A30))*--(Summary!$D30<>"") -> 0 | Q30: =IF($G$3="All",1,--(O30>0)) -> 1 | R30: =T30-O30 -> 0 | S30: =IF(Summary!$D30="","",Summary!B30) | T30: {=_xlfn.SWITCH($G$3,"MRP (Domestic)",IFERROR(_xlfn.XLOOKUP(Summary!$D30,Domestic!$C:$C,Domestic!$AU:$AU),0),"ROW Manjari",IFERROR(_xlfn.XLOOKUP(Summary!$D30,'INT-_Manjiri'!$C:$C,'INT-_Manjiri'!$AT:$AT),0),"USA Sea",IFERROR(_xlfn.XLOOKUP(Summary!$D30,'USA-_Sea_shipment'!$C:$C,'USA-_Sea_shipment'!#REF!),0),"Amazon USA Sea",IFERROR(_xlfn.XLOOKUP(Summary!$D30,Amazon_USA_Sea!$C:$C,Amazon_USA_Sea!$AT:$AT),0),"USA Air",IFERROR(_xlfn.XLOOKUP(Summary!$D30,USA_Air_Shipment!$C:$C,USA_Air_Shipment!$AS:$AS),0),"USA Amazon",IFERROR(_xlfn.XLOOKUP(Summary!$D30,Amazon_USA_Air_Shipment!$C:$C,Amazon_USA_Air_Shipment!$AS:$AS),0),"UK",IFERROR(_xlfn.XLOOKUP(Summary!$D30,UK!$C:$C,UK!$AW:$AW),0),"MENA",IFERROR(_xlfn.XLOOKUP(Summary!$D30,MENA!$C:$C,MENA!$AS:$AS),0),Summary!BB30)} -> 0 | U30: =IF($C$3="All",1,--(Summary!E30=$C$3)) -> 1 | Y30: =IF(Summary!E31="","",Summary!E31) | Z30: =IF(AND($G30<0,ISNUMBER(SEARCH("P1",$K30))),-$G30,"") | AA30: =IF($G30<0,-$G30,"") -> 29
A31: =IF($N31="","",ROW()-27) -> 4 | B31: {=IF($N31="","",INDEX(Summary!$B:$B,$N31))} -> Ghee | C31: {=IF($N31="","",INDEX(Summary!$D:$D,$N31))} -> FG00227 | D31: {=IF($N31="","",INDEX(Summary!$E:$E,$N31))} -> Shatavari Ghee - 250 gm | E31: {=IF($N31="","",INDEX($O:$O,$N31))} -> 319 | F31: {=IF($N31="","",INDEX($T:$T,$N31))} -> 64 | G31: {=IF($N31="","",INDEX($R:$R,$N31))} -> -255 | H31: {=IF($N31="","",IFERROR(INDEX($T:$T,$N31)/INDEX($O:$O,$N31),""))} -> 0.20062696 | I31: {=IF($N31="","",INDEX(Summary!$BI:$BI,$N31))} -> 4.3260188 | J31: {=IF($N31="","",INDEX(Summary!$BJ:$BJ,$N31))} -> 10 | K31: {=IF($N31="","",INDEX(Summary!$BK:$BK,$N31))} -> P1 – Critical | L31: {=IF($N31="","",INDEX(Summary!$BG:$BG,$N31))} -> WIP | N31: {=IFERROR(_xlfn.AGGREGATE(15,6,ROW(Summary!$D$3:$D$70)/(($R$3:$R$70<0)*$P$3:$P$70*$Q$3:$Q$70*$U$3:$U$70),ROW()-27),"")} -> 6 | O31: {=_xlfn.SWITCH($G$3,"MRP (Domestic)",Summary!G31,"ROW Manjari",Summary!H31,"USA Sea",Summary!I31,"Amazon USA Sea",Summary!J31,"USA Air",Summary!K31,"USA Amazon",Summary!L31,"UK",Summary!M31,"MENA",Summary!N31,Summary!O31)} -> 0 | P31: =--(ISNUMBER(Summary!$A31))*--(Summary!$D31<>"") -> 0 | Q31: =IF($G$3="All",1,--(O31>0)) -> 1 | R31: =T31-O31 -> 0 | S31: =IF(Summary!$D31="","",Summary!B31) | T31: {=_xlfn.SWITCH($G$3,"MRP (Domestic)",IFERROR(_xlfn.XLOOKUP(Summary!$D31,Domestic!$C:$C,Domestic!$AU:$AU),0),"ROW Manjari",IFERROR(_xlfn.XLOOKUP(Summary!$D31,'INT-_Manjiri'!$C:$C,'INT-_Manjiri'!$AT:$AT),0),"USA Sea",IFERROR(_xlfn.XLOOKUP(Summary!$D31,'USA-_Sea_shipment'!$C:$C,'USA-_Sea_shipment'!#REF!),0),"Amazon USA Sea",IFERROR(_xlfn.XLOOKUP(Summary!$D31,Amazon_USA_Sea!$C:$C,Amazon_USA_Sea!$AT:$AT),0),"USA Air",IFERROR(_xlfn.XLOOKUP(Summary!$D31,USA_Air_Shipment!$C:$C,USA_Air_Shipment!$AS:$AS),0),"USA Amazon",IFERROR(_xlfn.XLOOKUP(Summary!$D31,Amazon_USA_Air_Shipment!$C:$C,Amazon_USA_Air_Shipment!$AS:$AS),0),"UK",IFERROR(_xlfn.XLOOKUP(Summary!$D31,UK!$C:$C,UK!$AW:$AW),0),"MENA",IFERROR(_xlfn.XLOOKUP(Summary!$D31,MENA!$C:$C,MENA!$AS:$AS),0),Summary!BB31)} -> 0 | U31: =IF($C$3="All",1,--(Summary!E31=$C$3)) -> 1 | Y31: =IF(Summary!E32="","",Summary!E32) | Z31: =IF(AND($G31<0,ISNUMBER(SEARCH("P1",$K31))),-$G31,"") -> 255 | AA31: =IF($G31<0,-$G31,"") -> 255
A32: =IF($N32="","",ROW()-27) -> 5 | B32: {=IF($N32="","",INDEX(Summary!$B:$B,$N32))} -> Ghee | C32: {=IF($N32="","",INDEX(Summary!$D:$D,$N32))} -> FG00265 | D32: {=IF($N32="","",INDEX(Summary!$E:$E,$N32))} -> Turmeric Ghee 250gm | E32: {=IF($N32="","",INDEX($O:$O,$N32))} -> 149 | F32: {=IF($N32="","",INDEX($T:$T,$N32))} -> 130 | G32: {=IF($N32="","",INDEX($R:$R,$N32))} -> -19 | H32: {=IF($N32="","",IFERROR(INDEX($T:$T,$N32)/INDEX($O:$O,$N32),""))} -> 0.87248322 | I32: {=IF($N32="","",INDEX(Summary!$BI:$BI,$N32))} -> 15.302013 | J32: {=IF($N32="","",INDEX(Summary!$BJ:$BJ,$N32))} -> 5 | K32: {=IF($N32="","",INDEX(Summary!$BK:$BK,$N32))} -> P3 – Normal | L32: {=IF($N32="","",INDEX(Summary!$BG:$BG,$N32))} -> WIP | N32: {=IFERROR(_xlfn.AGGREGATE(15,6,ROW(Summary!$D$3:$D$70)/(($R$3:$R$70<0)*$P$3:$P$70*$Q$3:$Q$70*$U$3:$U$70),ROW()-27),"")} -> 7 | O32: {=_xlfn.SWITCH($G$3,"MRP (Domestic)",Summary!G32,"ROW Manjari",Summary!H32,"USA Sea",Summary!I32,"Amazon USA Sea",Summary!J32,"USA Air",Summary!K32,"USA Amazon",Summary!L32,"UK",Summary!M32,"MENA",Summary!N32,Summary!O32)} -> 0 | P32: =--(ISNUMBER(Summary!$A32))*--(Summary!$D32<>"") -> 0 | Q32: =IF($G$3="All",1,--(O32>0)) -> 1 | R32: =T32-O32 -> 0 | S32: =IF(Summary!$D32="","",Summary!B32) | T32: {=_xlfn.SWITCH($G$3,"MRP (Domestic)",IFERROR(_xlfn.XLOOKUP(Summary!$D32,Domestic!$C:$C,Domestic!$AU:$AU),0),"ROW Manjari",IFERROR(_xlfn.XLOOKUP(Summary!$D32,'INT-_Manjiri'!$C:$C,'INT-_Manjiri'!$AT:$AT),0),"USA Sea",IFERROR(_xlfn.XLOOKUP(Summary!$D32,'USA-_Sea_shipment'!$C:$C,'USA-_Sea_shipment'!#REF!),0),"Amazon USA Sea",IFERROR(_xlfn.XLOOKUP(Summary!$D32,Amazon_USA_Sea!$C:$C,Amazon_USA_Sea!$AT:$AT),0),"USA Air",IFERROR(_xlfn.XLOOKUP(Summary!$D32,USA_Air_Shipment!$C:$C,USA_Air_Shipment!$AS:$AS),0),"USA Amazon",IFERROR(_xlfn.XLOOKUP(Summary!$D32,Amazon_USA_Air_Shipment!$C:$C,Amazon_USA_Air_Shipment!$AS:$AS),0),"UK",IFERROR(_xlfn.XLOOKUP(Summary!$D32,UK!$C:$C,UK!$AW:$AW),0),"MENA",IFERROR(_xlfn.XLOOKUP(Summary!$D32,MENA!$C:$C,MENA!$AS:$AS),0),Summary!BB32)} -> 0 | U32: =IF($C$3="All",1,--(Summary!E32=$C$3)) -> 1 | Y32: =IF(Summary!E33="","",Summary!E33) | Z32: =IF(AND($G32<0,ISNUMBER(SEARCH("P1",$K32))),-$G32,"") | AA32: =IF($G32<0,-$G32,"") -> 19
A33: =IF($N33="","",ROW()-27) -> 6 | B33: {=IF($N33="","",INDEX(Summary!$B:$B,$N33))} -> Ghee | C33: {=IF($N33="","",INDEX(Summary!$D:$D,$N33))} -> FG00043 | D33: {=IF($N33="","",INDEX(Summary!$E:$E,$N33))} -> Buffalo Ghee - A2 Cultured 500ml | E33: {=IF($N33="","",INDEX($O:$O,$N33))} -> 22881 | F33: {=IF($N33="","",INDEX($T:$T,$N33))} -> 4295 | G33: {=IF($N33="","",INDEX($R:$R,$N33))} -> -18586 | H33: {=IF($N33="","",IFERROR(INDEX($T:$T,$N33)/INDEX($O:$O,$N33),""))} -> 0.18771033 | I33: {=IF($N33="","",INDEX(Summary!$BI:$BI,$N33))} -> 1.2770421 | J33: {=IF($N33="","",INDEX(Summary!$BJ:$BJ,$N33))} -> 10 | K33: {=IF($N33="","",INDEX(Summary!$BK:$BK,$N33))} -> P1 – Critical | L33: {=IF($N33="","",INDEX(Summary!$BG:$BG,$N33))} -> WIP | N33: {=IFERROR(_xlfn.AGGREGATE(15,6,ROW(Summary!$D$3:$D$70)/(($R$3:$R$70<0)*$P$3:$P$70*$Q$3:$Q$70*$U$3:$U$70),ROW()-27),"")} -> 8 | O33: {=_xlfn.SWITCH($G$3,"MRP (Domestic)",Summary!G33,"ROW Manjari",Summary!H33,"USA Sea",Summary!I33,"Amazon USA Sea",Summary!J33,"USA Air",Summary!K33,"USA Amazon",Summary!L33,"UK",Summary!M33,"MENA",Summary!N33,Summary!O33)} -> 0 | P33: =--(ISNUMBER(Summary!$A33))*--(Summary!$D33<>"") -> 0 | Q33: =IF($G$3="All",1,--(O33>0)) -> 1 | R33: =T33-O33 -> 0 | S33: =IF(Summary!$D33="","",Summary!B33) | T33: {=_xlfn.SWITCH($G$3,"MRP (Domestic)",IFERROR(_xlfn.XLOOKUP(Summary!$D33,Domestic!$C:$C,Domestic!$AU:$AU),0),"ROW Manjari",IFERROR(_xlfn.XLOOKUP(Summary!$D33,'INT-_Manjiri'!$C:$C,'INT-_Manjiri'!$AT:$AT),0),"USA Sea",IFERROR(_xlfn.XLOOKUP(Summary!$D33,'USA-_Sea_shipment'!$C:$C,'USA-_Sea_shipment'!#REF!),0),"Amazon USA Sea",IFERROR(_xlfn.XLOOKUP(Summary!$D33,Amazon_USA_Sea!$C:$C,Amazon_USA_Sea!$AT:$AT),0),"USA Air",IFERROR(_xlfn.XLOOKUP(Summary!$D33,USA_Air_Shipment!$C:$C,USA_Air_Shipment!$AS:$AS),0),"USA Amazon",IFERROR(_xlfn.XLOOKUP(Summary!$D33,Amazon_USA_Air_Shipment!$C:$C,Amazon_USA_Air_Shipment!$AS:$AS),0),"UK",IFERROR(_xlfn.XLOOKUP(Summary!$D33,UK!$C:$C,UK!$AW:$AW),0),"MENA",IFERROR(_xlfn.XLOOKUP(Summary!$D33,MENA!$C:$C,MENA!$AS:$AS),0),Summary!BB33)} -> 0 | U33: =IF($C$3="All",1,--(Summary!E33=$C$3)) -> 1 | Y33: =IF(Summary!E34="","",Summary!E34) | Z33: =IF(AND($G33<0,ISNUMBER(SEARCH("P1",$K33))),-$G33,"") -> 18586 | AA33: =IF($G33<0,-$G33,"") -> 18586
A34: =IF($N34="","",ROW()-27) -> 7 | B34: {=IF($N34="","",INDEX(Summary!$B:$B,$N34))} -> Ghee | C34: {=IF($N34="","",INDEX(Summary!$D:$D,$N34))} -> FG00904 | D34: {=IF($N34="","",INDEX(Summary!$E:$E,$N34))} -> A2 Desi Cow Ghee - 500ml | E34: {=IF($N34="","",INDEX($O:$O,$N34))} -> 10468.7 | F34: {=IF($N34="","",INDEX($T:$T,$N34))} -> 3381 | G34: {=IF($N34="","",INDEX($R:$R,$N34))} -> -7087.7 | H34: {=IF($N34="","",IFERROR(INDEX($T:$T,$N34)/INDEX($O:$O,$N34),""))} -> 0.32296274 | I34: {=IF($N34="","",INDEX(Summary!$BI:$BI,$N34))} -> 2.504609 | J34: {=IF($N34="","",INDEX(Summary!$BJ:$BJ,$N34))} -> 10 | K34: {=IF($N34="","",INDEX(Summary!$BK:$BK,$N34))} -> P1 – Critical | L34: {=IF($N34="","",INDEX(Summary!$BG:$BG,$N34))} | N34: {=IFERROR(_xlfn.AGGREGATE(15,6,ROW(Summary!$D$3:$D$70)/(($R$3:$R$70<0)*$P$3:$P$70*$Q$3:$Q$70*$U$3:$U$70),ROW()-27),"")} -> 9 | O34: {=_xlfn.SWITCH($G$3,"MRP (Domestic)",Summary!G34,"ROW Manjari",Summary!H34,"USA Sea",Summary!I34,"Amazon USA Sea",Summary!J34,"USA Air",Summary!K34,"USA Amazon",Summary!L34,"UK",Summary!M34,"MENA",Summary!N34,Summary!O34)} -> 0 | P34: =--(ISNUMBER(Summary!$A34))*--(Summary!$D34<>"") -> 0 | Q34: =IF($G$3="All",1,--(O34>0)) -> 1 | R34: =T34-O34 -> 0 | S34: =IF(Summary!$D34="","",Summary!B34) | T34: {=_xlfn.SWITCH($G$3,"MRP (Domestic)",IFERROR(_xlfn.XLOOKUP(Summary!$D34,Domestic!$C:$C,Domestic!$AU:$AU),0),"ROW Manjari",IFERROR(_xlfn.XLOOKUP(Summary!$D34,'INT-_Manjiri'!$C:$C,'INT-_Manjiri'!$AT:$AT),0),"USA Sea",IFERROR(_xlfn.XLOOKUP(Summary!$D34,'USA-_Sea_shipment'!$C:$C,'USA-_Sea_shipment'!#REF!),0),"Amazon USA Sea",IFERROR(_xlfn.XLOOKUP(Summary!$D34,Amazon_USA_Sea!$C:$C,Amazon_USA_Sea!$AT:$AT),0),"USA Air",IFERROR(_xlfn.XLOOKUP(Summary!$D34,USA_Air_Shipment!$C:$C,USA_Air_Shipment!$AS:$AS),0),"USA Amazon",IFERROR(_xlfn.XLOOKUP(Summary!$D34,Amazon_USA_Air_Shipment!$C:$C,Amazon_USA_Air_Shipment!$AS:$AS),0),"UK",IFERROR(_xlfn.XLOOKUP(Summary!$D34,UK!$C:$C,UK!$AW:$AW),0),"MENA",IFERROR(_xlfn.XLOOKUP(Summary!$D34,MENA!$C:$C,MENA!$AS:$AS),0),Summary!BB34)} -> 0 | U34: =IF($C$3="All",1,--(Summary!E34=$C$3)) -> 1 | Y34: =IF(Summary!E35="","",Summary!E35) | Z34: =IF(AND($G34<0,ISNUMBER(SEARCH("P1",$K34))),-$G34,"") -> 7087.7 | AA34: =IF($G34<0,-$G34,"") -> 7087.7
A35: =IF($N35="","",ROW()-27) -> 8 | B35: {=IF($N35="","",INDEX(Summary!$B:$B,$N35))} -> Ghee | C35: {=IF($N35="","",INDEX(Summary!$D:$D,$N35))} -> FG00052 | D35: {=IF($N35="","",INDEX(Summary!$E:$E,$N35))} -> Colostrum Powder, Desi Gir Cow - 100 gm | E35: {=IF($N35="","",INDEX($O:$O,$N35))} -> 1712 | F35: {=IF($N35="","",INDEX($T:$T,$N35))} -> 913 | G35: {=IF($N35="","",INDEX($R:$R,$N35))} -> -799 | H35: {=IF($N35="","",IFERROR(INDEX($T:$T,$N35)/INDEX($O:$O,$N35),""))} -> 0.53329439 | I35: {=IF($N35="","",INDEX(Summary!$BI:$BI,$N35))} -> 2.0327103 | J35: {=IF($N35="","",INDEX(Summary!$BJ:$BJ,$N35))} -> 10 | K35: {=IF($N35="","",INDEX(Summary!$BK:$BK,$N35))} -> P1 – Critical | L35: {=IF($N35="","",INDEX(Summary!$BG:$BG,$N35))} | N35: {=IFERROR(_xlfn.AGGREGATE(15,6,ROW(Summary!$D$3:$D$70)/(($R$3:$R$70<0)*$P$3:$P$70*$Q$3:$Q$70*$U$3:$U$70),ROW()-27),"")} -> 10 | O35: {=_xlfn.SWITCH($G$3,"MRP (Domestic)",Summary!G35,"ROW Manjari",Summary!H35,"USA Sea",Summary!I35,"Amazon USA Sea",Summary!J35,"USA Air",Summary!K35,"USA Amazon",Summary!L35,"UK",Summary!M35,"MENA",Summary!N35,Summary!O35)} -> 0 | P35: =--(ISNUMBER(Summary!$A35))*--(Summary!$D35<>"") -> 0 | Q35: =IF($G$3="All",1,--(O35>0)) -> 1 | R35: =T35-O35 -> 0 | S35: =IF(Summary!$D35="","",Summary!B35) | T35: {=_xlfn.SWITCH($G$3,"MRP (Domestic)",IFERROR(_xlfn.XLOOKUP(Summary!$D35,Domestic!$C:$C,Domestic!$AU:$AU),0),"ROW Manjari",IFERROR(_xlfn.XLOOKUP(Summary!$D35,'INT-_Manjiri'!$C:$C,'INT-_Manjiri'!$AT:$AT),0),"USA Sea",IFERROR(_xlfn.XLOOKUP(Summary!$D35,'USA-_Sea_shipment'!$C:$C,'USA-_Sea_shipment'!#REF!),0),"Amazon USA Sea",IFERROR(_xlfn.XLOOKUP(Summary!$D35,Amazon_USA_Sea!$C:$C,Amazon_USA_Sea!$AT:$AT),0),"USA Air",IFERROR(_xlfn.XLOOKUP(Summary!$D35,USA_Air_Shipment!$C:$C,USA_Air_Shipment!$AS:$AS),0),"USA Amazon",IFERROR(_xlfn.XLOOKUP(Summary!$D35,Amazon_USA_Air_Shipment!$C:$C,Amazon_USA_Air_Shipment!$AS:$AS),0),"UK",IFERROR(_xlfn.XLOOKUP(Summary!$D35,UK!$C:$C,UK!$AW:$AW),0),"MENA",IFERROR(_xlfn.XLOOKUP(Summary!$D35,MENA!$C:$C,MENA!$AS:$AS),0),Summary!BB35)} -> 0 | U35: =IF($C$3="All",1,--(Summary!E35=$C$3)) -> 1 | Y35: =IF(Summary!E36="","",Summary!E36) | Z35: =IF(AND($G35<0,ISNUMBER(SEARCH("P1",$K35))),-$G35,"") -> 799 | AA35: =IF($G35<0,-$G35,"") -> 799
A36: =IF($N36="","",ROW()-27) -> 9 | B36: {=IF($N36="","",INDEX(Summary!$B:$B,$N36))} -> Ghee | C36: {=IF($N36="","",INDEX(Summary!$D:$D,$N36))} -> FG00097 | D36: {=IF($N36="","",INDEX(Summary!$E:$E,$N36))} -> Full Moon Cultured Ghee - 500 ml | E36: {=IF($N36="","",INDEX($O:$O,$N36))} -> 3303.3 | F36: {=IF($N36="","",INDEX($T:$T,$N36))} -> 1602 | G36: {=IF($N36="","",INDEX($R:$R,$N36))} -> -1701.3 | H36: {=IF($N36="","",IFERROR(INDEX($T:$T,$N36)/INDEX($O:$O,$N36),""))} -> 0.48496958 | I36: {=IF($N36="","",INDEX(Summary!$BI:$BI,$N36))} -> 8.0737444 | J36: {=IF($N36="","",INDEX(Summary!$BJ:$BJ,$N36))} -> 7 | K36: {=IF($N36="","",INDEX(Summary!$BK:$BK,$N36))} -> P2 – High | L36: {=IF($N36="","",INDEX(Summary!$BG:$BG,$N36))} -> WIP | N36: {=IFERROR(_xlfn.AGGREGATE(15,6,ROW(Summary!$D$3:$D$70)/(($R$3:$R$70<0)*$P$3:$P$70*$Q$3:$Q$70*$U$3:$U$70),ROW()-27),"")} -> 11 | O36: {=_xlfn.SWITCH($G$3,"MRP (Domestic)",Summary!G36,"ROW Manjari",Summary!H36,"USA Sea",Summary!I36,"Amazon USA Sea",Summary!J36,"USA Air",Summary!K36,"USA Amazon",Summary!L36,"UK",Summary!M36,"MENA",Summary!N36,Summary!O36)} -> 0 | P36: =--(ISNUMBER(Summary!$A36))*--(Summary!$D36<>"") -> 0 | Q36: =IF($G$3="All",1,--(O36>0)) -> 1 | R36: =T36-O36 -> 0 | S36: =IF(Summary!$D36="","",Summary!B36) | T36: {=_xlfn.SWITCH($G$3,"MRP (Domestic)",IFERROR(_xlfn.XLOOKUP(Summary!$D36,Domestic!$C:$C,Domestic!$AU:$AU),0),"ROW Manjari",IFERROR(_xlfn.XLOOKUP(Summary!$D36,'INT-_Manjiri'!$C:$C,'INT-_Manjiri'!$AT:$AT),0),"USA Sea",IFERROR(_xlfn.XLOOKUP(Summary!$D36,'USA-_Sea_shipment'!$C:$C,'USA-_Sea_shipment'!#REF!),0),"Amazon USA Sea",IFERROR(_xlfn.XLOOKUP(Summary!$D36,Amazon_USA_Sea!$C:$C,Amazon_USA_Sea!$AT:$AT),0),"USA Air",IFERROR(_xlfn.XLOOKUP(Summary!$D36,USA_Air_Shipment!$C:$C,USA_Air_Shipment!$AS:$AS),0),"USA Amazon",IFERROR(_xlfn.XLOOKUP(Summary!$D36,Amazon_USA_Air_Shipment!$C:$C,Amazon_USA_Air_Shipment!$AS:$AS),0),"UK",IFERROR(_xlfn.XLOOKUP(Summary!$D36,UK!$C:$C,UK!$AW:$AW),0),"MENA",IFERROR(_xlfn.XLOOKUP(Summary!$D36,MENA!$C:$C,MENA!$AS:$AS),0),Summary!BB36)} -> 0 | U36: =IF($C$3="All",1,--(Summary!E36=$C$3)) -> 1 | Y36: =IF(Summary!E37="","",Summary!E37) | Z36: =IF(AND($G36<0,ISNUMBER(SEARCH("P1",$K36))),-$G36,"") | AA36: =IF($G36<0,-$G36,"") -> 1701.3
