Workbook

Sheet BI_Data
A1: FGCode | B1: Product | C1: Section | D1: Plant | E1: UOM | F1: Priority | G1: PriorityRank | H1: IsCritical | I1: DOHBucket | J1: FillRateBucket | K1: Remark | L1: Date | M1: DayIndex | N1: DayOfMonth | O1: MonthLabel | P1: IsElapsed | Q1: DailyProducedPKT | R1: EvenPaceTargetPKT | S1: IsSKURow | T1: PlanPKT | U1: ProducedPKT | V1: PendingPKT | W1: SOHCentralWH | X1: DOH | Y1: PlanMRPDomestic | Z1: PlanROWManjari | AA1: PlanUSASea | AB1: PlanAmazonUSASea | AC1: PlanUSAAir | AD1: PlanUSAAmazon | AE1: PlanUK | AF1: PlanMENA | AG1: RiskScore | AH1: SrcRow
A2: {=IFERROR(INDEX(Summary!$D:$D,$AH2)&"","")} -> FG00724 | B2: {=IF($A2="","",INDEX(Summary!$E:$E,$AH2))} -> Khapli Atta 1KG | C2: {=IF($A2="","",INDEX(Summary!$B:$B,$AH2))} -> Atta | D2: {=IF($A2="","",INDEX(Summary!$C:$C,$AH2))} -> C39 | E2: {=IF($A2="","",INDEX(Summary!$F:$F,$AH2))} -> 1 | F2: {=IF($A2="","",INDEX(Summary!$BC:$BC,$AH2)&"")} -> P2 – High | G2: =IF($A2="","",VALUE(LEFT(SUBSTITUTE($F2,"P",""),1))) -> 2 | H2: =IF($A2="","",IF(LEFT($F2,2)="P1",1,0)) -> 0 | I2: {=IF($A2="","",IF(IFERROR(INDEX(Summary!$BA:$BA,$AH2),0)<1,"Under 1 day",IF(INDEX(Summary!$BA:$BA,$AH2)<3,"1-3 days",IF(INDEX(Summary!$BA:$BA,$AH2)<7,"3-7 days","7+ days"))))} -> 7+ days | J2: {=IF($A2="","",IF(IFERROR(INDEX(Summary!$AX:$AX,$AH2),0)<0.25,"0-25%",IF(INDEX(Summary!$AX:$AX,$AH2)<0.5,"25-50%",IF(INDEX(Summary!$AX:$AX,$AH2)<0.75,"50-75%","75-100%"))))} -> 75-100% | K2: {=IF($A2="","",INDEX(Summary!$AY:$AY,$AH2)&"")} | L2: =IF($A2="","",Summary!$P$2+MOD(ROW()-2,30)) -> 46227 | M2: =IF($A2="","",MOD(ROW()-2,30)+1) -> 1 | N2: =IF($A2="","",DAY($L2)) -> 24 | O2: =IF($A2="","",TEXT($L2,"mmm-yyyy")) -> Jul-2026 | P2: =IF($A2="","",IF($L2<=TODAY(),1,0)) -> 1 | Q2: {=IF($A2="",0,IFERROR(INDEX(Summary!$P$3:$AS$67,$AH2-2,$M2),0))} -> 0 | R2: {=IF($A2="",0,ROUND(IFERROR(INDEX(Summary!$O:$O,$AH2),0)/30,0))} -> 200 | S2: =IF($A2="",0,IF($M2=1,1,0)) -> 1 | T2: {=IF($S2=1,IFERROR(INDEX(Summary!$O:$O,$AH2),0),0)} -> 6000 | U2: {=IF($S2=1,IFERROR(INDEX(Summary!$AT:$AT,$AH2),0),0)} -> 6271 | V2: =IF($S2=1,MAX(0,$T2-$U2),0) -> 0 | W2: {=IF($S2=1,IFERROR(INDEX(Summary!$AZ:$AZ,$AH2),0),0)} -> 1586 | X2: {=IF($S2=1,IFERROR(INDEX(Summary!$BA:$BA,$AH2),0),0)} -> 7.93 | Y2: {=IF($S2=1,IFERROR(INDEX(Summary!$G:$G,$AH2),0),0)} -> 0 | Z2: {=IF($S2=1,IFERROR(INDEX(Summary!$H:$H,$AH2),0),0)} -> 0 | AA2: {=IF($S2=1,IFERROR(INDEX(Summary!$I:$I,$AH2),0),0)} -> 0 | AB2: {=IF($S2=1,IFERROR(INDEX(Summary!$J:$J,$AH2),0),0)} -> 0 | AC2: {=IF($S2=1,IFERROR(INDEX(Summary!$K:$K,$AH2),0),0)} -> 6000 | AD2: {=IF($S2=1,IFERROR(INDEX(Summary!$L:$L,$AH2),0),0)} -> 0 | AE2: {=IF($S2=1,IFERROR(INDEX(Summary!$M:$M,$AH2),0),0)} -> 0 | AF2: {=IF($S2=1,IFERROR(INDEX(Summary!$N:$N,$AH2),0),0)} -> 0 | AG2: {=IF($A2="","",IFERROR(INDEX(Summary!$BB:$BB,$AH2),0))} -> 7 | AH2: =INT((ROW()-2)/30)+3 -> 3
A3: {=IFERROR(INDEX(Summary!$D:$D,$AH3)&"","")} -> FG00724 | B3: {=IF($A3="","",INDEX(Summary!$E:$E,$AH3))} -> Khapli Atta 1KG | C3: {=IF($A3="","",INDEX(Summary!$B:$B,$AH3))} -> Atta | D3: {=IF($A3="","",INDEX(Summary!$C:$C,$AH3))} -> C39 | E3: {=IF($A3="","",INDEX(Summary!$F:$F,$AH3))} -> 1 | F3: {=IF($A3="","",INDEX(Summary!$BC:$BC,$AH3)&"")} -> P2 – High | G3: =IF($A3="","",VALUE(LEFT(SUBSTITUTE($F3,"P",""),1))) -> 2 | H3: =IF($A3="","",IF(LEFT($F3,2)="P1",1,0)) -> 0 | I3: {=IF($A3="","",IF(IFERROR(INDEX(Summary!$BA:$BA,$AH3),0)<1,"Under 1 day",IF(INDEX(Summary!$BA:$BA,$AH3)<3,"1-3 days",IF(INDEX(Summary!$BA:$BA,$AH3)<7,"3-7 days","7+ days"))))} -> 7+ days | J3: {=IF($A3="","",IF(IFERROR(INDEX(Summary!$AX:$AX,$AH3),0)<0.25,"0-25%",IF(INDEX(Summary!$AX:$AX,$AH3)<0.5,"25-50%",IF(INDEX(Summary!$AX:$AX,$AH3)<0.75,"50-75%","75-100%"))))} -> 75-100% | K3: {=IF($A3="","",INDEX(Summary!$AY:$AY,$AH3)&"")} | L3: =IF($A3="","",Summary!$P$2+MOD(ROW()-2,30)) -> 46228 | M3: =IF($A3="","",MOD(ROW()-2,30)+1) -> 2 | N3: =IF($A3="","",DAY($L3)) -> 25 | O3: =IF($A3="","",TEXT($L3,"mmm-yyyy")) -> Jul-2026 | P3: =IF($A3="","",IF($L3<=TODAY(),1,0)) -> 1 | Q3: {=IF($A3="",0,IFERROR(INDEX(Summary!$P$3:$AS$67,$AH3-2,$M3),0))} -> 0 | R3: {=IF($A3="",0,ROUND(IFERROR(INDEX(Summary!$O:$O,$AH3),0)/30,0))} -> 200 | S3: =IF($A3="",0,IF($M3=1,1,0)) -> 0 | T3: {=IF($S3=1,IFERROR(INDEX(Summary!$O:$O,$AH3),0),0)} -> 0 | U3: {=IF($S3=1,IFERROR(INDEX(Summary!$AT:$AT,$AH3),0),0)} -> 0 | V3: =IF($S3=1,MAX(0,$T3-$U3),0) -> 0 | W3: {=IF($S3=1,IFERROR(INDEX(Summary!$AZ:$AZ,$AH3),0),0)} -> 0 | X3: {=IF($S3=1,IFERROR(INDEX(Summary!$BA:$BA,$AH3),0),0)} -> 0 | Y3: {=IF($S3=1,IFERROR(INDEX(Summary!$G:$G,$AH3),0),0)} -> 0 | Z3: {=IF($S3=1,IFERROR(INDEX(Summary!$H:$H,$AH3),0),0)} -> 0 | AA3: {=IF($S3=1,IFERROR(INDEX(Summary!$I:$I,$AH3),0),0)} -> 0 | AB3: {=IF($S3=1,IFERROR(INDEX(Summary!$J:$J,$AH3),0),0)} -> 0 | AC3: {=IF($S3=1,IFERROR(INDEX(Summary!$K:$K,$AH3),0),0)} -> 0 | AD3: {=IF($S3=1,IFERROR(INDEX(Summary!$L:$L,$AH3),0),0)} -> 0 | AE3: {=IF($S3=1,IFERROR(INDEX(Summary!$M:$M,$AH3),0),0)} -> 0 | AF3: {=IF($S3=1,IFERROR(INDEX(Summary!$N:$N,$AH3),0),0)} -> 0 | AG3: {=IF($A3="","",IFERROR(INDEX(Summary!$BB:$BB,$AH3),0))} -> 7 | AH3: =INT((ROW()-2)/30)+3 -> 3
A4: {=IFERROR(INDEX(Summary!$D:$D,$AH4)&"","")} -> FG00724 | B4: {=IF($A4="","",INDEX(Summary!$E:$E,$AH4))} -> Khapli Atta 1KG | C4: {=IF($A4="","",INDEX(Summary!$B:$B,$AH4))} -> Atta | D4: {=IF($A4="","",INDEX(Summary!$C:$C,$AH4))} -> C39 | E4: {=IF($A4="","",INDEX(Summary!$F:$F,$AH4))} -> 1 | F4: {=IF($A4="","",INDEX(Summary!$BC:$BC,$AH4)&"")} -> P2 – High | G4: =IF($A4="","",VALUE(LEFT(SUBSTITUTE($F4,"P",""),1))) -> 2 | H4: =IF($A4="","",IF(LEFT($F4,2)="P1",1,0)) -> 0 | I4: {=IF($A4="","",IF(IFERROR(INDEX(Summary!$BA:$BA,$AH4),0)<1,"Under 1 day",IF(INDEX(Summary!$BA:$BA,$AH4)<3,"1-3 days",IF(INDEX(Summary!$BA:$BA,$AH4)<7,"3-7 days","7+ days"))))} -> 7+ days | J4: {=IF($A4="","",IF(IFERROR(INDEX(Summary!$AX:$AX,$AH4),0)<0.25,"0-25%",IF(INDEX(Summary!$AX:$AX,$AH4)<0.5,"25-50%",IF(INDEX(Summary!$AX:$AX,$AH4)<0.75,"50-75%","75-100%"))))} -> 75-100% | K4: {=IF($A4="","",INDEX(Summary!$AY:$AY,$AH4)&"")} | L4: =IF($A4="","",Summary!$P$2+MOD(ROW()-2,30)) -> 46229 | M4: =IF($A4="","",MOD(ROW()-2,30)+1) -> 3 | N4: =IF($A4="","",DAY($L4)) -> 26 | O4: =IF($A4="","",TEXT($L4,"mmm-yyyy")) -> Jul-2026 | P4: =IF($A4="","",IF($L4<=TODAY(),1,0)) -> 1 | Q4: {=IF($A4="",0,IFERROR(INDEX(Summary!$P$3:$AS$67,$AH4-2,$M4),0))} -> 0 | R4: {=IF($A4="",0,ROUND(IFERROR(INDEX(Summary!$O:$O,$AH4),0)/30,0))} -> 200 | S4: =IF($A4="",0,IF($M4=1,1,0)) -> 0 | T4: {=IF($S4=1,IFERROR(INDEX(Summary!$O:$O,$AH4),0),0)} -> 0 | U4: {=IF($S4=1,IFERROR(INDEX(Summary!$AT:$AT,$AH4),0),0)} -> 0 | V4: =IF($S4=1,MAX(0,$T4-$U4),0) -> 0 | W4: {=IF($S4=1,IFERROR(INDEX(Summary!$AZ:$AZ,$AH4),0),0)} -> 0 | X4: {=IF($S4=1,IFERROR(INDEX(Summary!$BA:$BA,$AH4),0),0)} -> 0 | Y4: {=IF($S4=1,IFERROR(INDEX(Summary!$G:$G,$AH4),0),0)} -> 0 | Z4: {=IF($S4=1,IFERROR(INDEX(Summary!$H:$H,$AH4),0),0)} -> 0 | AA4: {=IF($S4=1,IFERROR(INDEX(Summary!$I:$I,$AH4),0),0)} -> 0 | AB4: {=IF($S4=1,IFERROR(INDEX(Summary!$J:$J,$AH4),0),0)} -> 0 | AC4: {=IF($S4=1,IFERROR(INDEX(Summary!$K:$K,$AH4),0),0)} -> 0 | AD4: {=IF($S4=1,IFERROR(INDEX(Summary!$L:$L,$AH4),0),0)} -> 0 | AE4: {=IF($S4=1,IFERROR(INDEX(Summary!$M:$M,$AH4),0),0)} -> 0 | AF4: {=IF($S4=1,IFERROR(INDEX(Summary!$N:$N,$AH4),0),0)} -> 0 | AG4: {=IF($A4="","",IFERROR(INDEX(Summary!$BB:$BB,$AH4),0))} -> 7 | AH4: =INT((ROW()-2)/30)+3 -> 3
A5: {=IFERROR(INDEX(Summary!$D:$D,$AH5)&"","")} -> FG00724 | B5: {=IF($A5="","",INDEX(Summary!$E:$E,$AH5))} -> Khapli Atta 1KG | C5: {=IF($A5="","",INDEX(Summary!$B:$B,$AH5))} -> Atta | D5: {=IF($A5="","",INDEX(Summary!$C:$C,$AH5))} -> C39 | E5: {=IF($A5="","",INDEX(Summary!$F:$F,$AH5))} -> 1 | F5: {=IF($A5="","",INDEX(Summary!$BC:$BC,$AH5)&"")} -> P2 – High | G5: =IF($A5="","",VALUE(LEFT(SUBSTITUTE($F5,"P",""),1))) -> 2 | H5: =IF($A5="","",IF(LEFT($F5,2)="P1",1,0)) -> 0 | I5: {=IF($A5="","",IF(IFERROR(INDEX(Summary!$BA:$BA,$AH5),0)<1,"Under 1 day",IF(INDEX(Summary!$BA:$BA,$AH5)<3,"1-3 days",IF(INDEX(Summary!$BA:$BA,$AH5)<7,"3-7 days","7+ days"))))} -> 7+ days | J5: {=IF($A5="","",IF(IFERROR(INDEX(Summary!$AX:$AX,$AH5),0)<0.25,"0-25%",IF(INDEX(Summary!$AX:$AX,$AH5)<0.5,"25-50%",IF(INDEX(Summary!$AX:$AX,$AH5)<0.75,"50-75%","75-100%"))))} -> 75-100% | K5: {=IF($A5="","",INDEX(Summary!$AY:$AY,$AH5)&"")} | L5: =IF($A5="","",Summary!$P$2+MOD(ROW()-2,30)) -> 46230 | M5: =IF($A5="","",MOD(ROW()-2,30)+1) -> 4 | N5: =IF($A5="","",DAY($L5)) -> 27 | O5: =IF($A5="","",TEXT($L5,"mmm-yyyy")) -> Jul-2026 | P5: =IF($A5="","",IF($L5<=TODAY(),1,0)) -> 1 | Q5: {=IF($A5="",0,IFERROR(INDEX(Summary!$P$3:$AS$67,$AH5-2,$M5),0))} -> 0 | R5: {=IF($A5="",0,ROUND(IFERROR(INDEX(Summary!$O:$O,$AH5),0)/30,0))} -> 200 | S5: =IF($A5="",0,IF($M5=1,1,0)) -> 0 | T5: {=IF($S5=1,IFERROR(INDEX(Summary!$O:$O,$AH5),0),0)} -> 0 | U5: {=IF($S5=1,IFERROR(INDEX(Summary!$AT:$AT,$AH5),0),0)} -> 0 | V5: =IF($S5=1,MAX(0,$T5-$U5),0) -> 0 | W5: {=IF($S5=1,IFERROR(INDEX(Summary!$AZ:$AZ,$AH5),0),0)} -> 0 | X5: {=IF($S5=1,IFERROR(INDEX(Summary!$BA:$BA,$AH5),0),0)} -> 0 | Y5: {=IF($S5=1,IFERROR(INDEX(Summary!$G:$G,$AH5),0),0)} -> 0 | Z5: {=IF($S5=1,IFERROR(INDEX(Summary!$H:$H,$AH5),0),0)} -> 0 | AA5: {=IF($S5=1,IFERROR(INDEX(Summary!$I:$I,$AH5),0),0)} -> 0 | AB5: {=IF($S5=1,IFERROR(INDEX(Summary!$J:$J,$AH5),0),0)} -> 0 | AC5: {=IF($S5=1,IFERROR(INDEX(Summary!$K:$K,$AH5),0),0)} -> 0 | AD5: {=IF($S5=1,IFERROR(INDEX(Summary!$L:$L,$AH5),0),0)} -> 0 | AE5: {=IF($S5=1,IFERROR(INDEX(Summary!$M:$M,$AH5),0),0)} -> 0 | AF5: {=IF($S5=1,IFERROR(INDEX(Summary!$N:$N,$AH5),0),0)} -> 0 | AG5: {=IF($A5="","",IFERROR(INDEX(Summary!$BB:$BB,$AH5),0))} -> 7 | AH5: =INT((ROW()-2)/30)+3 -> 3
A6: {=IFERROR(INDEX(Summary!$D:$D,$AH6)&"","")} -> FG00724 | B6: {=IF($A6="","",INDEX(Summary!$E:$E,$AH6))} -> Khapli Atta 1KG | C6: {=IF($A6="","",INDEX(Summary!$B:$B,$AH6))} -> Atta | D6: {=IF($A6="","",INDEX(Summary!$C:$C,$AH6))} -> C39 | E6: {=IF($A6="","",INDEX(Summary!$F:$F,$AH6))} -> 1 | F6: {=IF($A6="","",INDEX(Summary!$BC:$BC,$AH6)&"")} -> P2 – High | G6: =IF($A6="","",VALUE(LEFT(SUBSTITUTE($F6,"P",""),1))) -> 2 | H6: =IF($A6="","",IF(LEFT($F6,2)="P1",1,0)) -> 0 | I6: {=IF($A6="","",IF(IFERROR(INDEX(Summary!$BA:$BA,$AH6),0)<1,"Under 1 day",IF(INDEX(Summary!$BA:$BA,$AH6)<3,"1-3 days",IF(INDEX(Summary!$BA:$BA,$AH6)<7,"3-7 days","7+ days"))))} -> 7+ days | J6: {=IF($A6="","",IF(IFERROR(INDEX(Summary!$AX:$AX,$AH6),0)<0.25,"0-25%",IF(INDEX(Summary!$AX:$AX,$AH6)<0.5,"25-50%",IF(INDEX(Summary!$AX:$AX,$AH6)<0.75,"50-75%","75-100%"))))} -> 75-100% | K6: {=IF($A6="","",INDEX(Summary!$AY:$AY,$AH6)&"")} | L6: =IF($A6="","",Summary!$P$2+MOD(ROW()-2,30)) -> 46231 | M6: =IF($A6="","",MOD(ROW()-2,30)+1) -> 5 | N6: =IF($A6="","",DAY($L6)) -> 28 | O6: =IF($A6="","",TEXT($L6,"mmm-yyyy")) -> Jul-2026 | P6: =IF($A6="","",IF($L6<=TODAY(),1,0)) -> 1 | Q6: {=IF($A6="",0,IFERROR(INDEX(Summary!$P$3:$AS$67,$AH6-2,$M6),0))} -> 0 | R6: {=IF($A6="",0,ROUND(IFERROR(INDEX(Summary!$O:$O,$AH6),0)/30,0))} -> 200 | S6: =IF($A6="",0,IF($M6=1,1,0)) -> 0 | T6: {=IF($S6=1,IFERROR(INDEX(Summary!$O:$O,$AH6),0),0)} -> 0 | U6: {=IF($S6=1,IFERROR(INDEX(Summary!$AT:$AT,$AH6),0),0)} -> 0 | V6: =IF($S6=1,MAX(0,$T6-$U6),0) -> 0 | W6: {=IF($S6=1,IFERROR(INDEX(Summary!$AZ:$AZ,$AH6),0),0)} -> 0 | X6: {=IF($S6=1,IFERROR(INDEX(Summary!$BA:$BA,$AH6),0),0)} -> 0 | Y6: {=IF($S6=1,IFERROR(INDEX(Summary!$G:$G,$AH6),0),0)} -> 0 | Z6: {=IF($S6=1,IFERROR(INDEX(Summary!$H:$H,$AH6),0),0)} -> 0 | AA6: {=IF($S6=1,IFERROR(INDEX(Summary!$I:$I,$AH6),0),0)} -> 0 | AB6: {=IF($S6=1,IFERROR(INDEX(Summary!$J:$J,$AH6),0),0)} -> 0 | AC6: {=IF($S6=1,IFERROR(INDEX(Summary!$K:$K,$AH6),0),0)} -> 0 | AD6: {=IF($S6=1,IFERROR(INDEX(Summary!$L:$L,$AH6),0),0)} -> 0 | AE6: {=IF($S6=1,IFERROR(INDEX(Summary!$M:$M,$AH6),0),0)} -> 0 | AF6: {=IF($S6=1,IFERROR(INDEX(Summary!$N:$N,$AH6),0),0)} -> 0 | AG6: {=IF($A6="","",IFERROR(INDEX(Summary!$BB:$BB,$AH6),0))} -> 7 | AH6: =INT((ROW()-2)/30)+3 -> 3
A7: {=IFERROR(INDEX(Summary!$D:$D,$AH7)&"","")} -> FG00724 | B7: {=IF($A7="","",INDEX(Summary!$E:$E,$AH7))} -> Khapli Atta 1KG | C7: {=IF($A7="","",INDEX(Summary!$B:$B,$AH7))} -> Atta | D7: {=IF($A7="","",INDEX(Summary!$C:$C,$AH7))} -> C39 | E7: {=IF($A7="","",INDEX(Summary!$F:$F,$AH7))} -> 1 | F7: {=IF($A7="","",INDEX(Summary!$BC:$BC,$AH7)&"")} -> P2 – High | G7: =IF($A7="","",VALUE(LEFT(SUBSTITUTE($F7,"P",""),1))) -> 2 | H7: =IF($A7="","",IF(LEFT($F7,2)="P1",1,0)) -> 0 | I7: {=IF($A7="","",IF(IFERROR(INDEX(Summary!$BA:$BA,$AH7),0)<1,"Under 1 day",IF(INDEX(Summary!$BA:$BA,$AH7)<3,"1-3 days",IF(INDEX(Summary!$BA:$BA,$AH7)<7,"3-7 days","7+ days"))))} -> 7+ days | J7: {=IF($A7="","",IF(IFERROR(INDEX(Summary!$AX:$AX,$AH7),0)<0.25,"0-25%",IF(INDEX(Summary!$AX:$AX,$AH7)<0.5,"25-50%",IF(INDEX(Summary!$AX:$AX,$AH7)<0.75,"50-75%","75-100%"))))} -> 75-100% | K7: {=IF($A7="","",INDEX(Summary!$AY:$AY,$AH7)&"")} | L7: =IF($A7="","",Summary!$P$2+MOD(ROW()-2,30)) -> 46232 | M7: =IF($A7="","",MOD(ROW()-2,30)+1) -> 6 | N7: =IF($A7="","",DAY($L7)) -> 29 | O7: =IF($A7="","",TEXT($L7,"mmm-yyyy")) -> Jul-2026 | P7: =IF($A7="","",IF($L7<=TODAY(),1,0)) -> 1 | Q7: {=IF($A7="",0,IFERROR(INDEX(Summary!$P$3:$AS$67,$AH7-2,$M7),0))} -> 0 | R7: {=IF($A7="",0,ROUND(IFERROR(INDEX(Summary!$O:$O,$AH7),0)/30,0))} -> 200 | S7: =IF($A7="",0,IF($M7=1,1,0)) -> 0 | T7: {=IF($S7=1,IFERROR(INDEX(Summary!$O:$O,$AH7),0),0)} -> 0 | U7: {=IF($S7=1,IFERROR(INDEX(Summary!$AT:$AT,$AH7),0),0)} -> 0 | V7: =IF($S7=1,MAX(0,$T7-$U7),0) -> 0 | W7: {=IF($S7=1,IFERROR(INDEX(Summary!$AZ:$AZ,$AH7),0),0)} -> 0 | X7: {=IF($S7=1,IFERROR(INDEX(Summary!$BA:$BA,$AH7),0),0)} -> 0 | Y7: {=IF($S7=1,IFERROR(INDEX(Summary!$G:$G,$AH7),0),0)} -> 0 | Z7: {=IF($S7=1,IFERROR(INDEX(Summary!$H:$H,$AH7),0),0)} -> 0 | AA7: {=IF($S7=1,IFERROR(INDEX(Summary!$I:$I,$AH7),0),0)} -> 0 | AB7: {=IF($S7=1,IFERROR(INDEX(Summary!$J:$J,$AH7),0),0)} -> 0 | AC7: {=IF($S7=1,IFERROR(INDEX(Summary!$K:$K,$AH7),0),0)} -> 0 | AD7: {=IF($S7=1,IFERROR(INDEX(Summary!$L:$L,$AH7),0),0)} -> 0 | AE7: {=IF($S7=1,IFERROR(INDEX(Summary!$M:$M,$AH7),0),0)} -> 0 | AF7: {=IF($S7=1,IFERROR(INDEX(Summary!$N:$N,$AH7),0),0)} -> 0 | AG7: {=IF($A7="","",IFERROR(INDEX(Summary!$BB:$BB,$AH7),0))} -> 7 | AH7: =INT((ROW()-2)/30)+3 -> 3
A8: {=IFERROR(INDEX(Summary!$D:$D,$AH8)&"","")} -> FG00724 | B8: {=IF($A8="","",INDEX(Summary!$E:$E,$AH8))} -> Khapli Atta 1KG | C8: {=IF($A8="","",INDEX(Summary!$B:$B,$AH8))} -> Atta | D8: {=IF($A8="","",INDEX(Summary!$C:$C,$AH8))} -> C39 | E8: {=IF($A8="","",INDEX(Summary!$F:$F,$AH8))} -> 1 | F8: {=IF($A8="","",INDEX(Summary!$BC:$BC,$AH8)&"")} -> P2 – High | G8: =IF($A8="","",VALUE(LEFT(SUBSTITUTE($F8,"P",""),1))) -> 2 | H8: =IF($A8="","",IF(LEFT($F8,2)="P1",1,0)) -> 0 | I8: {=IF($A8="","",IF(IFERROR(INDEX(Summary!$BA:$BA,$AH8),0)<1,"Under 1 day",IF(INDEX(Summary!$BA:$BA,$AH8)<3,"1-3 days",IF(INDEX(Summary!$BA:$BA,$AH8)<7,"3-7 days","7+ days"))))} -> 7+ days | J8: {=IF($A8="","",IF(IFERROR(INDEX(Summary!$AX:$AX,$AH8),0)<0.25,"0-25%",IF(INDEX(Summary!$AX:$AX,$AH8)<0.5,"25-50%",IF(INDEX(Summary!$AX:$AX,$AH8)<0.75,"50-75%","75-100%"))))} -> 75-100% | K8: {=IF($A8="","",INDEX(Summary!$AY:$AY,$AH8)&"")} | L8: =IF($A8="","",Summary!$P$2+MOD(ROW()-2,30)) -> 46233 | M8: =IF($A8="","",MOD(ROW()-2,30)+1) -> 7 | N8: =IF($A8="","",DAY($L8)) -> 30 | O8: =IF($A8="","",TEXT($L8,"mmm-yyyy")) -> Jul-2026 | P8: =IF($A8="","",IF($L8<=TODAY(),1,0)) -> 1 | Q8: {=IF($A8="",0,IFERROR(INDEX(Summary!$P$3:$AS$67,$AH8-2,$M8),0))} -> 0 | R8: {=IF($A8="",0,ROUND(IFERROR(INDEX(Summary!$O:$O,$AH8),0)/30,0))} -> 200 | S8: =IF($A8="",0,IF($M8=1,1,0)) -> 0 | T8: {=IF($S8=1,IFERROR(INDEX(Summary!$O:$O,$AH8),0),0)} -> 0 | U8: {=IF($S8=1,IFERROR(INDEX(Summary!$AT:$AT,$AH8),0),0)} -> 0 | V8: =IF($S8=1,MAX(0,$T8-$U8),0) -> 0 | W8: {=IF($S8=1,IFERROR(INDEX(Summary!$AZ:$AZ,$AH8),0),0)} -> 0 | X8: {=IF($S8=1,IFERROR(INDEX(Summary!$BA:$BA,$AH8),0),0)} -> 0 | Y8: {=IF($S8=1,IFERROR(INDEX(Summary!$G:$G,$AH8),0),0)} -> 0 | Z8: {=IF($S8=1,IFERROR(INDEX(Summary!$H:$H,$AH8),0),0)} -> 0 | AA8: {=IF($S8=1,IFERROR(INDEX(Summary!$I:$I,$AH8),0),0)} -> 0 | AB8: {=IF($S8=1,IFERROR(INDEX(Summary!$J:$J,$AH8),0),0)} -> 0 | AC8: {=IF($S8=1,IFERROR(INDEX(Summary!$K:$K,$AH8),0),0)} -> 0 | AD8: {=IF($S8=1,IFERROR(INDEX(Summary!$L:$L,$AH8),0),0)} -> 0 | AE8: {=IF($S8=1,IFERROR(INDEX(Summary!$M:$M,$AH8),0),0)} -> 0 | AF8: {=IF($S8=1,IFERROR(INDEX(Summary!$N:$N,$AH8),0),0)} -> 0 | AG8: {=IF($A8="","",IFERROR(INDEX(Summary!$BB:$BB,$AH8),0))} -> 7 | AH8: =INT((ROW()-2)/30)+3 -> 3
A9: {=IFERROR(INDEX(Summary!$D:$D,$AH9)&"","")} -> FG00724 | B9: {=IF($A9="","",INDEX(Summary!$E:$E,$AH9))} -> Khapli Atta 1KG | C9: {=IF($A9="","",INDEX(Summary!$B:$B,$AH9))} -> Atta | D9: {=IF($A9="","",INDEX(Summary!$C:$C,$AH9))} -> C39 | E9: {=IF($A9="","",INDEX(Summary!$F:$F,$AH9))} -> 1 | F9: {=IF($A9="","",INDEX(Summary!$BC:$BC,$AH9)&"")} -> P2 – High | G9: =IF($A9="","",VALUE(LEFT(SUBSTITUTE($F9,"P",""),1))) -> 2 | H9: =IF($A9="","",IF(LEFT($F9,2)="P1",1,0)) -> 0 | I9: {=IF($A9="","",IF(IFERROR(INDEX(Summary!$BA:$BA,$AH9),0)<1,"Under 1 day",IF(INDEX(Summary!$BA:$BA,$AH9)<3,"1-3 days",IF(INDEX(Summary!$BA:$BA,$AH9)<7,"3-7 days","7+ days"))))} -> 7+ days | J9: {=IF($A9="","",IF(IFERROR(INDEX(Summary!$AX:$AX,$AH9),0)<0.25,"0-25%",IF(INDEX(Summary!$AX:$AX,$AH9)<0.5,"25-50%",IF(INDEX(Summary!$AX:$AX,$AH9)<0.75,"50-75%","75-100%"))))} -> 75-100% | K9: {=IF($A9="","",INDEX(Summary!$AY:$AY,$AH9)&"")} | L9: =IF($A9="","",Summary!$P$2+MOD(ROW()-2,30)) -> 46234 | M9: =IF($A9="","",MOD(ROW()-2,30)+1) -> 8 | N9: =IF($A9="","",DAY($L9)) -> 31 | O9: =IF($A9="","",TEXT($L9,"mmm-yyyy")) -> Jul-2026 | P9: =IF($A9="","",IF($L9<=TODAY(),1,0)) -> 1 | Q9: {=IF($A9="",0,IFERROR(INDEX(Summary!$P$3:$AS$67,$AH9-2,$M9),0))} -> 0 | R9: {=IF($A9="",0,ROUND(IFERROR(INDEX(Summary!$O:$O,$AH9),0)/30,0))} -> 200 | S9: =IF($A9="",0,IF($M9=1,1,0)) -> 0 | T9: {=IF($S9=1,IFERROR(INDEX(Summary!$O:$O,$AH9),0),0)} -> 0 | U9: {=IF($S9=1,IFERROR(INDEX(Summary!$AT:$AT,$AH9),0),0)} -> 0 | V9: =IF($S9=1,MAX(0,$T9-$U9),0) -> 0 | W9: {=IF($S9=1,IFERROR(INDEX(Summary!$AZ:$AZ,$AH9),0),0)} -> 0 | X9: {=IF($S9=1,IFERROR(INDEX(Summary!$BA:$BA,$AH9),0),0)} -> 0 | Y9: {=IF($S9=1,IFERROR(INDEX(Summary!$G:$G,$AH9),0),0)} -> 0 | Z9: {=IF($S9=1,IFERROR(INDEX(Summary!$H:$H,$AH9),0),0)} -> 0 | AA9: {=IF($S9=1,IFERROR(INDEX(Summary!$I:$I,$AH9),0),0)} -> 0 | AB9: {=IF($S9=1,IFERROR(INDEX(Summary!$J:$J,$AH9),0),0)} -> 0 | AC9: {=IF($S9=1,IFERROR(INDEX(Summary!$K:$K,$AH9),0),0)} -> 0 | AD9: {=IF($S9=1,IFERROR(INDEX(Summary!$L:$L,$AH9),0),0)} -> 0 | AE9: {=IF($S9=1,IFERROR(INDEX(Summary!$M:$M,$AH9),0),0)} -> 0 | AF9: {=IF($S9=1,IFERROR(INDEX(Summary!$N:$N,$AH9),0),0)} -> 0 | AG9: {=IF($A9="","",IFERROR(INDEX(Summary!$BB:$BB,$AH9),0))} -> 7 | AH9: =INT((ROW()-2)/30)+3 -> 3
A10: {=IFERROR(INDEX(Summary!$D:$D,$AH10)&"","")} -> FG00724 | B10: {=IF($A10="","",INDEX(Summary!$E:$E,$AH10))} -> Khapli Atta 1KG | C10: {=IF($A10="","",INDEX(Summary!$B:$B,$AH10))} -> Atta | D10: {=IF($A10="","",INDEX(Summary!$C:$C,$AH10))} -> C39 | E10: {=IF($A10="","",INDEX(Summary!$F:$F,$AH10))} -> 1 | F10: {=IF($A10="","",INDEX(Summary!$BC:$BC,$AH10)&"")} -> P2 – High | G10: =IF($A10="","",VALUE(LEFT(SUBSTITUTE($F10,"P",""),1))) -> 2 | H10: =IF($A10="","",IF(LEFT($F10,2)="P1",1,0)) -> 0 | I10: {=IF($A10="","",IF(IFERROR(INDEX(Summary!$BA:$BA,$AH10),0)<1,"Under 1 day",IF(INDEX(Summary!$BA:$BA,$AH10)<3,"1-3 days",IF(INDEX(Summary!$BA:$BA,$AH10)<7,"3-7 days","7+ days"))))} -> 7+ days | J10: {=IF($A10="","",IF(IFERROR(INDEX(Summary!$AX:$AX,$AH10),0)<0.25,"0-25%",IF(INDEX(Summary!$AX:$AX,$AH10)<0.5,"25-50%",IF(INDEX(Summary!$AX:$AX,$AH10)<0.75,"50-75%","75-100%"))))} -> 75-100% | K10: {=IF($A10="","",INDEX(Summary!$AY:$AY,$AH10)&"")} | L10: =IF($A10="","",Summary!$P$2+MOD(ROW()-2,30)) -> 46235 | M10: =IF($A10="","",MOD(ROW()-2,30)+1) -> 9 | N10: =IF($A10="","",DAY($L10)) -> 1 | O10: =IF($A10="","",TEXT($L10,"mmm-yyyy")) -> Aug-2026 | P10: =IF($A10="","",IF($L10<=TODAY(),1,0)) -> 1 | Q10: {=IF($A10="",0,IFERROR(INDEX(Summary!$P$3:$AS$67,$AH10-2,$M10),0))} -> 0 | R10: {=IF($A10="",0,ROUND(IFERROR(INDEX(Summary!$O:$O,$AH10),0)/30,0))} -> 200 | S10: =IF($A10="",0,IF($M10=1,1,0)) -> 0 | T10: {=IF($S10=1,IFERROR(INDEX(Summary!$O:$O,$AH10),0),0)} -> 0 | U10: {=IF($S10=1,IFERROR(INDEX(Summary!$AT:$AT,$AH10),0),0)} -> 0 | V10: =IF($S10=1,MAX(0,$T10-$U10),0) -> 0 | W10: {=IF($S10=1,IFERROR(INDEX(Summary!$AZ:$AZ,$AH10),0),0)} -> 0 | X10: {=IF($S10=1,IFERROR(INDEX(Summary!$BA:$BA,$AH10),0),0)} -> 0 | Y10: {=IF($S10=1,IFERROR(INDEX(Summary!$G:$G,$AH10),0),0)} -> 0 | Z10: {=IF($S10=1,IFERROR(INDEX(Summary!$H:$H,$AH10),0),0)} -> 0 | AA10: {=IF($S10=1,IFERROR(INDEX(Summary!$I:$I,$AH10),0),0)} -> 0 | AB10: {=IF($S10=1,IFERROR(INDEX(Summary!$J:$J,$AH10),0),0)} -> 0 | AC10: {=IF($S10=1,IFERROR(INDEX(Summary!$K:$K,$AH10),0),0)} -> 0 | AD10: {=IF($S10=1,IFERROR(INDEX(Summary!$L:$L,$AH10),0),0)} -> 0 | AE10: {=IF($S10=1,IFERROR(INDEX(Summary!$M:$M,$AH10),0),0)} -> 0 | AF10: {=IF($S10=1,IFERROR(INDEX(Summary!$N:$N,$AH10),0),0)} -> 0 | AG10: {=IF($A10="","",IFERROR(INDEX(Summary!$BB:$BB,$AH10),0))} -> 7 | AH10: =INT((ROW()-2)/30)+3 -> 3
A11: {=IFERROR(INDEX(Summary!$D:$D,$AH11)&"","")} -> FG00724 | B11: {=IF($A11="","",INDEX(Summary!$E:$E,$AH11))} -> Khapli Atta 1KG | C11: {=IF($A11="","",INDEX(Summary!$B:$B,$AH11))} -> Atta | D11: {=IF($A11="","",INDEX(Summary!$C:$C,$AH11))} -> C39 | E11: {=IF($A11="","",INDEX(Summary!$F:$F,$AH11))} -> 1 | F11: {=IF($A11="","",INDEX(Summary!$BC:$BC,$AH11)&"")} -> P2 – High | G11: =IF($A11="","",VALUE(LEFT(SUBSTITUTE($F11,"P",""),1))) -> 2 | H11: =IF($A11="","",IF(LEFT($F11,2)="P1",1,0)) -> 0 | I11: {=IF($A11="","",IF(IFERROR(INDEX(Summary!$BA:$BA,$AH11),0)<1,"Under 1 day",IF(INDEX(Summary!$BA:$BA,$AH11)<3,"1-3 days",IF(INDEX(Summary!$BA:$BA,$AH11)<7,"3-7 days","7+ days"))))} -> 7+ days | J11: {=IF($A11="","",IF(IFERROR(INDEX(Summary!$AX:$AX,$AH11),0)<0.25,"0-25%",IF(INDEX(Summary!$AX:$AX,$AH11)<0.5,"25-50%",IF(INDEX(Summary!$AX:$AX,$AH11)<0.75,"50-75%","75-100%"))))} -> 75-100% | K11: {=IF($A11="","",INDEX(Summary!$AY:$AY,$AH11)&"")} | L11: =IF($A11="","",Summary!$P$2+MOD(ROW()-2,30)) -> 46236 | M11: =IF($A11="","",MOD(ROW()-2,30)+1) -> 10 | N11: =IF($A11="","",DAY($L11)) -> 2 | O11: =IF($A11="","",TEXT($L11,"mmm-yyyy")) -> Aug-2026 | P11: =IF($A11="","",IF($L11<=TODAY(),1,0)) -> 1 | Q11: {=IF($A11="",0,IFERROR(INDEX(Summary!$P$3:$AS$67,$AH11-2,$M11),0))} -> 0 | R11: {=IF($A11="",0,ROUND(IFERROR(INDEX(Summary!$O:$O,$AH11),0)/30,0))} -> 200 | S11: =IF($A11="",0,IF($M11=1,1,0)) -> 0 | T11: {=IF($S11=1,IFERROR(INDEX(Summary!$O:$O,$AH11),0),0)} -> 0 | U11: {=IF($S11=1,IFERROR(INDEX(Summary!$AT:$AT,$AH11),0),0)} -> 0 | V11: =IF($S11=1,MAX(0,$T11-$U11),0) -> 0 | W11: {=IF($S11=1,IFERROR(INDEX(Summary!$AZ:$AZ,$AH11),0),0)} -> 0 | X11: {=IF($S11=1,IFERROR(INDEX(Summary!$BA:$BA,$AH11),0),0)} -> 0 | Y11: {=IF($S11=1,IFERROR(INDEX(Summary!$G:$G,$AH11),0),0)} -> 0 | Z11: {=IF($S11=1,IFERROR(INDEX(Summary!$H:$H,$AH11),0),0)} -> 0 | AA11: {=IF($S11=1,IFERROR(INDEX(Summary!$I:$I,$AH11),0),0)} -> 0 | AB11: {=IF($S11=1,IFERROR(INDEX(Summary!$J:$J,$AH11),0),0)} -> 0 | AC11: {=IF($S11=1,IFERROR(INDEX(Summary!$K:$K,$AH11),0),0)} -> 0 | AD11: {=IF($S11=1,IFERROR(INDEX(Summary!$L:$L,$AH11),0),0)} -> 0 | AE11: {=IF($S11=1,IFERROR(INDEX(Summary!$M:$M,$AH11),0),0)} -> 0 | AF11: {=IF($S11=1,IFERROR(INDEX(Summary!$N:$N,$AH11),0),0)} -> 0 | AG11: {=IF($A11="","",IFERROR(INDEX(Summary!$BB:$BB,$AH11),0))} -> 7 | AH11: =INT((ROW()-2)/30)+3 -> 3
A12: {=IFERROR(INDEX(Summary!$D:$D,$AH12)&"","")} -> FG00724 | B12: {=IF($A12="","",INDEX(Summary!$E:$E,$AH12))} -> Khapli Atta 1KG | C12: {=IF($A12="","",INDEX(Summary!$B:$B,$AH12))} -> Atta | D12: {=IF($A12="","",INDEX(Summary!$C:$C,$AH12))} -> C39 | E12: {=IF($A12="","",INDEX(Summary!$F:$F,$AH12))} -> 1 | F12: {=IF($A12="","",INDEX(Summary!$BC:$BC,$AH12)&"")} -> P2 – High | G12: =IF($A12="","",VALUE(LEFT(SUBSTITUTE($F12,"P",""),1))) -> 2 | H12: =IF($A12="","",IF(LEFT($F12,2)="P1",1,0)) -> 0 | I12: {=IF($A12="","",IF(IFERROR(INDEX(Summary!$BA:$BA,$AH12),0)<1,"Under 1 day",IF(INDEX(Summary!$BA:$BA,$AH12)<3,"1-3 days",IF(INDEX(Summary!$BA:$BA,$AH12)<7,"3-7 days","7+ days"))))} -> 7+ days | J12: {=IF($A12="","",IF(IFERROR(INDEX(Summary!$AX:$AX,$AH12),0)<0.25,"0-25%",IF(INDEX(Summary!$AX:$AX,$AH12)<0.5,"25-50%",IF(INDEX(Summary!$AX:$AX,$AH12)<0.75,"50-75%","75-100%"))))} -> 75-100% | K12: {=IF($A12="","",INDEX(Summary!$AY:$AY,$AH12)&"")} | L12: =IF($A12="","",Summary!$P$2+MOD(ROW()-2,30)) -> 46237 | M12: =IF($A12="","",MOD(ROW()-2,30)+1) -> 11 | N12: =IF($A12="","",DAY($L12)) -> 3 | O12: =IF($A12="","",TEXT($L12,"mmm-yyyy")) -> Aug-2026 | P12: =IF($A12="","",IF($L12<=TODAY(),1,0)) -> 1 | Q12: {=IF($A12="",0,IFERROR(INDEX(Summary!$P$3:$AS$67,$AH12-2,$M12),0))} -> 0 | R12: {=IF($A12="",0,ROUND(IFERROR(INDEX(Summary!$O:$O,$AH12),0)/30,0))} -> 200 | S12: =IF($A12="",0,IF($M12=1,1,0)) -> 0 | T12: {=IF($S12=1,IFERROR(INDEX(Summary!$O:$O,$AH12),0),0)} -> 0 | U12: {=IF($S12=1,IFERROR(INDEX(Summary!$AT:$AT,$AH12),0),0)} -> 0 | V12: =IF($S12=1,MAX(0,$T12-$U12),0) -> 0 | W12: {=IF($S12=1,IFERROR(INDEX(Summary!$AZ:$AZ,$AH12),0),0)} -> 0 | X12: {=IF($S12=1,IFERROR(INDEX(Summary!$BA:$BA,$AH12),0),0)} -> 0 | Y12: {=IF($S12=1,IFERROR(INDEX(Summary!$G:$G,$AH12),0),0)} -> 0 | Z12: {=IF($S12=1,IFERROR(INDEX(Summary!$H:$H,$AH12),0),0)} -> 0 | AA12: {=IF($S12=1,IFERROR(INDEX(Summary!$I:$I,$AH12),0),0)} -> 0 | AB12: {=IF($S12=1,IFERROR(INDEX(Summary!$J:$J,$AH12),0),0)} -> 0 | AC12: {=IF($S12=1,IFERROR(INDEX(Summary!$K:$K,$AH12),0),0)} -> 0 | AD12: {=IF($S12=1,IFERROR(INDEX(Summary!$L:$L,$AH12),0),0)} -> 0 | AE12: {=IF($S12=1,IFERROR(INDEX(Summary!$M:$M,$AH12),0),0)} -> 0 | AF12: {=IF($S12=1,IFERROR(INDEX(Summary!$N:$N,$AH12),0),0)} -> 0 | AG12: {=IF($A12="","",IFERROR(INDEX(Summary!$BB:$BB,$AH12),0))} -> 7 | AH12: =INT((ROW()-2)/30)+3 -> 3
A13: {=IFERROR(INDEX(Summary!$D:$D,$AH13)&"","")} -> FG00724 | B13: {=IF($A13="","",INDEX(Summary!$E:$E,$AH13))} -> Khapli Atta 1KG | C13: {=IF($A13="","",INDEX(Summary!$B:$B,$AH13))} -> Atta | D13: {=IF($A13="","",INDEX(Summary!$C:$C,$AH13))} -> C39 | E13: {=IF($A13="","",INDEX(Summary!$F:$F,$AH13))} -> 1 | F13: {=IF($A13="","",INDEX(Summary!$BC:$BC,$AH13)&"")} -> P2 – High | G13: =IF($A13="","",VALUE(LEFT(SUBSTITUTE($F13,"P",""),1))) -> 2 | H13: =IF($A13="","",IF(LEFT($F13,2)="P1",1,0)) -> 0 | I13: {=IF($A13="","",IF(IFERROR(INDEX(Summary!$BA:$BA,$AH13),0)<1,"Under 1 day",IF(INDEX(Summary!$BA:$BA,$AH13)<3,"1-3 days",IF(INDEX(Summary!$BA:$BA,$AH13)<7,"3-7 days","7+ days"))))} -> 7+ days | J13: {=IF($A13="","",IF(IFERROR(INDEX(Summary!$AX:$AX,$AH13),0)<0.25,"0-25%",IF(INDEX(Summary!$AX:$AX,$AH13)<0.5,"25-50%",IF(INDEX(Summary!$AX:$AX,$AH13)<0.75,"50-75%","75-100%"))))} -> 75-100% | K13: {=IF($A13="","",INDEX(Summary!$AY:$AY,$AH13)&"")} | L13: =IF($A13="","",Summary!$P$2+MOD(ROW()-2,30)) -> 46238 | M13: =IF($A13="","",MOD(ROW()-2,30)+1) -> 12 | N13: =IF($A13="","",DAY($L13)) -> 4 | O13: =IF($A13="","",TEXT($L13,"mmm-yyyy")) -> Aug-2026 | P13: =IF($A13="","",IF($L13<=TODAY(),1,0)) -> 1 | Q13: {=IF($A13="",0,IFERROR(INDEX(Summary!$P$3:$AS$67,$AH13-2,$M13),0))} -> 0 | R13: {=IF($A13="",0,ROUND(IFERROR(INDEX(Summary!$O:$O,$AH13),0)/30,0))} -> 200 | S13: =IF($A13="",0,IF($M13=1,1,0)) -> 0 | T13: {=IF($S13=1,IFERROR(INDEX(Summary!$O:$O,$AH13),0),0)} -> 0 | U13: {=IF($S13=1,IFERROR(INDEX(Summary!$AT:$AT,$AH13),0),0)} -> 0 | V13: =IF($S13=1,MAX(0,$T13-$U13),0) -> 0 | W13: {=IF($S13=1,IFERROR(INDEX(Summary!$AZ:$AZ,$AH13),0),0)} -> 0 | X13: {=IF($S13=1,IFERROR(INDEX(Summary!$BA:$BA,$AH13),0),0)} -> 0 | Y13: {=IF($S13=1,IFERROR(INDEX(Summary!$G:$G,$AH13),0),0)} -> 0 | Z13: {=IF($S13=1,IFERROR(INDEX(Summary!$H:$H,$AH13),0),0)} -> 0 | AA13: {=IF($S13=1,IFERROR(INDEX(Summary!$I:$I,$AH13),0),0)} -> 0 | AB13: {=IF($S13=1,IFERROR(INDEX(Summary!$J:$J,$AH13),0),0)} -> 0 | AC13: {=IF($S13=1,IFERROR(INDEX(Summary!$K:$K,$AH13),0),0)} -> 0 | AD13: {=IF($S13=1,IFERROR(INDEX(Summary!$L:$L,$AH13),0),0)} -> 0 | AE13: {=IF($S13=1,IFERROR(INDEX(Summary!$M:$M,$AH13),0),0)} -> 0 | AF13: {=IF($S13=1,IFERROR(INDEX(Summary!$N:$N,$AH13),0),0)} -> 0 | AG13: {=IF($A13="","",IFERROR(INDEX(Summary!$BB:$BB,$AH13),0))} -> 7 | AH13: =INT((ROW()-2)/30)+3 -> 3
... A1801: {=IFERROR(INDEX(Summary!$D:$D,$AH1801)&"","")} -> FG00678 | B1801: {=IF($A1801="","",INDEX(Summary!$E:$E,$AH1801))} -> Virgin Coconut Oil - 100ml - Units | C1801: {=IF($A1801="","",INDEX(Summary!$B:$B,$AH1801))} -> Oil | D1801: {=IF($A1801="","",INDEX(Summary!$C:$C,$AH1801))} -> C6 | E1801: {=IF($A1801="","",INDEX(Summary!$F:$F,$AH1801))} -> 0.1 | F1801: {=IF($A1801="","",INDEX(Summary!$BC:$BC,$AH1801)&"")} | G1801: =IF($A1801="","",VALUE(LEFT(SUBSTITUTE($F1801,"P",""),1))) -> #VALUE! | H1801: =IF($A1801="","",IF(LEFT($F1801,2)="P1",1,0)) -> 0 | I1801: {=IF($A1801="","",IF(IFERROR(INDEX(Summary!$BA:$BA,$AH1801),0)<1,"Under 1 day",IF(INDEX(Summary!$BA:$BA,$AH1801)<3,"1-3 days",IF(INDEX(Summary!$BA:$BA,$AH1801)<7,"3-7 days","7+ days"))))} -> Under 1 day | J1801: {=IF($A1801="","",IF(IFERROR(INDEX(Summary!$AX:$AX,$AH1801),0)<0.25,"0-25%",IF(INDEX(Summary!$AX:$AX,$AH1801)<0.5,"25-50%",IF(INDEX(Summary!$AX:$AX,$AH1801)<0.75,"50-75%","75-100%"))))} -> 75-100% | K1801: {=IF($A1801="","",INDEX(Summary!$AY:$AY,$AH1801)&"")} | L1801: =IF($A1801="","",Summary!$P$2+MOD(ROW()-2,30)) -> 46256 | M1801: =IF($A1801="","",MOD(ROW()-2,30)+1) -> 30 | N1801: =IF($A1801="","",DAY($L1801)) -> 22 | O1801: =IF($A1801="","",TEXT($L1801,"mmm-yyyy")) -> Aug-2026 | P1801: =IF($A1801="","",IF($L1801<=TODAY(),1,0)) -> 1 | Q1801: {=IF($A1801="",0,IFERROR(INDEX(Summary!$P$3:$AS$67,$AH1801-2,$M1801),0))} -> 0 | R1801: {=IF($A1801="",0,ROUND(IFERROR(INDEX(Summary!$O:$O,$AH1801),0)/30,0))} -> 0 | S1801: =IF($A1801="",0,IF($M1801=1,1,0)) -> 0 | T1801: {=IF($S1801=1,IFERROR(INDEX(Summary!$O:$O,$AH1801),0),0)} -> 0 | U1801: {=IF($S1801=1,IFERROR(INDEX(Summary!$AT:$AT,$AH1801),0),0)} -> 0 | V1801: =IF($S1801=1,MAX(0,$T1801-$U1801),0) -> 0 | W1801: {=IF($S1801=1,IFERROR(INDEX(Summary!$AZ:$AZ,$AH1801),0),0)} -> 0 | X1801: {=IF($S1801=1,IFERROR(INDEX(Summary!$BA:$BA,$AH1801),0),0)} -> 0 | Y1801: {=IF($S1801=1,IFERROR(INDEX(Summary!$G:$G,$AH1801),0),0)} -> 0 | Z1801: {=IF($S1801=1,IFERROR(INDEX(Summary!$H:$H,$AH1801),0),0)} -> 0 | AA1801: {=IF($S1801=1,IFERROR(INDEX(Summary!$I:$I,$AH1801),0),0)} -> 0 | AB1801: {=IF($S1801=1,IFERROR(INDEX(Summary!$J:$J,$AH1801),0),0)} -> 0 | AC1801: {=IF($S1801=1,IFERROR(INDEX(Summary!$K:$K,$AH1801),0),0)} -> 0 | AD1801: {=IF($S1801=1,IFERROR(INDEX(Summary!$L:$L,$AH1801),0),0)} -> 0 | AE1801: {=IF($S1801=1,IFERROR(INDEX(Summary!$M:$M,$AH1801),0),0)} -> 0 | AF1801: {=IF($S1801=1,IFERROR(INDEX(Summary!$N:$N,$AH1801),0),0)} -> 0 | AG1801: {=IF($A1801="","",IFERROR(INDEX(Summary!$BB:$BB,$AH1801),0))} -> 0 | AH1801: =INT((ROW()-2)/30)+3 -> 62

Sheet BI_Channel
A1: FGCode | B1: Product | C1: Section | D1: Plant | E1: Channel | F1: PlanPKT | G1: ProducedPKT | H1: PendingPKT | I1: FillRate | J1: SrcRow
A2: {=IFERROR(INDEX(Summary!$D:$D,$J2)&"","")} -> FG00724 | B2: {=IF($A2="","",INDEX(Summary!$E:$E,$J2))} -> Khapli Atta 1KG | C2: {=IF($A2="","",INDEX(Summary!$B:$B,$J2))} -> Atta | D2: {=IF($A2="","",INDEX(Summary!$C:$C,$J2))} -> C39 | E2: {=IF($A2="","",INDEX(Summary!$G$2:$N$2,MOD(ROW()-2,8)+1))} -> MRP (Domestic) | F2: {=IF($A2="",0,IFERROR(INDEX(Summary!$G$3:$N$62,$J2-2,MOD(ROW()-2,8)+1),0))} -> 0 | G2: {=IF($A2="",0,IFERROR(_xlfn.SWITCH($E2,"MRP (Domestic)",_xlfn.XLOOKUP($A2,Domestic!$C:$C,Domestic!$BE:$BE),"ROW Manjari",_xlfn.XLOOKUP($A2,ROW_Manjari!$C:$C,ROW_Manjari!$BE:$BE),"USA Sea",_xlfn.XLOOKUP($A2,USA_Sea!$C:$C,USA_Sea!$BE:$BE),"Amazon USA Sea",_xlfn.XLOOKUP($A2,Amazon_USA_Sea!$C:$C,Amazon_USA_Sea!$AX:$AX),"USA Air",_xlfn.XLOOKUP($A2,USA_Air!$C:$C,USA_Air!$BE:$BE),"USA Amazon",_xlfn.XLOOKUP($A2,USA_Amazon_Air!$C:$C,USA_Amazon_Air!$BE:$BE),"UK",_xlfn.XLOOKUP($A2,UK_Order!$C:$C,UK_Order!$BE:$BE),"MENA",_xlfn.XLOOKUP($A2,MENA_Order!$C:$C,MENA_Order!$BE:$BE),0),0))} -> 0 | H2: =IF($A2="",0,MAX(0,$F2-$G2)) -> 0 | I2: =IF($A2="",0,IFERROR($G2/$F2,0)) -> 0 | J2: =INT((ROW()-2)/8)+3 -> 3
A3: {=IFERROR(INDEX(Summary!$D:$D,$J3)&"","")} -> FG00724 | B3: {=IF($A3="","",INDEX(Summary!$E:$E,$J3))} -> Khapli Atta 1KG | C3: {=IF($A3="","",INDEX(Summary!$B:$B,$J3))} -> Atta | D3: {=IF($A3="","",INDEX(Summary!$C:$C,$J3))} -> C39 | E3: {=IF($A3="","",INDEX(Summary!$G$2:$N$2,MOD(ROW()-2,8)+1))} -> ROW Manjari | F3: {=IF($A3="",0,IFERROR(INDEX(Summary!$G$3:$N$62,$J3-2,MOD(ROW()-2,8)+1),0))} -> 0 | G3: {=IF($A3="",0,IFERROR(_xlfn.SWITCH($E3,"MRP (Domestic)",_xlfn.XLOOKUP($A3,Domestic!$C:$C,Domestic!$BE:$BE),"ROW Manjari",_xlfn.XLOOKUP($A3,ROW_Manjari!$C:$C,ROW_Manjari!$BE:$BE),"USA Sea",_xlfn.XLOOKUP($A3,USA_Sea!$C:$C,USA_Sea!$BE:$BE),"Amazon USA Sea",_xlfn.XLOOKUP($A3,Amazon_USA_Sea!$C:$C,Amazon_USA_Sea!$AX:$AX),"USA Air",_xlfn.XLOOKUP($A3,USA_Air!$C:$C,USA_Air!$BE:$BE),"USA Amazon",_xlfn.XLOOKUP($A3,USA_Amazon_Air!$C:$C,USA_Amazon_Air!$BE:$BE),"UK",_xlfn.XLOOKUP($A3,UK_Order!$C:$C,UK_Order!$BE:$BE),"MENA",_xlfn.XLOOKUP($A3,MENA_Order!$C:$C,MENA_Order!$BE:$BE),0),0))} -> 0 | H3: =IF($A3="",0,MAX(0,$F3-$G3)) -> 0 | I3: =IF($A3="",0,IFERROR($G3/$F3,0)) -> 0 | J3: =INT((ROW()-2)/8)+3 -> 3
A4: {=IFERROR(INDEX(Summary!$D:$D,$J4)&"","")} -> FG00724 | B4: {=IF($A4="","",INDEX(Summary!$E:$E,$J4))} -> Khapli Atta 1KG | C4: {=IF($A4="","",INDEX(Summary!$B:$B,$J4))} -> Atta | D4: {=IF($A4="","",INDEX(Summary!$C:$C,$J4))} -> C39 | E4: {=IF($A4="","",INDEX(Summary!$G$2:$N$2,MOD(ROW()-2,8)+1))} -> USA Sea | F4: {=IF($A4="",0,IFERROR(INDEX(Summary!$G$3:$N$62,$J4-2,MOD(ROW()-2,8)+1),0))} -> 0 | G4: {=IF($A4="",0,IFERROR(_xlfn.SWITCH($E4,"MRP (Domestic)",_xlfn.XLOOKUP($A4,Domestic!$C:$C,Domestic!$BE:$BE),"ROW Manjari",_xlfn.XLOOKUP($A4,ROW_Manjari!$C:$C,ROW_Manjari!$BE:$BE),"USA Sea",_xlfn.XLOOKUP($A4,USA_Sea!$C:$C,USA_Sea!$BE:$BE),"Amazon USA Sea",_xlfn.XLOOKUP($A4,Amazon_USA_Sea!$C:$C,Amazon_USA_Sea!$AX:$AX),"USA Air",_xlfn.XLOOKUP($A4,USA_Air!$C:$C,USA_Air!$BE:$BE),"USA Amazon",_xlfn.XLOOKUP($A4,USA_Amazon_Air!$C:$C,USA_Amazon_Air!$BE:$BE),"UK",_xlfn.XLOOKUP($A4,UK_Order!$C:$C,UK_Order!$BE:$BE),"MENA",_xlfn.XLOOKUP($A4,MENA_Order!$C:$C,MENA_Order!$BE:$BE),0),0))} -> 0 | H4: =IF($A4="",0,MAX(0,$F4-$G4)) -> 0 | I4: =IF($A4="",0,IFERROR($G4/$F4,0)) -> 0 | J4: =INT((ROW()-2)/8)+3 -> 3
A5: {=IFERROR(INDEX(Summary!$D:$D,$J5)&"","")} -> FG00724 | B5: {=IF($A5="","",INDEX(Summary!$E:$E,$J5))} -> Khapli Atta 1KG | C5: {=IF($A5="","",INDEX(Summary!$B:$B,$J5))} -> Atta | D5: {=IF($A5="","",INDEX(Summary!$C:$C,$J5))} -> C39 | E5: {=IF($A5="","",INDEX(Summary!$G$2:$N$2,MOD(ROW()-2,8)+1))} -> Amazon USA Sea | F5: {=IF($A5="",0,IFERROR(INDEX(Summary!$G$3:$N$62,$J5-2,MOD(ROW()-2,8)+1),0))} -> 0 | G5: {=IF($A5="",0,IFERROR(_xlfn.SWITCH($E5,"MRP (Domestic)",_xlfn.XLOOKUP($A5,Domestic!$C:$C,Domestic!$BE:$BE),"ROW Manjari",_xlfn.XLOOKUP($A5,ROW_Manjari!$C:$C,ROW_Manjari!$BE:$BE),"USA Sea",_xlfn.XLOOKUP($A5,USA_Sea!$C:$C,USA_Sea!$BE:$BE),"Amazon USA Sea",_xlfn.XLOOKUP($A5,Amazon_USA_Sea!$C:$C,Amazon_USA_Sea!$AX:$AX),"USA Air",_xlfn.XLOOKUP($A5,USA_Air!$C:$C,USA_Air!$BE:$BE),"USA Amazon",_xlfn.XLOOKUP($A5,USA_Amazon_Air!$C:$C,USA_Amazon_Air!$BE:$BE),"UK",_xlfn.XLOOKUP($A5,UK_Order!$C:$C,UK_Order!$BE:$BE),"MENA",_xlfn.XLOOKUP($A5,MENA_Order!$C:$C,MENA_Order!$BE:$BE),0),0))} -> 0 | H5: =IF($A5="",0,MAX(0,$F5-$G5)) -> 0 | I5: =IF($A5="",0,IFERROR($G5/$F5,0)) -> 0 | J5: =INT((ROW()-2)/8)+3 -> 3
A6: {=IFERROR(INDEX(Summary!$D:$D,$J6)&"","")} -> FG00724 | B6: {=IF($A6="","",INDEX(Summary!$E:$E,$J6))} -> Khapli Atta 1KG | C6: {=IF($A6="","",INDEX(Summary!$B:$B,$J6))} -> Atta | D6: {=IF($A6="","",INDEX(Summary!$C:$C,$J6))} -> C39 | E6: {=IF($A6="","",INDEX(Summary!$G$2:$N$2,MOD(ROW()-2,8)+1))} -> USA Air | F6: {=IF($A6="",0,IFERROR(INDEX(Summary!$G$3:$N$62,$J6-2,MOD(ROW()-2,8)+1),0))} -> 6000 | G6: {=IF($A6="",0,IFERROR(_xlfn.SWITCH($E6,"MRP (Domestic)",_xlfn.XLOOKUP($A6,Domestic!$C:$C,Domestic!$BE:$BE),"ROW Manjari",_xlfn.XLOOKUP($A6,ROW_Manjari!$C:$C,ROW_Manjari!$BE:$BE),"USA Sea",_xlfn.XLOOKUP($A6,USA_Sea!$C:$C,USA_Sea!$BE:$BE),"Amazon USA Sea",_xlfn.XLOOKUP($A6,Amazon_USA_Sea!$C:$C,Amazon_USA_Sea!$AX:$AX),"USA Air",_xlfn.XLOOKUP($A6,USA_Air!$C:$C,USA_Air!$BE:$BE),"USA Amazon",_xlfn.XLOOKUP($A6,USA_Amazon_Air!$C:$C,USA_Amazon_Air!$BE:$BE),"UK",_xlfn.XLOOKUP($A6,UK_Order!$C:$C,UK_Order!$BE:$BE),"MENA",_xlfn.XLOOKUP($A6,MENA_Order!$C:$C,MENA_Order!$BE:$BE),0),0))} -> 6011 | H6: =IF($A6="",0,MAX(0,$F6-$G6)) -> 0 | I6: =IF($A6="",0,IFERROR($G6/$F6,0)) -> 1.0018333 | J6: =INT((ROW()-2)/8)+3 -> 3
A7: {=IFERROR(INDEX(Summary!$D:$D,$J7)&"","")} -> FG00724 | B7: {=IF($A7="","",INDEX(Summary!$E:$E,$J7))} -> Khapli Atta 1KG | C7: {=IF($A7="","",INDEX(Summary!$B:$B,$J7))} -> Atta | D7: {=IF($A7="","",INDEX(Summary!$C:$C,$J7))} -> C39 | E7: {=IF($A7="","",INDEX(Summary!$G$2:$N$2,MOD(ROW()-2,8)+1))} -> USA Amazon | F7: {=IF($A7="",0,IFERROR(INDEX(Summary!$G$3:$N$62,$J7-2,MOD(ROW()-2,8)+1),0))} -> 0 | G7: {=IF($A7="",0,IFERROR(_xlfn.SWITCH($E7,"MRP (Domestic)",_xlfn.XLOOKUP($A7,Domestic!$C:$C,Domestic!$BE:$BE),"ROW Manjari",_xlfn.XLOOKUP($A7,ROW_Manjari!$C:$C,ROW_Manjari!$BE:$BE),"USA Sea",_xlfn.XLOOKUP($A7,USA_Sea!$C:$C,USA_Sea!$BE:$BE),"Amazon USA Sea",_xlfn.XLOOKUP($A7,Amazon_USA_Sea!$C:$C,Amazon_USA_Sea!$AX:$AX),"USA Air",_xlfn.XLOOKUP($A7,USA_Air!$C:$C,USA_Air!$BE:$BE),"USA Amazon",_xlfn.XLOOKUP($A7,USA_Amazon_Air!$C:$C,USA_Amazon_Air!$BE:$BE),"UK",_xlfn.XLOOKUP($A7,UK_Order!$C:$C,UK_Order!$BE:$BE),"MENA",_xlfn.XLOOKUP($A7,MENA_Order!$C:$C,MENA_Order!$BE:$BE),0),0))} -> 0 | H7: =IF($A7="",0,MAX(0,$F7-$G7)) -> 0 | I7: =IF($A7="",0,IFERROR($G7/$F7,0)) -> 0 | J7: =INT((ROW()-2)/8)+3 -> 3
A8: {=IFERROR(INDEX(Summary!$D:$D,$J8)&"","")} -> FG00724 | B8: {=IF($A8="","",INDEX(Summary!$E:$E,$J8))} -> Khapli Atta 1KG | C8: {=IF($A8="","",INDEX(Summary!$B:$B,$J8))} -> Atta | D8: {=IF($A8="","",INDEX(Summary!$C:$C,$J8))} -> C39 | E8: {=IF($A8="","",INDEX(Summary!$G$2:$N$2,MOD(ROW()-2,8)+1))} -> UK | F8: {=IF($A8="",0,IFERROR(INDEX(Summary!$G$3:$N$62,$J8-2,MOD(ROW()-2,8)+1),0))} -> 0 | G8: {=IF($A8="",0,IFERROR(_xlfn.SWITCH($E8,"MRP (Domestic)",_xlfn.XLOOKUP($A8,Domestic!$C:$C,Domestic!$BE:$BE),"ROW Manjari",_xlfn.XLOOKUP($A8,ROW_Manjari!$C:$C,ROW_Manjari!$BE:$BE),"USA Sea",_xlfn.XLOOKUP($A8,USA_Sea!$C:$C,USA_Sea!$BE:$BE),"Amazon USA Sea",_xlfn.XLOOKUP($A8,Amazon_USA_Sea!$C:$C,Amazon_USA_Sea!$AX:$AX),"USA Air",_xlfn.XLOOKUP($A8,USA_Air!$C:$C,USA_Air!$BE:$BE),"USA Amazon",_xlfn.XLOOKUP($A8,USA_Amazon_Air!$C:$C,USA_Amazon_Air!$BE:$BE),"UK",_xlfn.XLOOKUP($A8,UK_Order!$C:$C,UK_Order!$BE:$BE),"MENA",_xlfn.XLOOKUP($A8,MENA_Order!$C:$C,MENA_Order!$BE:$BE),0),0))} -> 0 | H8: =IF($A8="",0,MAX(0,$F8-$G8)) -> 0 | I8: =IF($A8="",0,IFERROR($G8/$F8,0)) -> 0 | J8: =INT((ROW()-2)/8)+3 -> 3
A9: {=IFERROR(INDEX(Summary!$D:$D,$J9)&"","")} -> FG00724 | B9: {=IF($A9="","",INDEX(Summary!$E:$E,$J9))} -> Khapli Atta 1KG | C9: {=IF($A9="","",INDEX(Summary!$B:$B,$J9))} -> Atta | D9: {=IF($A9="","",INDEX(Summary!$C:$C,$J9))} -> C39 | E9: {=IF($A9="","",INDEX(Summary!$G$2:$N$2,MOD(ROW()-2,8)+1))} -> MENA | F9: {=IF($A9="",0,IFERROR(INDEX(Summary!$G$3:$N$62,$J9-2,MOD(ROW()-2,8)+1),0))} -> 0 | G9: {=IF($A9="",0,IFERROR(_xlfn.SWITCH($E9,"MRP (Domestic)",_xlfn.XLOOKUP($A9,Domestic!$C:$C,Domestic!$BE:$BE),"ROW Manjari",_xlfn.XLOOKUP($A9,ROW_Manjari!$C:$C,ROW_Manjari!$BE:$BE),"USA Sea",_xlfn.XLOOKUP($A9,USA_Sea!$C:$C,USA_Sea!$BE:$BE),"Amazon USA Sea",_xlfn.XLOOKUP($A9,Amazon_USA_Sea!$C:$C,Amazon_USA_Sea!$AX:$AX),"USA Air",_xlfn.XLOOKUP($A9,USA_Air!$C:$C,USA_Air!$BE:$BE),"USA Amazon",_xlfn.XLOOKUP($A9,USA_Amazon_Air!$C:$C,USA_Amazon_Air!$BE:$BE),"UK",_xlfn.XLOOKUP($A9,UK_Order!$C:$C,UK_Order!$BE:$BE),"MENA",_xlfn.XLOOKUP($A9,MENA_Order!$C:$C,MENA_Order!$BE:$BE),0),0))} -> 0 | H9: =IF($A9="",0,MAX(0,$F9-$G9)) -> 0 | I9: =IF($A9="",0,IFERROR($G9/$F9,0)) -> 0 | J9: =INT((ROW()-2)/8)+3 -> 3
A10: {=IFERROR(INDEX(Summary!$D:$D,$J10)&"","")} -> FG00537 | B10: {=IF($A10="","",INDEX(Summary!$E:$E,$J10))} -> Khapli Atta (Stoneground) - 2kg | C10: {=IF($A10="","",INDEX(Summary!$B:$B,$J10))} -> Atta | D10: {=IF($A10="","",INDEX(Summary!$C:$C,$J10))} -> C39 | E10: {=IF($A10="","",INDEX(Summary!$G$2:$N$2,MOD(ROW()-2,8)+1))} -> MRP (Domestic) | F10: {=IF($A10="",0,IFERROR(INDEX(Summary!$G$3:$N$62,$J10-2,MOD(ROW()-2,8)+1),0))} -> 0 | G10: {=IF($A10="",0,IFERROR(_xlfn.SWITCH($E10,"MRP (Domestic)",_xlfn.XLOOKUP($A10,Domestic!$C:$C,Domestic!$BE:$BE),"ROW Manjari",_xlfn.XLOOKUP($A10,ROW_Manjari!$C:$C,ROW_Manjari!$BE:$BE),"USA Sea",_xlfn.XLOOKUP($A10,USA_Sea!$C:$C,USA_Sea!$BE:$BE),"Amazon USA Sea",_xlfn.XLOOKUP($A10,Amazon_USA_Sea!$C:$C,Amazon_USA_Sea!$AX:$AX),"USA Air",_xlfn.XLOOKUP($A10,USA_Air!$C:$C,USA_Air!$BE:$BE),"USA Amazon",_xlfn.XLOOKUP($A10,USA_Amazon_Air!$C:$C,USA_Amazon_Air!$BE:$BE),"UK",_xlfn.XLOOKUP($A10,UK_Order!$C:$C,UK_Order!$BE:$BE),"MENA",_xlfn.XLOOKUP($A10,MENA_Order!$C:$C,MENA_Order!$BE:$BE),0),0))} -> 0 | H10: =IF($A10="",0,MAX(0,$F10-$G10)) -> 0 | I10: =IF($A10="",0,IFERROR($G10/$F10,0)) -> 0 | J10: =INT((ROW()-2)/8)+3 -> 4
A11: {=IFERROR(INDEX(Summary!$D:$D,$J11)&"","")} -> FG00537 | B11: {=IF($A11="","",INDEX(Summary!$E:$E,$J11))} -> Khapli Atta (Stoneground) - 2kg | C11: {=IF($A11="","",INDEX(Summary!$B:$B,$J11))} -> Atta | D11: {=IF($A11="","",INDEX(Summary!$C:$C,$J11))} -> C39 | E11: {=IF($A11="","",INDEX(Summary!$G$2:$N$2,MOD(ROW()-2,8)+1))} -> ROW Manjari | F11: {=IF($A11="",0,IFERROR(INDEX(Summary!$G$3:$N$62,$J11-2,MOD(ROW()-2,8)+1),0))} -> 0 | G11: {=IF($A11="",0,IFERROR(_xlfn.SWITCH($E11,"MRP (Domestic)",_xlfn.XLOOKUP($A11,Domestic!$C:$C,Domestic!$BE:$BE),"ROW Manjari",_xlfn.XLOOKUP($A11,ROW_Manjari!$C:$C,ROW_Manjari!$BE:$BE),"USA Sea",_xlfn.XLOOKUP($A11,USA_Sea!$C:$C,USA_Sea!$BE:$BE),"Amazon USA Sea",_xlfn.XLOOKUP($A11,Amazon_USA_Sea!$C:$C,Amazon_USA_Sea!$AX:$AX),"USA Air",_xlfn.XLOOKUP($A11,USA_Air!$C:$C,USA_Air!$BE:$BE),"USA Amazon",_xlfn.XLOOKUP($A11,USA_Amazon_Air!$C:$C,USA_Amazon_Air!$BE:$BE),"UK",_xlfn.XLOOKUP($A11,UK_Order!$C:$C,UK_Order!$BE:$BE),"MENA",_xlfn.XLOOKUP($A11,MENA_Order!$C:$C,MENA_Order!$BE:$BE),0),0))} -> 0 | H11: =IF($A11="",0,MAX(0,$F11-$G11)) -> 0 | I11: =IF($A11="",0,IFERROR($G11/$F11,0)) -> 0 | J11: =INT((ROW()-2)/8)+3 -> 4
A12: {=IFERROR(INDEX(Summary!$D:$D,$J12)&"","")} -> FG00537 | B12: {=IF($A12="","",INDEX(Summary!$E:$E,$J12))} -> Khapli Atta (Stoneground) - 2kg | C12: {=IF($A12="","",INDEX(Summary!$B:$B,$J12))} -> Atta | D12: {=IF($A12="","",INDEX(Summary!$C:$C,$J12))} -> C39 | E12: {=IF($A12="","",INDEX(Summary!$G$2:$N$2,MOD(ROW()-2,8)+1))} -> USA Sea | F12: {=IF($A12="",0,IFERROR(INDEX(Summary!$G$3:$N$62,$J12-2,MOD(ROW()-2,8)+1),0))} -> 0 | G12: {=IF($A12="",0,IFERROR(_xlfn.SWITCH($E12,"MRP (Domestic)",_xlfn.XLOOKUP($A12,Domestic!$C:$C,Domestic!$BE:$BE),"ROW Manjari",_xlfn.XLOOKUP($A12,ROW_Manjari!$C:$C,ROW_Manjari!$BE:$BE),"USA Sea",_xlfn.XLOOKUP($A12,USA_Sea!$C:$C,USA_Sea!$BE:$BE),"Amazon USA Sea",_xlfn.XLOOKUP($A12,Amazon_USA_Sea!$C:$C,Amazon_USA_Sea!$AX:$AX),"USA Air",_xlfn.XLOOKUP($A12,USA_Air!$C:$C,USA_Air!$BE:$BE),"USA Amazon",_xlfn.XLOOKUP($A12,USA_Amazon_Air!$C:$C,USA_Amazon_Air!$BE:$BE),"UK",_xlfn.XLOOKUP($A12,UK_Order!$C:$C,UK_Order!$BE:$BE),"MENA",_xlfn.XLOOKUP($A12,MENA_Order!$C:$C,MENA_Order!$BE:$BE),0),0))} -> 0 | H12: =IF($A12="",0,MAX(0,$F12-$G12)) -> 0 | I12: =IF($A12="",0,IFERROR($G12/$F12,0)) -> 0 | J12: =INT((ROW()-2)/8)+3 -> 4
A13: {=IFERROR(INDEX(Summary!$D:$D,$J13)&"","")} -> FG00537 | B13: {=IF($A13="","",INDEX(Summary!$E:$E,$J13))} -> Khapli Atta (Stoneground) - 2kg | C13: {=IF($A13="","",INDEX(Summary!$B:$B,$J13))} -> Atta | D13: {=IF($A13="","",INDEX(Summary!$C:$C,$J13))} -> C39 | E13: {=IF($A13="","",INDEX(Summary!$G$2:$N$2,MOD(ROW()-2,8)+1))} -> Amazon USA Sea | F13: {=IF($A13="",0,IFERROR(INDEX(Summary!$G$3:$N$62,$J13-2,MOD(ROW()-2,8)+1),0))} -> 0 | G13: {=IF($A13="",0,IFERROR(_xlfn.SWITCH($E13,"MRP (Domestic)",_xlfn.XLOOKUP($A13,Domestic!$C:$C,Domestic!$BE:$BE),"ROW Manjari",_xlfn.XLOOKUP($A13,ROW_Manjari!$C:$C,ROW_Manjari!$BE:$BE),"USA Sea",_xlfn.XLOOKUP($A13,USA_Sea!$C:$C,USA_Sea!$BE:$BE),"Amazon USA Sea",_xlfn.XLOOKUP($A13,Amazon_USA_Sea!$C:$C,Amazon_USA_Sea!$AX:$AX),"USA Air",_xlfn.XLOOKUP($A13,USA_Air!$C:$C,USA_Air!$BE:$BE),"USA Amazon",_xlfn.XLOOKUP($A13,USA_Amazon_Air!$C:$C,USA_Amazon_Air!$BE:$BE),"UK",_xlfn.XLOOKUP($A13,UK_Order!$C:$C,UK_Order!$BE:$BE),"MENA",_xlfn.XLOOKUP($A13,MENA_Order!$C:$C,MENA_Order!$BE:$BE),0),0))} -> 0 | H13: =IF($A13="",0,MAX(0,$F13-$G13)) -> 0 | I13: =IF($A13="",0,IFERROR($G13/$F13,0)) -> 0 | J13: =INT((ROW()-2)/8)+3 -> 4
... A481: {=IFERROR(INDEX(Summary!$D:$D,$J481)&"","")} -> FG00678 | B481: {=IF($A481="","",INDEX(Summary!$E:$E,$J481))} -> Virgin Coconut Oil - 100ml - Units | C481: {=IF($A481="","",INDEX(Summary!$B:$B,$J481))} -> Oil | D481: {=IF($A481="","",INDEX(Summary!$C:$C,$J481))} -> C6 | E481: {=IF($A481="","",INDEX(Summary!$G$2:$N$2,MOD(ROW()-2,8)+1))} -> MENA | F481: {=IF($A481="",0,IFERROR(INDEX(Summary!$G$3:$N$62,$J481-2,MOD(ROW()-2,8)+1),0))} -> 0 | G481: {=IF($A481="",0,IFERROR(_xlfn.SWITCH($E481,"MRP (Domestic)",_xlfn.XLOOKUP($A481,Domestic!$C:$C,Domestic!$BE:$BE),"ROW Manjari",_xlfn.XLOOKUP($A481,ROW_Manjari!$C:$C,ROW_Manjari!$BE:$BE),"USA Sea",_xlfn.XLOOKUP($A481,USA_Sea!$C:$C,USA_Sea!$BE:$BE),"Amazon USA Sea",_xlfn.XLOOKUP($A481,Amazon_USA_Sea!$C:$C,Amazon_USA_Sea!$AX:$AX),"USA Air",_xlfn.XLOOKUP($A481,USA_Air!$C:$C,USA_Air!$BE:$BE),"USA Amazon",_xlfn.XLOOKUP($A481,USA_Amazon_Air!$C:$C,USA_Amazon_Air!$BE:$BE),"UK",_xlfn.XLOOKUP($A481,UK_Order!$C:$C,UK_Order!$BE:$BE),"MENA",_xlfn.XLOOKUP($A481,MENA_Order!$C:$C,MENA_Order!$BE:$BE),0),0))} -> 0 | H481: =IF($A481="",0,MAX(0,$F481-$G481)) -> 0 | I481: =IF($A481="",0,IFERROR($G481/$F481,0)) -> 0 | J481: =INT((ROW()-2)/8)+3 -> 62

Sheet BI_ReadMe
A1: POWER BI — SINGLE SOURCE TABLE | B1: tbl_BI_Data on sheet BI_Data
A3: Item | B3: Detail
A4: Grain | B4: One row per SKU per day: 60 SKUs x 30 days = 1,800 rows. Connect Power BI directly to tbl_BI_Data — no Power Query transformation needed.
A5: Source | B5: Every column is a live formula reading the Summary sheet (rows 3:62). A Power BI refresh always picks up the latest Summary values.
A6: Additive design | B6: SKU-level values (PlanPKT, ProducedPKT, PendingPKT, SOHCentralWH, DOH and the eight Plan-by-channel columns) are written ONLY on each SKU's first day row, where IsSKURow = 1, and are 0 on the other 29 rows. A plain SUM over the whole table therefore gives the correct SKU-level total with no duplication.
A7: Daily values | B7: DailyProducedPKT and EvenPaceTargetPKT are populated on every row — use these for run-rate and pace trends over Date.
A8: Date | B8: Mark Date as a date column, or build a date table in Power BI and relate it to tbl_BI_Data[Date]. The plan month runs 24-Jul to 22-Aug.
A9: Non-additive fields | B9: DOH and SOHCentralWH: filter to IsSKURow = 1 before averaging, otherwise the 29 zero rows drag the average down.
A11: Suggested DAX measures
A12: Total Plan | B12: = SUM ( tbl_BI_Data[PlanPKT] )
A13: Total Produced | B13: = SUM ( tbl_BI_Data[ProducedPKT] )
A14: Total Pending | B14: = SUM ( tbl_BI_Data[PendingPKT] )
A15: Fulfillment % | B15: = DIVIDE ( [Total Produced], [Total Plan] )
A16: Pending SKUs | B16: = CALCULATE ( COUNTROWS ( tbl_BI_Data ), tbl_BI_Data[IsSKURow] = 1, tbl_BI_Data[PendingPKT] > 0 )
A17: Critical SKUs | B17: = CALCULATE ( COUNTROWS ( tbl_BI_Data ), tbl_BI_Data[IsSKURow] = 1, tbl_BI_Data[IsCritical] = 1, tbl_BI_Data[PendingPKT] > 0 )
A18: Critical Pending PKT | B18: = CALCULATE ( [Total Pending], tbl_BI_Data[IsCritical] = 1 )
A19: Avg DOH | B19: = CALCULATE ( AVERAGE ( tbl_BI_Data[DOH] ), tbl_BI_Data[IsSKURow] = 1 )
A20: Days Elapsed | B20: = CALCULATE ( DISTINCTCOUNT ( tbl_BI_Data[Date] ), tbl_BI_Data[IsElapsed] = 1 )
A21: Days Remaining | B21: = CALCULATE ( DISTINCTCOUNT ( tbl_BI_Data[Date] ), tbl_BI_Data[IsElapsed] = 0 )
A22: Run Rate per Day | B22: = DIVIDE ( [Total Produced], [Days Elapsed] )
A23: Required Run Rate | B23: = DIVIDE ( [Total Pending], [Days Remaining] )
... A41: Note | B41: Channel-wise ProducedPKT totals 70,559 vs the master Summary total of ~78,000 — the per-channel sheets are not fully reconciled with Summary's daily entry. Use tbl_BI_Data for headline produced/fulfilment KPIs and tbl_BI_Channel only for channel-split views.

Sheet Dashboard
A1: Non Ghee Production Dashboard | Y1: All
O2: Selected Plan | P2: Plant Flag | Q2: Channel Flag | R2: Selected Pending | S2: Section | T2: Selected Produced | U2: Section Flag | V2: Product Flag | Y2: =Summary!E3 -> Khapli Atta 1KG
A3: Plant selector | C3: C6 | E3: Section selector | G3: All | O3: {=_xlfn.SWITCH($C$4,"MRP (Domestic)",Summary!G3,"ROW Manjari",Summary!H3,"USA Sea",Summary!I3,"Amazon USA Sea",Summary!J3,"USA Air",Summary!K3,"USA Amazon",Summary!L3,"UK",Summary!M3,"MENA",Summary!N3,Summary!O3)} -> 6000 | P3: =--(Summary!B3<>"")*IF($C$3="All",1,--(Summary!C3=$C$3)) -> 0 | Q3: =IF($C$4="All",1,--(O3>0)) -> 1 | R3: =T3-O3 -> 271 | S3: =Summary!B3 -> Atta | T3: {=_xlfn.SWITCH($C$4,"MRP (Domestic)",IFERROR(_xlfn.XLOOKUP(Summary!D3,Domestic!$C:$C,Domestic!$BE:$BE),0),"ROW Manjari",IFERROR(_xlfn.XLOOKUP(Summary!D3,ROW_Manjari!$C:$C,ROW_Manjari!$BE:$BE),0),"USA Sea",IFERROR(_xlfn.XLOOKUP(Summary!D3,USA_Sea!$C:$C,USA_Sea!$BE:$BE),0),"Amazon USA Sea",IFERROR(_xlfn.XLOOKUP(Summary!D3,Amazon_USA_Sea!$C:$C,Amazon_USA_Sea!$AX:$AX),0),"USA Air",IFERROR(_xlfn.XLOOKUP(Summary!D3,USA_Air!$C:$C,USA_Air!$BE:$BE),0),"USA Amazon",IFERROR(_xlfn.XLOOKUP(Summary!D3,USA_Amazon_Air!$C:$C,USA_Amazon_Air!$BE:$BE),0),"UK",IFERROR(_xlfn.XLOOKUP(Summary!D3,UK_Order!$C:$C,UK_Order!$BE:$BE),0),"MENA",IFERROR(_xlfn.XLOOKUP(Summary!D3,MENA_Order!$C:$C,MENA_Order!$BE:$BE),0),Summary!AT3)} -> 6271 | U3: =IF($G$3="All",1,--($S3=$G$3)) -> 1 | V3: =IF($G$4="All",1,--(Summary!E3=$G$4)) -> 1 | Y3: =Summary!E4 -> Khapli Atta (Stoneground) - 2kg
A4: Channel selector | C4: All | E4: Product selector | G4: All | O4: {=_xlfn.SWITCH($C$4,"MRP (Domestic)",Summary!G4,"ROW Manjari",Summary!H4,"USA Sea",Summary!I4,"Amazon USA Sea",Summary!J4,"USA Air",Summary!K4,"USA Amazon",Summary!L4,"UK",Summary!M4,"MENA",Summary!N4,Summary!O4)} -> 0 | P4: =--(Summary!B4<>"")*IF($C$3="All",1,--(Summary!C4=$C$3)) -> 0 | Q4: =IF($C$4="All",1,--(O4>0)) -> 1 | R4: =T4-O4 -> 18596 | S4: =Summary!B4 -> Atta | T4: {=_xlfn.SWITCH($C$4,"MRP (Domestic)",IFERROR(_xlfn.XLOOKUP(Summary!D4,Domestic!$C:$C,Domestic!$BE:$BE),0),"ROW Manjari",IFERROR(_xlfn.XLOOKUP(Summary!D4,ROW_Manjari!$C:$C,ROW_Manjari!$BE:$BE),0),"USA Sea",IFERROR(_xlfn.XLOOKUP(Summary!D4,USA_Sea!$C:$C,USA_Sea!$BE:$BE),0),"Amazon USA Sea",IFERROR(_xlfn.XLOOKUP(Summary!D4,Amazon_USA_Sea!$C:$C,Amazon_USA_Sea!$AX:$AX),0),"USA Air",IFERROR(_xlfn.XLOOKUP(Summary!D4,USA_Air!$C:$C,USA_Air!$BE:$BE),0),"USA Amazon",IFERROR(_xlfn.XLOOKUP(Summary!D4,USA_Amazon_Air!$C:$C,USA_Amazon_Air!$BE:$BE),0),"UK",IFERROR(_xlfn.XLOOKUP(Summary!D4,UK_Order!$C:$C,UK_Order!$BE:$BE),0),"MENA",IFERROR(_xlfn.XLOOKUP(Summary!D4,MENA_Order!$C:$C,MENA_Order!$BE:$BE),0),Summary!AT4)} -> 18596 | U4: =IF($G$3="All",1,--($S4=$G$3)) -> 1 | V4: =IF($G$4="All",1,--(Summary!E4=$G$4)) -> 1 | Y4: =Summary!E5 -> Khapli Atta (Stoneground) - 5kg
A5: Total Plan | C5: Produced PKT | E5: Fulfillment % | G5: Pending PKT | I5: Pending SKUs | K5: Critical SKUs | O5: {=_xlfn.SWITCH($C$4,"MRP (Domestic)",Summary!G5,"ROW Manjari",Summary!H5,"USA Sea",Summary!I5,"Amazon USA Sea",Summary!J5,"USA Air",Summary!K5,"USA Amazon",Summary!L5,"UK",Summary!M5,"MENA",Summary!N5,Summary!O5)} -> 0 | P5: =--(Summary!B5<>"")*IF($C$3="All",1,--(Summary!C5=$C$3)) -> 0 | Q5: =IF($C$4="All",1,--(O5>0)) -> 1 | R5: =T5-O5 -> 1260 | S5: =Summary!B5 -> Atta | T5: {=_xlfn.SWITCH($C$4,"MRP (Domestic)",IFERROR(_xlfn.XLOOKUP(Summary!D5,Domestic!$C:$C,Domestic!$BE:$BE),0),"ROW Manjari",IFERROR(_xlfn.XLOOKUP(Summary!D5,ROW_Manjari!$C:$C,ROW_Manjari!$BE:$BE),0),"USA Sea",IFERROR(_xlfn.XLOOKUP(Summary!D5,USA_Sea!$C:$C,USA_Sea!$BE:$BE),0),"Amazon USA Sea",IFERROR(_xlfn.XLOOKUP(Summary!D5,Amazon_USA_Sea!$C:$C,Amazon_USA_Sea!$AX:$AX),0),"USA Air",IFERROR(_xlfn.XLOOKUP(Summary!D5,USA_Air!$C:$C,USA_Air!$BE:$BE),0),"USA Amazon",IFERROR(_xlfn.XLOOKUP(Summary!D5,USA_Amazon_Air!$C:$C,USA_Amazon_Air!$BE:$BE),0),"UK",IFERROR(_xlfn.XLOOKUP(Summary!D5,UK_Order!$C:$C,UK_Order!$BE:$BE),0),"MENA",IFERROR(_xlfn.XLOOKUP(Summary!D5,MENA_Order!$C:$C,MENA_Order!$BE:$BE),0),Summary!AT5)} -> 1260 | U5: =IF($G$3="All",1,--($S5=$G$3)) -> 1 | V5: =IF($G$4="All",1,--(Summary!E5=$G$4)) -> 1 | Y5: =Summary!E6 -> Jowar Atta (Stoneground) - 1kg khapli for international ( 3kg and 5kg added)
A6: =IFERROR(SUMPRODUCT($O$3:$O$70,$P$3:$P$70,$Q$3:$Q$70,$U$3:$U$70,$V$3:$V$70),"") -> 174571 | C6: =IFERROR(SUMPRODUCT($T$3:$T$70,$P$3:$P$70,$Q$3:$Q$70,$U$3:$U$70,$V$3:$V$70),"") -> 140745.8 | E6: =IFERROR(C6/A6,"") -> 0.80623815 | G6: {=IFERROR(ABS(SUMPRODUCT($R$3:$R$70,--($R$3:$R$70<0),$P$3:$P$70,$Q$3:$Q$70,$U$3:$U$70,$V$3:$V$70)),"")} | I6: {=IFERROR(SUMPRODUCT(--($R$3:$R$70<0),$P$3:$P$70,$Q$3:$Q$70,$U$3:$U$70,$V$3:$V$70),"")} | K6: {=IFERROR(SUMPRODUCT(--(Summary!$BC$3:$BC$70="P1 – Critical"),--($R$3:$R$70<0),$P$3:$P$70,$Q$3:$Q$70,$U$3:$U$70,$V$3:$V$70),"")} | O6: {=_xlfn.SWITCH($C$4,"MRP (Domestic)",Summary!G6,"ROW Manjari",Summary!H6,"USA Sea",Summary!I6,"Amazon USA Sea",Summary!J6,"USA Air",Summary!K6,"USA Amazon",Summary!L6,"UK",Summary!M6,"MENA",Summary!N6,Summary!O6)} -> 0 | P6: =--(Summary!B6<>"")*IF($C$3="All",1,--(Summary!C6=$C$3)) -> 1 | Q6: =IF($C$4="All",1,--(O6>0)) -> 1 | R6: =T6-O6 -> 0 | S6: =Summary!B6 -> Atta | T6: {=_xlfn.SWITCH($C$4,"MRP (Domestic)",IFERROR(_xlfn.XLOOKUP(Summary!D6,Domestic!$C:$C,Domestic!$BE:$BE),0),"ROW Manjari",IFERROR(_xlfn.XLOOKUP(Summary!D6,ROW_Manjari!$C:$C,ROW_Manjari!$BE:$BE),0),"USA Sea",IFERROR(_xlfn.XLOOKUP(Summary!D6,USA_Sea!$C:$C,USA_Sea!$BE:$BE),0),"Amazon USA Sea",IFERROR(_xlfn.XLOOKUP(Summary!D6,Amazon_USA_Sea!$C:$C,Amazon_USA_Sea!$AX:$AX),0),"USA Air",IFERROR(_xlfn.XLOOKUP(Summary!D6,USA_Air!$C:$C,USA_Air!$BE:$BE),0),"USA Amazon",IFERROR(_xlfn.XLOOKUP(Summary!D6,USA_Amazon_Air!$C:$C,USA_Amazon_Air!$BE:$BE),0),"UK",IFERROR(_xlfn.XLOOKUP(Summary!D6,UK_Order!$C:$C,UK_Order!$BE:$BE),0),"MENA",IFERROR(_xlfn.XLOOKUP(Summary!D6,MENA_Order!$C:$C,MENA_Order!$BE:$BE),0),Summary!AT6)} -> 0 | U6: =IF($G$3="All",1,--($S6=$G$3)) -> 1 | V6: =IF($G$4="All",1,--(Summary!E6=$G$4)) -> 1 | Y6: =Summary!E7 -> Jowar atta 500
O7: {=_xlfn.SWITCH($C$4,"MRP (Domestic)",Summary!G7,"ROW Manjari",Summary!H7,"USA Sea",Summary!I7,"Amazon USA Sea",Summary!J7,"USA Air",Summary!K7,"USA Amazon",Summary!L7,"UK",Summary!M7,"MENA",Summary!N7,Summary!O7)} -> 11719 | P7: =--(Summary!B7<>"")*IF($C$3="All",1,--(Summary!C7=$C$3)) -> 1 | Q7: =IF($C$4="All",1,--(O7>0)) -> 1 | R7: =T7-O7 -> -6095 | S7: =Summary!B7 -> Atta | T7: {=_xlfn.SWITCH($C$4,"MRP (Domestic)",IFERROR(_xlfn.XLOOKUP(Summary!D7,Domestic!$C:$C,Domestic!$BE:$BE),0),"ROW Manjari",IFERROR(_xlfn.XLOOKUP(Summary!D7,ROW_Manjari!$C:$C,ROW_Manjari!$BE:$BE),0),"USA Sea",IFERROR(_xlfn.XLOOKUP(Summary!D7,USA_Sea!$C:$C,USA_Sea!$BE:$BE),0),"Amazon USA Sea",IFERROR(_xlfn.XLOOKUP(Summary!D7,Amazon_USA_Sea!$C:$C,Amazon_USA_Sea!$AX:$AX),0),"USA Air",IFERROR(_xlfn.XLOOKUP(Summary!D7,USA_Air!$C:$C,USA_Air!$BE:$BE),0),"USA Amazon",IFERROR(_xlfn.XLOOKUP(Summary!D7,USA_Amazon_Air!$C:$C,USA_Amazon_Air!$BE:$BE),0),"UK",IFERROR(_xlfn.XLOOKUP(Summary!D7,UK_Order!$C:$C,UK_Order!$BE:$BE),0),"MENA",IFERROR(_xlfn.XLOOKUP(Summary!D7,MENA_Order!$C:$C,MENA_Order!$BE:$BE),0),Summary!AT7)} -> 5624 | U7: =IF($G$3="All",1,--($S7=$G$3)) -> 1 | V7: =IF($G$4="All",1,--(Summary!E7=$G$4)) -> 1 | Y7: =Summary!E8 -> Jowar Atta (Stoneground) - 2kg
O8: {=_xlfn.SWITCH($C$4,"MRP (Domestic)",Summary!G8,"ROW Manjari",Summary!H8,"USA Sea",Summary!I8,"Amazon USA Sea",Summary!J8,"USA Air",Summary!K8,"USA Amazon",Summary!L8,"UK",Summary!M8,"MENA",Summary!N8,Summary!O8)} -> 3354 | P8: =--(Summary!B8<>"")*IF($C$3="All",1,--(Summary!C8=$C$3)) -> 1 | Q8: =IF($C$4="All",1,--(O8>0)) -> 1 | R8: =T8-O8 -> -1780 | S8: =Summary!B8 -> Atta | T8: {=_xlfn.SWITCH($C$4,"MRP (Domestic)",IFERROR(_xlfn.XLOOKUP(Summary!D8,Domestic!$C:$C,Domestic!$BE:$BE),0),"ROW Manjari",IFERROR(_xlfn.XLOOKUP(Summary!D8,ROW_Manjari!$C:$C,ROW_Manjari!$BE:$BE),0),"USA Sea",IFERROR(_xlfn.XLOOKUP(Summary!D8,USA_Sea!$C:$C,USA_Sea!$BE:$BE),0),"Amazon USA Sea",IFERROR(_xlfn.XLOOKUP(Summary!D8,Amazon_USA_Sea!$C:$C,Amazon_USA_Sea!$AX:$AX),0),"USA Air",IFERROR(_xlfn.XLOOKUP(Summary!D8,USA_Air!$C:$C,USA_Air!$BE:$BE),0),"USA Amazon",IFERROR(_xlfn.XLOOKUP(Summary!D8,USA_Amazon_Air!$C:$C,USA_Amazon_Air!$BE:$BE),0),"UK",IFERROR(_xlfn.XLOOKUP(Summary!D8,UK_Order!$C:$C,UK_Order!$BE:$BE),0),"MENA",IFERROR(_xlfn.XLOOKUP(Summary!D8,MENA_Order!$C:$C,MENA_Order!$BE:$BE),0),Summary!AT8)} -> 1574 | U8: =IF($G$3="All",1,--($S8=$G$3)) -> 1 | V8: =IF($G$4="All",1,--(Summary!E8=$G$4)) -> 1 | Y8: =Summary!E9 -> Besan Flour | Gram Flour | Stoneground - 1kg
A9: =IFERROR("For plant "&$C$3&", channel "&$C$4&", section "&$G$3&", product "&$G$4&": fulfillment is "&TEXT(E6,"0%")&" against "&TEXT(A6,"#,##0")&" planned packets. Pending exposure is "&TEXT(G6,"#,##0")&" packets across "&TEXT(I6,"#,##0")&" SKUs, including "&TEXT(K6,"#,##0")&" critical SKUs.","") -> For plant C6, channel All, section All, product All: fulfillment is 81% against 1,74,571 planned packets. Pending exposure is packets across SKUs, including critical SKUs. | O9: {=_xlfn.SWITCH($C$4,"MRP (Domestic)",Summary!G9,"ROW Manjari",Summary!H9,"USA Sea",Summary!I9,"Amazon USA Sea",Summary!J9,"USA Air",Summary!K9,"USA Amazon",Summary!L9,"UK",Summary!M9,"MENA",Summary!N9,Summary!O9)} -> 3565 | P9: =--(Summary!B9<>"")*IF($C$3="All",1,--(Summary!C9=$C$3)) -> 0 | Q9: =IF($C$4="All",1,--(O9>0)) -> 1 | R9: =T9-O9 -> -398 | S9: =Summary!B9 -> Atta | T9: {=_xlfn.SWITCH($C$4,"MRP (Domestic)",IFERROR(_xlfn.XLOOKUP(Summary!D9,Domestic!$C:$C,Domestic!$BE:$BE),0),"ROW Manjari",IFERROR(_xlfn.XLOOKUP(Summary!D9,ROW_Manjari!$C:$C,ROW_Manjari!$BE:$BE),0),"USA Sea",IFERROR(_xlfn.XLOOKUP(Summary!D9,USA_Sea!$C:$C,USA_Sea!$BE:$BE),0),"Amazon USA Sea",IFERROR(_xlfn.XLOOKUP(Summary!D9,Amazon_USA_Sea!$C:$C,Amazon_USA_Sea!$AX:$AX),0),"USA Air",IFERROR(_xlfn.XLOOKUP(Summary!D9,USA_Air!$C:$C,USA_Air!$BE:$BE),0),"USA Amazon",IFERROR(_xlfn.XLOOKUP(Summary!D9,USA_Amazon_Air!$C:$C,USA_Amazon_Air!$BE:$BE),0),"UK",IFERROR(_xlfn.XLOOKUP(Summary!D9,UK_Order!$C:$C,UK_Order!$BE:$BE),0),"MENA",IFERROR(_xlfn.XLOOKUP(Summary!D9,MENA_Order!$C:$C,MENA_Order!$BE:$BE),0),Summary!AT9)} -> 3167 | U9: =IF($G$3="All",1,--($S9=$G$3)) -> 1 | V9: =IF($G$4="All",1,--(Summary!E9=$G$4)) -> 1 | Y9: =Summary!E10 -> Bajra Atta 1kg
O10: {=_xlfn.SWITCH($C$4,"MRP (Domestic)",Summary!G10,"ROW Manjari",Summary!H10,"USA Sea",Summary!I10,"Amazon USA Sea",Summary!J10,"USA Air",Summary!K10,"USA Amazon",Summary!L10,"UK",Summary!M10,"MENA",Summary!N10,Summary!O10)} | P10: =--(Summary!B10<>"")*IF($C$3="All",1,--(Summary!C10=$C$3)) -> 1 | Q10: =IF($C$4="All",1,--(O10>0)) -> 1 | R10: =T10-O10 -> #VALUE! | S10: =Summary!B10 -> Atta | T10: {=_xlfn.SWITCH($C$4,"MRP (Domestic)",IFERROR(_xlfn.XLOOKUP(Summary!D10,Domestic!$C:$C,Domestic!$BE:$BE),0),"ROW Manjari",IFERROR(_xlfn.XLOOKUP(Summary!D10,ROW_Manjari!$C:$C,ROW_Manjari!$BE:$BE),0),"USA Sea",IFERROR(_xlfn.XLOOKUP(Summary!D10,USA_Sea!$C:$C,USA_Sea!$BE:$BE),0),"Amazon USA Sea",IFERROR(_xlfn.XLOOKUP(Summary!D10,Amazon_USA_Sea!$C:$C,Amazon_USA_Sea!$AX:$AX),0),"USA Air",IFERROR(_xlfn.XLOOKUP(Summary!D10,USA_Air!$C:$C,USA_Air!$BE:$BE),0),"USA Amazon",IFERROR(_xlfn.XLOOKUP(Summary!D10,USA_Amazon_Air!$C:$C,USA_Amazon_Air!$BE:$BE),0),"UK",IFERROR(_xlfn.XLOOKUP(Summary!D10,UK_Order!$C:$C,UK_Order!$BE:$BE),0),"MENA",IFERROR(_xlfn.XLOOKUP(Summary!D10,MENA_Order!$C:$C,MENA_Order!$BE:$BE),0),Summary!AT10)} -> 295 | U10: =IF($G$3="All",1,--($S10=$G$3)) -> 1 | V10: =IF($G$4="All",1,--(Summary!E10=$G$4)) -> 1 | Y10: =Summary!E11 -> Jowar atta 910g
